Workbook

Sheet Parent
A1: BRIEF-2 Parent
A3: Directions: Enter all information in the green boxes.
A4: Use the following code: | J4: Age: | K4: 5-7
B5: 1 = Never | F5: 3 = Often | J5: Gender: | K5: Boys
B6: 2 = Sometimes | F6: ? = (Skipped)
C8: Raw Score | F8: Raw Score | H8: Total Missing Items: | N8: Raw Score Calculation:
A9: Item | B9: 1 | D9: Item | E9: 33 | H9: Total: | I9: Limit: | K9: Classification: | N9: Scale/Index/Comp | P9: Raw Score | Q9: # Missing
A10: Item | B10: =B9+1 -> 2 | D10: Item | E10: =E9+1 -> 34 | H10: =SUM(IF(C9="?",1,0),IF(C10="?",1,0),IF(C11="?",1,0),IF(C12="?",1,0),IF(C13="?",1,0),IF(C14="?",1,0),IF(C15="?",1,0),IF(C16="?",1,0),IF(C17="?",1,0),IF(C18="?",1,0),IF(C19="?",1,0),IF(C20="?",1,0),IF(C21="?",1,0),IF(C22="?",1,0),IF(C23="?",1,0),IF(C24="?",1,0),IF(C25="?",1,0),IF(C26="?",1,0),IF(C27="?",1,0),IF(C28="?",1,0),IF(C29="?",1,0),IF(C30="?",1,0),IF(C31="?",1,0),IF(C32="?",1,0),IF(C33="?",1,0),IF(C34="?",1,0),IF(C35="?",1,0),IF(C36="?",1,0),IF(C37="?",1,0),IF(C38="?",1,0),IF(C39="?",1,0),IF(C40="?",1,0),IF(F9="?",1,0),IF(F10="?",1,0),IF(F11="?",1,0),IF(F12="?",1,0),IF(F13="?",1,0),IF(F14="?",1,0),IF(F15="?",1,0),IF(F16="?",1,0),IF(F17="?",1,0),IF(F18="?",1,0),IF(F19="?",1,0),IF(F20="?",1,0),IF(F21="?",1,0),IF(F22="?",1,0),IF(F23="?",1,0),IF(F24="?",1,0),IF(F25="?",1,0),IF(F26="?",1,0),IF(F27="?",1,0),IF(F28="?",1,0),IF(F29="?",1,0),IF(F30="?",1,0),IF(F31="?",1,0),IF(F32="?",1,0),IF(F33="?",1,0),IF(F34="?",1,0),IF(F35="?",1,0),IF(F36="?",1,0),IF(F37="?",1,0),IF(F38="?",1,0),IF(F39="?",1,0)) -> 0 | I10: 12 | K10: =IF(H10>I10,"Invalid","Acceptable") -> Acceptable | N10: Inhibit | P10: =IF(Q10<2,SUM(C9,C18,C24,C32,C38,F15,F24,F38,Q10),"INVALID") -> 0 | Q10: =SUM(IF(C9="?",1,0),IF(C18="?",1,0),IF(C24="?",1,0),IF(C32="?",1,0),IF(C38="?",1,0),IF(F15="?",1,0),IF(F24="?",1,0),IF(F38="?",1,0)) -> 0
A11: Item | B11: =B10+1 -> 3 | D11: Item | E11: =E10+1 -> 35 | N11: Self-Monitor | P11: =IF(Q11<2,SUM(C12,C21,C28,C34,Q11),"INVALID") -> 0 | Q11: =SUM(IF(C12="?",1,0),IF(C21="?",1,0),IF(C28="?",1,0),IF(C34="?",1,0)) -> 0
A12: Item | B12: =B11+1 -> 4 | D12: Item | E12: =E11+1 -> 36 | H12: Negativity Scale: | N12: BRI | P12: =IF(AND(Q10<2,Q11<2),SUM(P10:P11),"INVALID") -> 0 | Q12: =SUM(Q10:Q11) -> 0
A13: Item | B13: =B12+1 -> 5 | D13: Item | E13: =E12+1 -> 37 | H13: Score: | I13: Percentile: | K13: Classification: | N13: Shift | P13: =IF(Q13<2,SUM(C10,C19,C25,C39,F16,F25,F34,F36,Q13),"INVALID") -> 0 | Q13: =SUM(IF(C10="?",1,0),IF(C19="?",1,0),IF(C25="?",1,0),IF(C39="?",1,0),IF(F16="?",1,0),IF(F25="?",1,0),IF(F34="?",1,0),IF(F36="?",1,0)) -> 0
A14: Item | B14: =B13+1 -> 6 | D14: Item | E14: =E13+1 -> 38 | H14: =SUM(IF(C22="?",0,TRUNC(C22/3)),IF(C36="?",0,TRUNC(C36/3)),IF(C38="?",0,TRUNC(C38/3)),IF(F10="?",0,TRUNC(F10/3)),IF(F15="?",0,TRUNC(F15/3)),IF(F17="?",0,TRUNC(F17/3)),IF(F34="?",0,TRUNC(F34/3)),IF(F36="?",0,TRUNC(F36/3))) -> 0 | I14: =IF(H14>7,">99",IF(H14=7,"99","≤98")) -> ≤98 | K14: =IF(H14>7,"Highly Elevated",IF(H14=7,"Elevated","Acceptable")) -> Acceptable | N14: Emotional Control | P14: =IF(Q14<2,SUM(C14,C22,C30,C35,F10,F19,F27,F32,Q14),"INVALID") -> 0 | Q14: =SUM(IF(C14="?",1,0),IF(C22="?",1,0),IF(C30="?",1,0),IF(C35="?",1,0),IF(F10="?",1,0),IF(F19="?",1,0),IF(F27="?",1,0),IF(F32="?",1,0)) -> 0
A15: Item | B15: =B14+1 -> 7 | D15: Item | E15: =E14+1 -> 39 | N15: ERI | P15: =IF(AND(Q13<2,Q14<2),SUM(P13:P14),"INVALID") -> 0 | Q15: =SUM(Q13:Q14) -> 0
A16: Item | B16: =B15+1 -> 8 | D16: Item | E16: =E15+1 -> 40 | H16: Infrequency Scale: | N16: Initiate | P16: =IF(Q16<2,SUM(C17,F14,F26,F31,F37,Q16),"INVALID") -> 0 | Q16: =SUM(IF(C17="?",1,0),IF(F14="?",1,0),IF(F26="?",1,0),IF(F31="?",1,0),IF(F37="?",1,0)) -> 0
A17: Item | B17: =B16+1 -> 9 | D17: Item | E17: =E16+1 -> 41 | H17: Score: | I17: Percentile: | K17: Classification: | N17: Working Memory | P17: =IF(Q17<2,SUM(C11,C20,C27,C33,C36,C40,F17,F22,Q17),"INVALID") -> 0 | Q17: =SUM(IF(C11="?",1,0),IF(C20="?",1,0),IF(C27="?",1,0),IF(C33="?",1,0),IF(C36="?",1,0),IF(C40="?",1,0),IF(F17="?",1,0),IF(F22="?",1,0)) -> 0
A18: Item | B18: =B17+1 -> 10 | D18: Item | E18: =E17+1 -> 42 | H18: =SUM(IF(C26="?",0,ROUND(C26/3,0)),IF(F12="?",0,ROUND(F12/3,0)),IF(F30="?",0,ROUND(F30/3,0))) -> 0 | I18: =IF(H18=0,"99",">99") -> 99 | K18: =IF(H18=0,"Acceptable","Questionable") -> Acceptable | N18: Plan/Organize | P18: =IF(Q18<2,SUM(C15,C23,C31,F11,F20,F28,F33,F35,Q18),"INVALID") -> 0 | Q18: =SUM(IF(C15="?",1,0),IF(C23="?",1,0),IF(C31="?",1,0),IF(F11="?",1,0),IF(F20="?",1,0),IF(F28="?",1,0),IF(F33="?",1,0),IF(F35="?",1,0)) -> 0
A19: Item | B19: =B18+1 -> 11 | D19: Item | E19: =E18+1 -> 43 | N19: Task-Monitor | P19: =IF(Q19<2,SUM(C13,C29,C37,F9,F18,Q19),"INVALID") -> 0 | Q19: =SUM(IF(C13="?",1,0),IF(C29="?",1,0),IF(C37="?",1,0),IF(F9="?",1,0),IF(F18="?",1,0)) -> 0
A20: Item | B20: =B19+1 -> 12 | D20: Item | E20: =E19+1 -> 44 | H20: Inconsistency Scale: | N20: Org. of Materials | P20: =IF(Q20<2,SUM(C16,F13,F21,F23,F29,F39,Q20),"INVALID") -> 0 | Q20: =SUM(IF(C16="?",1,0),IF(F13="?",1,0),IF(F21="?",1,0),IF(F23="?",1,0),IF(F29="?",1,0),IF(F39="?",1,0)) -> 0
A21: Item | B21: =B20+1 -> 13 | D21: Item | E21: =E20+1 -> 45 | H21: Score: | I21: Percentile: | K21: Classification: | N21: CRI | P21: =IF(AND(Q16<2,Q17<2,Q18<2,Q19<2,Q20<2),SUM(P16:P20),"INVALID") -> 0 | Q21: =SUM(Q16:Q20) -> 0
A22: Item | B22: =B21+1 -> 14 | D22: Item | E22: =E21+1 -> 46 | H22: =SUM(L25:L32) -> 0 | I22: =IF(H22>10,">99",IF(H22<7,"≤98","99")) -> ≤98 | K22: =IF(H22>10,"Inconsistent",IF(H22<7,"Acceptable","Questionable")) -> Acceptable | N22: GEC | P22: =IF(P12="INVALID","INVALID",IF(P15="INVALID","INVALID",IF(P21="INVALID","INVALID",SUM(P12,P15,P21)))) -> 0 | Q22: =SUM(Q12,Q15,Q21) -> 0
A23: Item | B23: =B22+1 -> 15 | D23: Item | E23: =E22+1 -> 47
A24: Item | B24: =B23+1 -> 16 | D24: Item | E24: =E23+1 -> 48 | H24: Item no. | I24: Score | J24: Item no. | K24: Score | L24: Difference | N24: Scoring Summary Table
A25: Item | B25: =B24+1 -> 17 | D25: Item | E25: =E24+1 -> 49 | H25: 5 | I25: =IF(C13="?",1,C13) -> 0 | J25: 21 | K25: =IF(C29="?",1,C29) -> 0 | L25: =ABS(I25-K25) -> 0 | N25: Scale/Index/Comp | P25: Raw Score | Q25: T-Score | R25: %ile | S25: 90% CI
A26: Item | B26: =B25+1 -> 18 | D26: Item | E26: =E25+1 -> 50 | H26: 9 | I26: =IF(C17="?",1,C17) -> 0 | J26: 55 | K26: =IF(F31="?",1,F31) -> 0 | L26: =ABS(I26-K26) -> 0 | N26: Inhibit | P26: =P10 -> 0 | Q26: ='Calc - Parent'!D7 | R26: ='Calc - Parent'!E7 | S26: ='Calc - Parent'!F7 -> #VALUE! | T26: - | U26: ='Calc - Parent'!G7 -> #VALUE!
A27: Item | B27: =B26+1 -> 19 | D27: Item | E27: =E26+1 -> 51 | H27: 10 | I27: =IF(C18="?",1,C18) -> 0 | J27: 48 | K27: =IF(F24="?",1,F24) -> 0 | L27: =ABS(I27-K27) -> 0 | N27: Self-Monitor | P27: =P11 -> 0 | Q27: ='Calc - Parent'!D8 | R27: ='Calc - Parent'!E8 | S27: ='Calc - Parent'!F8 -> #VALUE! | T27: - | U27: ='Calc - Parent'!G8 -> #VALUE!
A28: Item | B28: =B27+1 -> 20 | D28: Item | E28: =E27+1 -> 52 | H28: 17 | I28: =IF(C25="?",1,C25) -> 0 | J28: 40 | K28: =IF(F16="?",1,F16) -> 0 | L28: =ABS(I28-K28) -> 0 | N28: BRI | P28: =P12 -> 0 | Q28: ='Calc - Parent'!D9 | R28: ='Calc - Parent'!E9 | S28: ='Calc - Parent'!F9 -> #VALUE! | T28: - | U28: ='Calc - Parent'!G9 -> #VALUE!
A29: Item | B29: =B28+1 -> 21 | D29: Item | E29: =E28+1 -> 53 | H29: 20 | I29: =IF(C28="?",1,C28) -> 0 | J29: 26 | K29: =IF(C34="?",1,C34) -> 0 | L29: =ABS(I29-K29) -> 0 | N29: Shift | P29: =P13 -> 0 | Q29: ='Calc - Parent'!D10 | R29: ='Calc - Parent'!E10 | S29: ='Calc - Parent'!F10 -> #VALUE! | T29: - | U29: ='Calc - Parent'!G10 -> #VALUE!
A30: Item | B30: =B29+1 -> 22 | D30: Item | E30: =E29+1 -> 54 | H30: 22 | I30: =IF(C30="?",1,C30) -> 0 | J30: 56 | K30: =IF(F32="?",1,F32) -> 0 | L30: =ABS(I30-K30) -> 0 | N30: Emotional Control | P30: =P14 -> 0 | Q30: ='Calc - Parent'!D11 | R30: ='Calc - Parent'!E11 | S30: ='Calc - Parent'!F11 -> #VALUE! | T30: - | U30: ='Calc - Parent'!G11 -> #VALUE!
A31: Item | B31: =B30+1 -> 23 | D31: Item | E31: =E30+1 -> 55 | H31: 25 | I31: =IF(C33="?",1,C33) -> 0 | J31: 50 | K31: =IF(F26="?",1,F26) -> 0 | L31: =ABS(I31-K31) -> 0 | N31: ERI | P31: =P15 -> 0 | Q31: ='Calc - Parent'!D12 | R31: ='Calc - Parent'!E12 | S31: ='Calc - Parent'!F12 -> #VALUE! | T31: - | U31: ='Calc - Parent'!G12 -> #VALUE!
A32: Item | B32: =B31+1 -> 24 | D32: Item | E32: =E31+1 -> 56 | H32: 37 | I32: =IF(F13="?",1,F13) -> 0 | J32: 63 | K32: =IF(F39="?",1,F39) -> 0 | L32: =ABS(I32-K32) -> 0 | N32: Initiate | P32: =P16 -> 0 | Q32: ='Calc - Parent'!D13 | R32: ='Calc - Parent'!E13 | S32: ='Calc - Parent'!F13 -> #VALUE! | T32: - | U32: ='Calc - Parent'!G13 -> #VALUE!
A33: Item | B33: =B32+1 -> 25 | D33: Item | E33: =E32+1 -> 57 | N33: Working Memory | P33: =P17 -> 0 | Q33: ='Calc - Parent'!D14 | R33: ='Calc - Parent'!E14 | S33: ='Calc - Parent'!F14 -> #VALUE! | T33: - | U33: ='Calc - Parent'!G14 -> #VALUE!
A34: Item | B34: 26 | D34: Item | E34: =E33+1 -> 58 | N34: Plan/Organize | P34: =P18 -> 0 | Q34: ='Calc - Parent'!D15 | R34: ='Calc - Parent'!E15 | S34: ='Calc - Parent'!F15 -> #VALUE! | T34: - | U34: ='Calc - Parent'!G15 -> #VALUE!
A35: Item | B35: 27 | D35: Item | E35: =E34+1 -> 59 | N35: Task-Monitor | P35: =P19 -> 0 | Q35: ='Calc - Parent'!D16 | R35: ='Calc - Parent'!E16 | S35: ='Calc - Parent'!F16 -> #VALUE! | T35: - | U35: ='Calc - Parent'!G16 -> #VALUE!
A36: Item | B36: 28 | D36: Item | E36: =E35+1 -> 60 | N36: Org. of Materials | P36: =P20 -> 0 | Q36: ='Calc - Parent'!D17 | R36: ='Calc - Parent'!E17 | S36: ='Calc - Parent'!F17 -> #VALUE! | T36: - | U36: ='Calc - Parent'!G17 -> #VALUE!
A37: Item | B37: =B36+1 -> 29 | D37: Item | E37: =E36+1 -> 61 | N37: CRI | P37: =P21 -> 0 | Q37: ='Calc - Parent'!D18 | R37: ='Calc - Parent'!E18 | S37: ='Calc - Parent'!F18 -> #VALUE! | T37: - | U37: ='Calc - Parent'!G18 -> #VALUE!
A38: Item | B38: =B37+1 -> 30 | D38: Item | E38: =E37+1 -> 62 | N38: GEC | P38: =P22 -> 0 | Q38: ='Calc - Parent'!D19 | R38: ='Calc - Parent'!E19 | S38: ='Calc - Parent'!F19 -> #VALUE! | T38: - | U38: ='Calc - Parent'!G19 -> #VALUE!
A39: Item | B39: =B38+1 -> 31 | D39: Item | E39: =E38+1 -> 63
A40: Item | B40: =B39+1 -> 32

Sheet Teacher
A1: BRIEF-2 Teacher
A3: Directions: Enter all information in the green boxes.
A4: Use the following code: | J4: Age: | K4: Select:
B5: 1 = Never | F5: 3 = Often | J5: Gender: | K5: Select:
B6: 2 = Sometimes | F6: ? = (Skipped)
C8: Raw Score | F8: Raw Score | H8: Total Missing Items: | N8: Raw Scores Calculation:
A9: Item | B9: 1 | D9: Item | E9: 33 | H9: Total: | I9: Limit: | K9: Classification: | N9: Scale/Index/Comp | P9: Raw Score | Q9: # Missing
A10: Item | B10: =B9+1 -> 2 | D10: Item | E10: =E9+1 -> 34 | H10: =SUM(IF(C9="?",1,0),IF(C10="?",1,0),IF(C11="?",1,0),IF(C12="?",1,0),IF(C13="?",1,0),IF(C14="?",1,0),IF(C15="?",1,0),IF(C16="?",1,0),IF(C17="?",1,0),IF(C18="?",1,0),IF(C19="?",1,0),IF(C20="?",1,0),IF(C21="?",1,0),IF(C22="?",1,0),IF(C23="?",1,0),IF(C24="?",1,0),IF(C25="?",1,0),IF(C26="?",1,0),IF(C27="?",1,0),IF(C28="?",1,0),IF(C29="?",1,0),IF(C30="?",1,0),IF(C31="?",1,0),IF(C32="?",1,0),IF(C33="?",1,0),IF(C34="?",1,0),IF(C35="?",1,0),IF(C36="?",1,0),IF(C37="?",1,0),IF(C38="?",1,0),IF(C39="?",1,0),IF(C40="?",1,0),IF(F9="?",1,0),IF(F10="?",1,0),IF(F11="?",1,0),IF(F12="?",1,0),IF(F13="?",1,0),IF(F14="?",1,0),IF(F15="?",1,0),IF(F16="?",1,0),IF(F17="?",1,0),IF(F18="?",1,0),IF(F19="?",1,0),IF(F20="?",1,0),IF(F21="?",1,0),IF(F22="?",1,0),IF(F23="?",1,0),IF(F24="?",1,0),IF(F25="?",1,0),IF(F26="?",1,0),IF(F27="?",1,0),IF(F28="?",1,0),IF(F29="?",1,0),IF(F30="?",1,0),IF(F31="?",1,0),IF(F32="?",1,0),IF(F33="?",1,0),IF(F34="?",1,0),IF(F35="?",1,0),IF(F36="?",1,0),IF(F37="?",1,0),IF(F38="?",1,0),IF(F39="?",1,0)) -> 0 | I10: 12 | K10: =IF(H10>I10,"Invalid","Acceptable") -> Acceptable | N10: Inhibit | P10: =IF(Q10<2,SUM(C9,C18,C24,C32,C38,F15,F24,F34),"INVALID") -> 0 | Q10: =SUM(IF(C9="?",1,0),IF(C18="?",1,0),IF(C24="?",1,0),IF(C32="?",1,0),IF(C38="?",1,0),IF(F15="?",1,0),IF(F24="?",1,0),IF(F34="?",1,0)) -> 0
A11: Item | B11: =B10+1 -> 3 | D11: Item | E11: =E10+1 -> 35 | N11: Self-Monitor | P11: =IF(Q11<2,SUM(C12,C21,C28,C34,F35),"INVALID") -> 0 | Q11: =SUM(IF(C12="?",1,0),IF(C21="?",1,0),IF(C28="?",1,0),IF(C34="?",1,0),IF(F35="?",1,0)) -> 0
A12: Item | B12: =B11+1 -> 4 | D12: Item | E12: =E11+1 -> 36 | H12: Negativity Scale: | N12: BRI | P12: =IF(AND(Q10<2,Q11<2),SUM(P10:P11),"INVALID") -> 0 | Q12: =SUM(Q10:Q11) -> 0
A13: Item | B13: =B12+1 -> 5 | D13: Item | E13: =E12+1 -> 37 | H13: Score: | I13: Percentile: | K13: Classification: | N13: Shift | P13: =IF(Q13<2,SUM(C10,C19,C25,C39,F16,F25,F36,F39),"INVALID") -> 0 | Q13: =SUM(IF(C10="?",1,0),IF(C19="?",1,0),IF(C25="?",1,0),IF(C39="?",1,0),IF(F16="?",1,0),IF(F25="?",1,0),IF(F36="?",1,0),IF(F39="?",1,0)) -> 0
A14: Item | B14: =B13+1 -> 6 | D14: Item | E14: =E13+1 -> 38 | H14: =SUM(IF(C10="?",0,TRUNC(C10/3)),IF(C19="?",0,TRUNC(C19/3)),IF(C39="?",0,TRUNC(C39/3)),IF(F10="?",0,TRUNC(F10/3)),IF(F13="?",0,TRUNC(F13/3)),IF(F19="?",0,TRUNC(F19/3)),IF(F21="?",0,TRUNC(F21/3)),IF(F25="?",0,TRUNC(F25/3))) -> 0 | I14: =IF(H14>7,">99",IF(H14=7,"99","≤98")) -> ≤98 | K14: =IF(H14>7,"Highly Elevated",IF(H14=7,"Elevated","Acceptable")) -> Acceptable | N14: Emotional Control | P14: =IF(Q14<2,SUM(C14,C22,C30,C35,F10,F19,F27,F32),"INVALID") -> 0 | Q14: =SUM(IF(C14="?",1,0),IF(C22="?",1,0),IF(C30="?",1,0),IF(C35="?",1,0),IF(F10="?",1,0),IF(F19="?",1,0),IF(F27="?",1,0),IF(F32="?",1,0)) -> 0
A15: Item | B15: =B14+1 -> 7 | D15: Item | E15: =E14+1 -> 39 | N15: ERI | P15: =IF(AND(Q13<2,Q14<2),SUM(P13:P14),"INVALID") -> 0 | Q15: =SUM(Q13:Q14) -> 0
A16: Item | B16: =B15+1 -> 8 | D16: Item | E16: =E15+1 -> 40 | H16: Infrequency Scale: | N16: Initiate | P16: =IF(Q16<2,SUM(C17,F14,F26,F31),"INVALID") -> 0 | Q16: =SUM(IF(C17="?",1,0),IF(F14="?",1,0),IF(F26="?",1,0),IF(F31="?",1,0)) -> 0
A17: Item | B17: =B16+1 -> 9 | D17: Item | E17: =E16+1 -> 41 | H17: Score: | I17: Percentile: | K17: Classification: | N17: Working Memory | P17: =IF(Q17<2,SUM(C11,C20,C27,C33,C36,C40,F17,F22),"INVALID") -> 0 | Q17: =SUM(IF(C11="?",1,0),IF(C20="?",1,0),IF(C27="?",1,0),IF(C33="?",1,0),IF(C36="?",1,0),IF(C40="?",1,0),IF(F17="?",1,0),IF(F22="?",1,0)) -> 0
A18: Item | B18: =B17+1 -> 10 | D18: Item | E18: =E17+1 -> 42 | H18: =SUM(IF(C26="?",0,ROUND(C26/3,0)),IF(F12="?",0,ROUND(F12/3,0)),IF(F30="?",0,ROUND(F30/3,0))) -> 0 | I18: =IF(H18=0,"99",">99") -> 99 | K18: =IF(H18=0,"Acceptable","Questionable") -> Acceptable | N18: Plan/Organize | P18: =IF(Q18<2,SUM(C15,C23,C31,F11,F20,F28,F33,F37),"INVALID") -> 0 | Q18: =SUM(IF(C15="?",1,0),IF(C23="?",1,0),IF(C31="?",1,0),IF(F11="?",1,0),IF(F20="?",1,0),IF(F28="?",1,0),IF(F33="?",1,0),IF(F37="?",1,0)) -> 0
A19: Item | B19: =B18+1 -> 11 | D19: Item | E19: =E18+1 -> 43 | N19: Task-Monitor | P19: =IF(Q19<2,SUM(C13,C29,C37,F9,F18,F38),"INVALID") -> 0 | Q19: =SUM(IF(C13="?",1,0),IF(C29="?",1,0),IF(C37="?",1,0),IF(F9="?",1,0),IF(F18="?",1,0),IF(C38="?",1,0)) -> 0
A20: Item | B20: =B19+1 -> 12 | D20: Item | E20: =E19+1 -> 44 | H20: Inconsistency Scale: | N20: Org. of Materials | P20: =IF(Q20<2,SUM(C16,F13,F21,F23,F29),"INVALID") -> 0 | Q20: =SUM(IF(C16="?",1,0),IF(F13="?",1,0),IF(F21="?",1,0),IF(F23="?",1,0),IF(F29="?",1,0)) -> 0
A21: Item | B21: =B20+1 -> 13 | D21: Item | E21: =E20+1 -> 45 | H21: Score: | I21: Percentile: | K21: Classification: | N21: CRI | P21: =IF(AND(Q16<2,Q17<2,Q18<2,Q19<2,Q20<2),SUM(P16:P20),"INVALID") -> 0 | Q21: =SUM(Q16:Q20) -> 0
A22: Item | B22: =B21+1 -> 14 | D22: Item | E22: =E21+1 -> 46 | H22: =SUM(L25:L32) -> 0 | I22: =IF(H22>10,">99",IF(H22<7,"≤98","99")) -> ≤98 | K22: =IF(H22>10,"Inconsistent",IF(H22<7,"Acceptable","Questionable")) -> Acceptable | N22: GEC | P22: =IF(P12="INVALID","INVALID",IF(P15="INVALID","INVALID",IF(P21="INVALID","INVALID",SUM(P12,P15,P21)))) -> 0 | Q22: =SUM(Q12,Q15,Q21) -> 0
A23: Item | B23: =B22+1 -> 15 | D23: Item | E23: =E22+1 -> 47
A24: Item | B24: =B23+1 -> 16 | D24: Item | E24: =E23+1 -> 48 | H24: Item no. | I24: Score | J24: Item no. | K24: Score | L24: Difference | N24: Scoring Summary Table
A25: Item | B25: =B24+1 -> 17 | D25: Item | E25: =E24+1 -> 49 | H25: 3 | I25: =IF(C11="?",1,C11) -> 0 | J25: 19 | K25: =IF(C27="?",1,C27) -> 0 | L25: =ABS(I25-K25) -> 0 | N25: Scale/Index/Comp | P25: Raw Score | Q25: T-Score | R25: %ile | S25: 90% CI
A26: Item | B26: =B25+1 -> 18 | D26: Item | E26: =E25+1 -> 50 | H26: 4 | I26: =IF(C12="?",1,C12) -> 0 | J26: 20 | K26: =IF(C28="?",1,C28) -> 0 | L26: =ABS(I26-K26) -> 0 | N26: Inhibit | P26: =P10 -> 0 | T26: -
A27: Item | B27: =B26+1 -> 19 | D27: Item | E27: =E26+1 -> 51 | H27: 5 | I27: =IF(C13="?",1,C13) -> 0 | J27: 33 | K27: =IF(F9="?",1,F9) -> 0 | L27: =ABS(I27-K27) -> 0 | N27: Self-Monitor | P27: =P11 -> 0 | T27: -
A28: Item | B28: =B27+1 -> 20 | D28: Item | E28: =E27+1 -> 52 | H28: 6 | I28: =IF(C14="?",1,C14) -> 0 | J28: 14 | K28: =IF(C22="?",1,C22) -> 0 | L28: =ABS(I28-K28) -> 0 | N28: BRI | P28: =P12 -> 0 | T28: -
A29: Item | B29: =B28+1 -> 21 | D29: Item | E29: =E28+1 -> 53 | H29: 12 | I29: =IF(C20="?",1,C20) -> 0 | J29: 32 | K29: =IF(C40="?",1,C40) -> 0 | L29: =ABS(I29-K29) -> 0 | N29: Shift | P29: =P13 -> 0 | T29: -
A30: Item | B30: =B29+1 -> 22 | D30: Item | E30: =E29+1 -> 54 | H30: 16 | I30: =IF(C24="?",1,C24) -> 0 | J30: 39 | K30: =IF(F15="?",1,F15) -> 0 | L30: =ABS(I30-K30) -> 0 | N30: Emotional Control | P30: =P14 -> 0 | T30: -
A31: Item | B31: =B30+1 -> 23 | D31: Item | E31: =E30+1 -> 55 | H31: 22 | I31: =IF(C30="?",1,C30) -> 0 | J31: 56 | K31: =IF(F32="?",1,F32) -> 0 | L31: =ABS(I31-K31) -> 0 | N31: ERI | P31: =P15 -> 0 | T31: -
A32: Item | B32: =B31+1 -> 24 | D32: Item | E32: =E31+1 -> 56 | H32: 60 | I32: =IF(F36="?",1,F36) -> 0 | J32: 63 | K32: =IF(F39="?",1,F39) -> 0 | L32: =ABS(I32-K32) -> 0 | N32: Initiate | P32: =P16 -> 0 | T32: -
A33: Item | B33: =B32+1 -> 25 | D33: Item | E33: =E32+1 -> 57 | N33: Working Memory | P33: =P17 -> 0 | T33: -
A34: Item | B34: 26 | D34: Item | E34: =E33+1 -> 58 | H34: TEACHER T-SCORES, %ILES AND CIs NOT YET AVAILABLE | N34: Plan/Organize | P34: =P18 -> 0 | T34: -
A35: Item | B35: 27 | D35: Item | E35: =E34+1 -> 59 | N35: Task-Monitor | P35: =P19 -> 0 | T35: -
A36: Item | B36: 28 | D36: Item | E36: =E35+1 -> 60 | N36: Org. of Materials | P36: =P20 -> 0 | T36: -
A37: Item | B37: =B36+1 -> 29 | D37: Item | E37: =E36+1 -> 61 | N37: CRI | P37: =P21 -> 0 | T37: -
A38: Item | B38: =B37+1 -> 30 | D38: Item | E38: =E37+1 -> 62 | N38: GEC | P38: =P22 -> 0 | T38: -
A39: Item | B39: =B38+1 -> 31 | D39: Item | E39: =E38+1 -> 63
A40: Item | B40: =B39+1 -> 32

Sheet Self
A1: BRIEF-2 Self
A3: Directions: Enter all information in the green boxes.
A4: Use the following code: | J4: Age: | K4: 14-18
B5: 1 = Never | F5: 3 = Often | J5: Gender: | K5: Boys
B6: 2 = Sometimes | F6: ? = (Skipped)
C8: Raw Score | F8: Raw Score | H8: Total Missing Items: | N8: Raw Scores Calculation:
A9: Item | B9: 1 | D9: Item | E9: 31 | H9: Total: | I9: Limit: | K9: Classification: | N9: Scale/Index/Comp | P9: Raw Score | Q9: # Missing
A10: Item | B10: =B9+1 -> 2 | D10: Item | E10: =E9+1 -> 32 | H10: =SUM(IF(C9="?",1,0),IF(C10="?",1,0),IF(C11="?",1,0),IF(C12="?",1,0),IF(C13="?",1,0),IF(C14="?",1,0),IF(C15="?",1,0),IF(C16="?",1,0),IF(C17="?",1,0),IF(C18="?",1,0),IF(C19="?",1,0),IF(C20="?",1,0),IF(C21="?",1,0),IF(C22="?",1,0),IF(C23="?",1,0),IF(C24="?",1,0),IF(C25="?",1,0),IF(C26="?",1,0),IF(C27="?",1,0),IF(C28="?",1,0),IF(C29="?",1,0),IF(C30="?",1,0),IF(C31="?",1,0),IF(C32="?",1,0),IF(C33="?",1,0),IF(C34="?",1,0),IF(C35="?",1,0),IF(C36="?",1,0),IF(C37="?",1,0),IF(C38="?",1,0),IF(F9="?",1,0),IF(F10="?",1,0),IF(F11="?",1,0),IF(F12="?",1,0),IF(F13="?",1,0),IF(F14="?",1,0),IF(F15="?",1,0),IF(F16="?",1,0),IF(F17="?",1,0),IF(F18="?",1,0),IF(F19="?",1,0),IF(F20="?",1,0),IF(F21="?",1,0),IF(F22="?",1,0),IF(F23="?",1,0),IF(F24="?",1,0),IF(F25="?",1,0),IF(F26="?",1,0),IF(F27="?",1,0),IF(F28="?",1,0),IF(F29="?",1,0),IF(F30="?",1,0),IF(F31="?",1,0),IF(F32="?",1,0),IF(F33="?",1,0)) -> 0 | I10: 10 | K10: =IF(H10>I10,"Invalid","Acceptable") -> Acceptable | N10: Inhibit | P10: =IF(Q10<2,SUM(C9,C18,C24,C32,C38,F17,F26,F27),"INVALID") -> 0 | Q10: =SUM(IF(C9="?",1,0),IF(C18="?",1,0),IF(C24="?",1,0),IF(C32="?",1,0),IF(C38="?",1,0),IF(F17="?",1,0),IF(F26="?",1,0),IF(F27="?",1,0)) -> 0
A11: Item | B11: =B10+1 -> 3 | D11: Item | E11: =E10+1 -> 33 | N11: Self-Monitor | P11: =IF(Q11<2,SUM(C12,C21,C28,C34,F28),"INVALID") -> 0 | Q11: =SUM(IF(C12="?",1,0),IF(C21="?",1,0),IF(C28="?",1,0),IF(C34="?",1,0),IF(F28="?",1,0)) -> 0
A12: Item | B12: =B11+1 -> 4 | D12: Item | E12: =E11+1 -> 34 | H12: Negativity Scale: | N12: BRI | P12: =IF(AND(Q10<2,Q11<2),SUM(P10:P11),"INVALID") -> 0 | Q12: =SUM(Q10:Q11) -> 0
A13: Item | B13: =B12+1 -> 5 | D13: Item | E13: =E12+1 -> 35 | H13: Score: | I13: Percentile: | K13: Classification: | N13: Shift | P13: =IF(Q13<2,SUM(C10,C19,C25,F9,F18,F23,F29,F31),"INVALID") -> 0 | Q13: =SUM(IF(C10="?",1,0),IF(C19="?",1,0),IF(C25="?",1,0),IF(F9="?",1,0),IF(F18="?",1,0),IF(F23="?",1,0),IF(F29="?",1,0),IF(F31="?",1,0)) -> 0
A14: Item | B14: =B13+1 -> 6 | D14: Item | E14: =E13+1 -> 36 | H14: =SUM(IF(C24="?",0,TRUNC(C24/3)),IF(C27="?",0,TRUNC(C27/3)),IF(C28="?",0,TRUNC(C28/3)),IF(C32="?",0,TRUNC(C32/3)),IF(C38="?",0,TRUNC(C38/3)),IF(F21="?",0,TRUNC(F21/3)),IF(F28="?",0,TRUNC(F28/3)),IF(F29="?",0,TRUNC(F29/3))) -> 0 | I14: =IF(H14>7,">99",IF(H14=7,"99","≤98")) -> ≤98 | K14: =IF(H14>4,"Highly Elevated",IF(H14=4,"Elevated","Acceptable")) -> Acceptable | N14: Emotional Control | P14: =IF(Q14<2,SUM(C14,C22,C30,C35,F12,F21),"INVALID") -> 0 | Q14: =SUM(IF(C14="?",1,0),IF(C22="?",1,0),IF(C30="?",1,0),IF(C35="?",1,0),IF(F12="?",1,0),IF(F21="?",1,0)) -> 0
A15: Item | B15: =B14+1 -> 7 | D15: Item | E15: =E14+1 -> 37 | N15: ERI | P15: =IF(AND(Q13<2,Q14<2),SUM(P13:P14),"INVALID") -> 0 | Q15: =SUM(Q13:Q14) -> 0
A16: Item | B16: =B15+1 -> 8 | D16: Item | E16: =E15+1 -> 38 | H16: Infrequency Scale: | N16: Task Completion | P16: =IF(Q16<2,SUM(C31,C33,F11,F16,F20,F22,F33),"INVALID") -> 0 | Q16: =SUM(IF(C31="?",1,0),IF(C33="?",1,0),IF(F11="?",1,0),IF(F16="?",1,0),IF(F20="?",1,0),IF(F22="?",1,0),IF(F33="?",1,0)) -> 0
A17: Item | B17: =B16+1 -> 9 | D17: Item | E17: =E16+1 -> 39 | H17: Score: | I17: Percentile: | K17: Classification: | N17: Working Memory | P17: =IF(Q17<2,SUM(C11,C20,C27,C36,C37,F10,F19,F24),"INVALID") -> 0 | Q17: =SUM(IF(C11="?",1,0),IF(C20="?",1,0),IF(C27="?",1,0),IF(C36="?",1,0),IF(C37="?",1,0),IF(F10="?",1,0),IF(F19="?",1,0),IF(F24="?",1,0)) -> 0
A18: Item | B18: =B17+1 -> 10 | D18: Item | E18: =E17+1 -> 40 | H18: =SUM(IF(C26="?",0,ROUND(C26/3,0)),IF(F14="?",0,ROUND(F14/3,0)),IF(F32="?",0,ROUND(F32/3,0))) -> 0 | I18: =IF(H18=0,"99",">99") -> 99 | K18: =IF(H18=0,"Acceptable","Questionable") -> Acceptable | N18: Plan/Organize | P18: =IF(Q18<2,SUM(C13,C15,C16,C17,C23,C29,F13,F15,F25,F30),"INVALID") -> 0 | Q18: =SUM(IF(C13="?",1,0),IF(C15="?",1,0),IF(C16="?",1,0),IF(C17="?",1,0),IF(C23="?",1,0),IF(C29="?",1,0),IF(F13="?",1,0),IF(F15="?",1,0),IF(F25="?",1,0),IF(F30="?",1,0)) -> 0
A19: Item | B19: =B18+1 -> 11 | D19: Item | E19: =E18+1 -> 41 | N19: CRI | P19: =IF(AND(Q16<2,Q17<2,Q18<2),SUM(P16:P18),"INVALID") -> 0 | Q19: =SUM(Q14:Q16) -> 0
A20: Item | B20: =B19+1 -> 12 | D20: Item | E20: =E19+1 -> 42 | H20: Inconsistency Scale: | N20: GEC | P20: =IF(P12="INVALID","INVALID",IF(P15="INVALID","INVALID",IF(P19="INVALID","INVALID",SUM(P12,P15,P19)))) -> 0 | Q20: =SUM(Q12,Q15,Q19) -> 0
A21: Item | B21: =B20+1 -> 13 | D21: Item | E21: =E20+1 -> 43 | H21: Score: | I21: Percentile: | K21: Classification:
A22: Item | B22: =B21+1 -> 14 | D22: Item | E22: =E21+1 -> 44 | H22: =SUM(L25:L32) -> 0 | I22: =IF(H22>10,">99",IF(H22<7,"≤98","99")) -> ≤98 | K22: =IF(H22>10,"Inconsistent",IF(H22<6,"Acceptable","Questionable")) -> Acceptable | N22: Scoring Summary Table
A23: Item | B23: =B22+1 -> 15 | D23: Item | E23: =E22+1 -> 45 | N23: Scale/Index/Comp | P23: Raw Score | Q23: T-Score | R23: %ile | S23: 90% CI
A24: Item | B24: =B23+1 -> 16 | D24: Item | E24: =E23+1 -> 46 | H24: Item no. | I24: Score | J24: Item no. | K24: Score | L24: Difference | N24: Inhibit | P24: =P10 -> 0 | Q24: ='Calc - Self'!D7 | R24: ='Calc - Self'!E7 | S24: ='Calc - Self'!F7 -> #VALUE! | T24: - | U24: ='Calc - Self'!G7 -> #VALUE!
A25: Item | B25: =B24+1 -> 17 | D25: Item | E25: =E24+1 -> 47 | H25: 1 | I25: =IF(C9="?",1,C9) -> 0 | J25: 12 | K25: =IF(C20="?",1,C20) -> 0 | L25: =ABS(I25-K25) -> 0 | N25: Self-Monitor | P25: =P11 -> 0 | Q25: ='Calc - Self'!D8 | R25: ='Calc - Self'!E8 | S25: ='Calc - Self'!F8 -> #VALUE! | T25: - | U25: ='Calc - Self'!G8 -> #VALUE!
A26: Item | B26: =B25+1 -> 18 | D26: Item | E26: =E25+1 -> 48 | H26: 6 | I26: =IF(C14="?",1,C14) -> 0 | J26: 14 | K26: =IF(C22="?",1,C22) -> 0 | L26: =ABS(I26-K26) -> 0 | N26: BRI | P26: =P12 -> 0 | Q26: ='Calc - Self'!D9 | R26: ='Calc - Self'!E9 | S26: ='Calc - Self'!F9 -> #VALUE! | T26: - | U26: ='Calc - Self'!G9 -> #VALUE!
A27: Item | B27: =B26+1 -> 19 | D27: Item | E27: =E26+1 -> 49 | H27: 22 | I27: =IF(C30="?",1,C30) -> 0 | J27: 27 | K27: =IF(C35="?",1,C35) -> 0 | L27: =ABS(I27-K27) -> 0 | N27: Shift | P27: =P13 -> 0 | Q27: ='Calc - Self'!D10 | R27: ='Calc - Self'!E10 | S27: ='Calc - Self'!F10 -> #VALUE! | T27: - | U27: ='Calc - Self'!G10 -> #VALUE!
A28: Item | B28: =B27+1 -> 20 | D28: Item | E28: =E27+1 -> 50 | H28: 23 | I28: =IF(C31="?",1,C31) -> 0 | J28: 52 | K28: =IF(F30="?",1,F30) -> 0 | L28: =ABS(I28-K28) -> 0 | N28: Emotional Control | P28: =P14 -> 0 | Q28: ='Calc - Self'!D11 | R28: ='Calc - Self'!E11 | S28: ='Calc - Self'!F11 -> #VALUE! | T28: - | U28: ='Calc - Self'!G11 -> #VALUE!
A29: Item | B29: =B28+1 -> 21 | D29: Item | E29: =E28+1 -> 51 | H29: 28 | I29: =IF(C36="?",1,C36) -> 0 | J29: 41 | K29: =IF(F19="?",1,F19) -> 0 | L29: =ABS(I29-K29) -> 0 | N29: ERI | P29: =P15 -> 0 | Q29: ='Calc - Self'!D12 | R29: ='Calc - Self'!E12 | S29: ='Calc - Self'!F12 -> #VALUE! | T29: - | U29: ='Calc - Self'!G12 -> #VALUE!
A30: Item | B30: =B29+1 -> 22 | D30: Item | E30: =E29+1 -> 52 | H30: 33 | I30: =IF(F11="?",1,F11) -> 0 | J30: 42 | K30: =IF(F20="?",1,F20) -> 0 | L30: =ABS(I30-K30) -> 0 | N30: Task Completion | P30: =P16 -> 0 | Q30: ='Calc - Self'!D13 | R30: ='Calc - Self'!E13 | S30: ='Calc - Self'!F13 -> #VALUE! | T30: - | U30: ='Calc - Self'!G13 -> #VALUE!
A31: Item | B31: =B30+1 -> 23 | D31: Item | E31: =E30+1 -> 53 | H31: 44 | I31: =IF(F22="?",1,F22) -> 0 | J31: 55 | K31: =IF(F33="?",1,F33) -> 0 | L31: =ABS(I31-K31) -> 0 | N31: Working Memory | P31: =P17 -> 0 | Q31: ='Calc - Self'!D14 | R31: ='Calc - Self'!E14 | S31: ='Calc - Self'!F14 -> #VALUE! | T31: - | U31: ='Calc - Self'!G14 -> #VALUE!
A32: Item | B32: =B31+1 -> 24 | D32: Item | E32: =E31+1 -> 54 | H32: 45 | I32: =IF(F23="?",1,F23) -> 0 | J32: 53 | K32: =IF(F31="?",1,F31) -> 0 | L32: =ABS(I32-K32) -> 0 | N32: Plan/Organize | P32: =P18 -> 0 | Q32: ='Calc - Self'!D15 | R32: ='Calc - Self'!E15 | S32: ='Calc - Self'!F15 -> #VALUE! | T32: - | U32: ='Calc - Self'!G15 -> #VALUE!
A33: Item | B33: =B32+1 -> 25 | D33: Item | E33: =E32+1 -> 55 | N33: CRI | P33: =P19 -> 0 | Q33: ='Calc - Self'!D16 | R33: ='Calc - Self'!E16 | S33: ='Calc - Self'!F16 -> #VALUE! | T33: - | U33: ='Calc - Self'!G16 -> #VALUE!
A34: Item | B34: 26 | N34: GEC | P34: =P20 -> 0 | Q34: ='Calc - Self'!D17 | R34: ='Calc - Self'!E17 | S34: ='Calc - Self'!F17 -> #VALUE! | T34: - | U34: ='Calc - Self'!G17 -> #VALUE!
A35: Item | B35: 27
A36: Item | B36: 28
A37: Item | B37: =B36+1 -> 29
A38: Item | B38: =B37+1 -> 30

Sheet Calc - Parent
B3: Age: | C3: =IF(Parent!K4="Select:","",Parent!K4) -> 5-7
B4: Gender: | C4: =IF(Parent!K5="Select:","",Parent!K5) -> Boys | D4: Column Adjust: | F4: =IF(C4="Girls",4,0) -> 0 | J4: Inhibition - T-Scores | R4: Self-Montor - T-Scores | Z4: Shift - T-Scores | AJ4: Inhibition - Percentiles | AR4: Self-Montor - Percentiles | AZ4: Shift - Percentiles
J5: Boys | N5: Girls | R5: Boys | V5: Girls | Z5: Boys | AD5: Girls | AJ5: Boys | AN5: Girls | AR5: Boys | AV5: Girls | AZ5: Boys | BD5: Girls
B6: Scale | C6: Raw | D6: T Score | E6: %ile | F6: 90% CI | I6: Raw | J6: 5-7 | K6: 8-10 | L6: 11-13 | M6: 14-18 | N6: 5-7 | O6: 8-10 | P6: 11-13 | Q6: 14-18 | R6: 5-7 | S6: 8-10 | T6: 11-13 | U6: 14-18 | V6: 5-7 | W6: 8-10 | X6: 11-13 | Y6: 14-18 | Z6: 5-7 | AA6: 8-10 | AB6: 11-13 | AC6: 14-18 | AD6: 5-7 | AE6: 8-10 | AF6: 11-13 | AG6: 14-18 | AI6: Raw | AJ6: 5-7 | AK6: 8-10 | AL6: 11-13 | AM6: 14-18 | AN6: 5-7 | AO6: 8-10 | AP6: 11-13 | AQ6: 14-18 | AR6: 5-7 | AS6: 8-10 | AT6: 11-13 | AU6: 14-18 | AV6: 5-7 | AW6: 8-10 | AX6: 11-13 | AY6: 14-18 | AZ6: 5-7 | BA6: 8-10 | BB6: 11-13 | BC6: 14-18 | BD6: 5-7 | BE6: 8-10 | BF6: 11-13 | BG6: 14-18
B7: Inhibit | C7: =Parent!P26 -> 0 | D7: =IFERROR(VLOOKUP(C7,I6:AG27,C25,FALSE),"") | E7: =IFERROR(VLOOKUP(C7,AI6:BG27,C25,FALSE),"") | F7: =D7-(VLOOKUP("CI",I28:AG28,C25,FALSE)) -> #VALUE! | G7: =D7+(VLOOKUP("CI",I28:AG28,C25,FALSE)) -> #VALUE! | I7: 24 | J7: 79 | K7: 79 | L7: 87 | M7: 88 | N7: 87 | O7: >90 | P7: >90 | Q7: >90 | Z7: 89 | AA7: >90 | AB7: >90 | AC7: >90 | AD7: >90 | AE7: >90 | AF7: >90 | AG7: >90 | AI7: 24 | AJ7: >99 | AK7: >99 | AL7: >99 | AM7: >99 | AN7: >99 | AO7: >99 | AP7: >99 | AQ7: >99 | AZ7: >99 | BA7: >99 | BB7: >99 | BC7: >99 | BD7: >99 | BE7: >99 | BF7: >99 | BG7: >99
B8: Self-Mon. | C8: =Parent!P27 -> 0 | D8: =IFERROR(VLOOKUP(C8,I6:AG27,C25+8,FALSE),"") | E8: =IFERROR(VLOOKUP(C8,AI6:BG27,C25+8,FALSE),"") | F8: =D8-(VLOOKUP("CI",I28:AG28,C25+8,FALSE)) -> #VALUE! | G8: =D8+(VLOOKUP("CI",I28:AG28,C25+8,FALSE)) -> #VALUE! | I8: 23 | J8: 77 | K8: 77 | L8: 84 | M8: 85 | N8: 84 | O8: 89 | P8: 89 | Q8: 89 | Z8: 86 | AA8: 88 | AB8: 88 | AC8: 88 | AD8: 90 | AE8: 90 | AF8: >90 | AG8: >90 | AI8: 23 | AJ8: 99 | AK8: >99 | AL8: >99 | AM8: >99 | AN8: 99 | AO8: >99 | AP8: >99 | AQ8: >99 | AZ8: >99 | BA8: >99 | BB8: >99 | BC8: >99 | BD8: >99 | BE8: >99 | BF8: >99 | BG8: >99
B9: BRI | C9: =Parent!P28 -> 0 | D9: =IFERROR(VLOOKUP(C9,I81:AG166,C25,FALSE),"") | E9: =IFERROR(VLOOKUP(C9,AI81:BG166,C25,FALSE),"") | F9: =D9-(VLOOKUP("CI",I167:AG167,C25,FALSE)) -> #VALUE! | G9: =D9+(VLOOKUP("CI",I167:AG167,C25,FALSE)) -> #VALUE! | I9: 22 | J9: 75 | K9: 75 | L9: 81 | M9: 82 | N9: 81 | O9: 85 | P9: 85 | Q9: 85 | Z9: 82 | AA9: 85 | AB9: 85 | AC9: 85 | AD9: 87 | AE9: 87 | AF9: 90 | AG9: 90 | AI9: 22 | AJ9: 99 | AK9: 99 | AL9: >99 | AM9: 99 | AN9: 99 | AO9: >99 | AP9: 99 | AQ9: 99 | AZ9: >99 | BA9: >99 | BB9: >99 | BC9: >99 | BD9: >99 | BE9: 99 | BF9: >99 | BG9: >99
B10: Shift | C10: =Parent!P29 -> 0 | D10: =IFERROR(VLOOKUP(C10,I6:AG27,C25+16,FALSE),"") | E10: =IFERROR(VLOOKUP(C10,AI6:BG27,C25+16,FALSE),"") | F10: =D10-(VLOOKUP("CI",I28:AG28,C25+16,FALSE)) -> #VALUE! | G10: =D10+(VLOOKUP("CI",I28:AG28,C25+16,FALSE)) -> #VALUE! | I10: 21 | J10: 72 | K10: 72 | L10: 78 | M10: 79 | N10: 78 | O10: 82 | P10: 82 | Q10: 82 | Z10: 79 | AA10: 82 | AB10: 82 | AC10: 82 | AD10: 84 | AE10: 84 | AF10: 86 | AG10: 86 | AI10: 21 | AJ10: 99 | AK10: 96 | AL10: 98 | AM10: 99 | AN10: 99 | AO10: >99 | AP10: 99 | AQ10: 98 | AZ10: 99 | BA10: 99 | BB10: >99 | BC10: >99 | BD10: 99 | BE10: 99 | BF10: >99 | BG10: 99
B11: Emo Ctrl. | C11: =Parent!P30 -> 0 | D11: =IFERROR(VLOOKUP(C11,I31:AG52,C25,FALSE),"") | E11: =IFERROR(VLOOKUP(C11,AI31:BG52,C25,FALSE),"") | F11: =D11-(VLOOKUP("CI",I53:AG53,C25,FALSE)) -> #VALUE! | G11: =D11+(VLOOKUP("CI",I53:AG53,C25,FALSE)) -> #VALUE! | I11: 20 | J11: 69 | K11: 69 | L11: 75 | M11: 76 | N11: 74 | O11: 79 | P11: 79 | Q11: 79 | Z11: 76 | AA11: 79 | AB11: 79 | AC11: 79 | AD11: 80 | AE11: 80 | AF11: 83 | AG11: 83 | AI11: 20 | AJ11: 96 | AK11: 94 | AL11: 97 | AM11: 99 | AN11: 99 | AO11: 99 | AP11: 99 | AQ11: 98 | AZ11: 99 | BA11: 99 | BB11: 99 | BC11: 99 | BD11: 99 | BE11: 99 | BF11: 99 | BG11: 99
B12: ERI | C12: =Parent!P31 -> 0 | D12: =IFERROR(VLOOKUP(C12,I81:AG166,C25+8,FALSE),"") | E12: =IFERROR(VLOOKUP(C12,AI81:BG166,C25+8,FALSE),"") | F12: =D12-(VLOOKUP("CI",I167:AG167,C25+8,FALSE)) -> #VALUE! | G12: =D12+(VLOOKUP("CI",I167:AG167,C25+8,FALSE)) -> #VALUE! | I12: 19 | J12: 66 | K12: 66 | L12: 72 | M12: 73 | N12: 71 | O12: 75 | P12: 75 | Q12: 76 | Z12: 73 | AA12: 76 | AB12: 76 | AC12: 76 | AD12: 77 | AE12: 77 | AF12: 79 | AG12: 79 | AI12: 19 | AJ12: 94 | AK12: 93 | AL12: 97 | AM12: 97 | AN12: 97 | AO12: 97 | AP12: 98 | AQ12: 98 | AZ12: 98 | BA12: 98 | BB12: 98 | BC12: 98 | BD12: 98 | BE12: 97 | BF12: 99 | BG12: 98
B13: Initiate | C13: =Parent!P32 -> 0 | D13: =IFERROR(VLOOKUP(C13,I31:AG52,C25+8,FALSE),"") | E13: =IFERROR(VLOOKUP(C13,AI31:BG52,C25+8,FALSE),"") | F13: =D13-(VLOOKUP("CI",I53:AG53,C25+8,FALSE)) -> #VALUE! | G13: =D13+(VLOOKUP("CI",I53:AG53,C25+8,FALSE)) -> #VALUE! | I13: 18 | J13: 63 | K13: 64 | L13: 69 | M13: 70 | N13: 68 | O13: 72 | P13: 72 | Q13: 73 | Z13: 70 | AA13: 72 | AB13: 72 | AC13: 72 | AD13: 72 | AE13: 72 | AF13: 76 | AG13: 76 | AI13: 18 | AJ13: 90 | AK13: 91 | AL13: 97 | AM13: 94 | AN13: 95 | AO13: 95 | AP13: 97 | AQ13: 97 | AZ13: 95 | BA13: 97 | BB13: 96 | BC13: 96 | BD13: 97 | BE13: 97 | BF13: 99 | BG13: 98
B14: Work Mem. | C14: =Parent!P33 -> 0 | D14: =IFERROR(VLOOKUP(C14,I31:AG52,C25+16,FALSE),"") | E14: =IFERROR(VLOOKUP(C14,AI31:BG52,C25+16,FALSE),"") | F14: =D14-(VLOOKUP("CI",I53:AG53,C25+16,FALSE)) -> #VALUE! | G14: =D14+(VLOOKUP("CI",I53:AG53,C25+16,FALSE)) -> #VALUE! | I14: 17 | J14: 61 | K14: 61 | L14: 66 | M14: 67 | N14: 65 | O14: 68 | P14: 68 | Q14: 69 | Z14: 67 | AA14: 69 | AB14: 69 | AC14: 69 | AD14: 71 | AE14: 71 | AF14: 72 | AG14: 72 | AI14: 17 | AJ14: 88 | AK14: 88 | AL14: 94 | AM14: 94 | AN14: 94 | AO14: 95 | AP14: 95 | AQ14: 95 | AZ14: 93 | BA14: 97 | BB14: 95 | BC14: 95 | BD14: 97 | BE14: 96 | BF14: 99 | BG14: 97
B15: Plan/Org. | C15: =Parent!P34 -> 0 | D15: =IFERROR(VLOOKUP(C15,I56:AG77,C25,FALSE),"") | E15: =IFERROR(VLOOKUP(C15,AI56:BG77,C25,FALSE),"") | F15: =D15-(VLOOKUP("CI",I78:AG78,C25,FALSE)) -> #VALUE! | G15: =D15+(VLOOKUP("CI",I78:AG78,C25,FALSE)) -> #VALUE! | I15: 16 | J15: 58 | K15: 59 | L15: 63 | M15: 64 | N15: 62 | O15: 65 | P15: 65 | Q15: 66 | Z15: 64 | AA15: 66 | AB15: 66 | AC15: 66 | AD15: 67 | AE15: 67 | AF15: 68 | AG15: 68 | AI15: 16 | AJ15: 85 | AK15: 84 | AL15: 93 | AM15: 92 | AN15: 90 | AO15: 93 | AP15: 94 | AQ15: 93 | AZ15: 91 | BA15: 94 | BB15: 93 | BC15: 94 | BD15: 97 | BE15: 95 | BF15: 97 | BG15: 94
B16: Task-Mon. | C16: =Parent!P35 -> 0 | D16: =IFERROR(VLOOKUP(C16,I56:AG77,C25+8,FALSE),"") | E16: =IFERROR(VLOOKUP(C16,AI56:BG77,C25+8,FALSE),"") | F16: =D16-(VLOOKUP("CI",I78:AG78,C25+8,FALSE)) -> #VALUE! | G16: =D16+(VLOOKUP("CI",I78:AG78,C25+8,FALSE)) -> #VALUE! | I16: 15 | J16: 55 | K16: 56 | L16: 60 | M16: 61 | N16: 59 | O16: 61 | P16: 62 | Q16: 63 | Z16: 61 | AA16: 62 | AB16: 62 | AC16: 63 | AD16: 62 | AE16: 62 | AF16: 65 | AG16: 65 | AI16: 15 | AJ16: 77 | AK16: 79 | AL16: 87 | AM16: 87 | AN16: 86 | AO16: 90 | AP16: 89 | AQ16: 91 | AZ16: 87 | BA16: 90 | BB16: 88 | BC16: 91 | BD16: 95 | BE16: 90 | BF16: 92 | BG16: 91
B17: Org. Mat. | C17: =Parent!P36 -> 0 | D17: =IFERROR(VLOOKUP(C17,I56:AG77,C25+16,FALSE),"") | E17: =IFERROR(VLOOKUP(C17,AI56:BG77,C25+16,FALSE),"") | F17: =D17-(VLOOKUP("CI",I78:AG78,C25+16,FALSE)) -> #VALUE! | G17: =D17+(VLOOKUP("CI",I78:AG78,C25+16,FALSE)) -> #VALUE! | I17: 14 | J17: 52 | K17: 53 | L17: 57 | M17: 58 | N17: 55 | O17: 58 | P17: 58 | Q17: 60 | Z17: 58 | AA17: 59 | AB17: 59 | AC17: 60 | AD17: 61 | AE17: 61 | AF17: 61 | AG17: 61 | AI17: 14 | AJ17: 67 | AK17: 71 | AL17: 81 | AM17: 83 | AN17: 77 | AO17: 86 | AP17: 85 | AQ17: 86 | AZ17: 85 | BA17: 85 | BB17: 82 | BC17: 86 | BD17: 91 | BE17: 84 | BF17: 88 | BG17: 88
B18: CRI | C18: =Parent!P37 -> 0 | D18: =IFERROR(VLOOKUP(C18,I81:AG166,C25+16,FALSE),"") | E18: =IFERROR(VLOOKUP(C18,AI81:BG166,C25+16,FALSE),"") | F18: =D18-(VLOOKUP("CI",I167:AG167,C25+16,FALSE)) -> #VALUE! | G18: =D18+(VLOOKUP("CI",I167:AG167,C25+16,FALSE)) -> #VALUE! | I18: 13 | J18: 50 | K18: 51 | L18: 54 | M18: 55 | N18: 52 | O18: 54 | P18: 55 | Q18: 57 | Z18: 55 | AA18: 56 | AB18: 56 | AC18: 57 | AD18: 56 | AE18: 56 | AF18: 58 | AG18: 58 | AI18: 13 | AJ18: 55 | AK18: 63 | AL18: 71 | AM18: 78 | AN18: 69 | AO18: 76 | AP18: 79 | AQ18: 83 | AZ18: 77 | BA18: 77 | BB18: 78 | BC18: 79 | BD18: 81 | BE18: 78 | BF18: 82 | BG18: 83
B19: GEC | C19: =Parent!P38 -> 0 | D19: =IFERROR(VLOOKUP(C19,I170:Q291,C25,FALSE),"") | E19: =IFERROR(VLOOKUP(C19,AI170:AQ291,C25,FALSE),"") | F19: =D19-(VLOOKUP("CI",I292:Q292,C25,FALSE)) -> #VALUE! | G19: =D19+(VLOOKUP("CI",I292:Q292,C25,FALSE)) -> #VALUE! | I19: 12 | J19: 47 | K19: 48 | L19: 51 | M19: 52 | N19: 49 | O19: 51 | P19: 51 | Q19: 54 | R19: 78 | S19: 78 | T19: 78 | U19: 78 | V19: 79 | W19: 79 | X19: 80 | Y19: 80 | Z19: 52 | AA19: 52 | AB19: 53 | AC19: 54 | AD19: 53 | AE19: 53 | AF19: 54 | AG19: 54 | AI19: 12 | AJ19: 45 | AK19: 53 | AL19: 61 | AM19: 74 | AN19: 58 | AO19: 69 | AP19: 69 | AQ19: 78 | AR19: >99 | AS19: >99 | AT19: >99 | AU19: >99 | AV19: >99 | AW19: >99 | AX19: >99 | AY19: >99 | AZ19: 68 | BA19: 69 | BB19: 76 | BC19: 73 | BD19: 75 | BE19: 71 | BF19: 73 | BG19: 78
I20: 11 | J20: 44 | K20: 45 | L20: 48 | M20: 49 | N20: 46 | O20: 48 | P20: 48 | Q20: 51 | R20: 74 | S20: 74 | T20: 74 | U20: 74 | V20: 74 | W20: 74 | X20: 75 | Y20: 75 | Z20: 49 | AA20: 49 | AB20: 50 | AC20: 50 | AD20: 49 | AE20: 49 | AF20: 50 | AG20: 51 | AI20: 11 | AJ20: 34 | AK20: 43 | AL20: 57 | AM20: 64 | AN20: 44 | AO20: 54 | AP20: 55 | AQ20: 70 | AR20: 98 | AS20: 97 | AT20: 99 | AU20: 99 | AV20: >99 | AW20: 99 | AX20: 99 | AY20: 99 | AZ20: 60 | BA20: 62 | BB20: 65 | BC20: 69 | BD20: 60 | BE20: 62 | BF20: 64 | BG20: 68
C21: 5-7 | D21: 8-10 | E21: 11-13 | F21: 14-18 | I21: 10 | J21: 41 | K21: 43 | L21: 45 | M21: 46 | N21: 43 | O21: 44 | P21: 45 | Q21: 47 | R21: 68 | S21: 68 | T21: 69 | U21: 69 | V21: 69 | W21: 69 | X21: 70 | Y21: 70 | Z21: 45 | AA21: 46 | AB21: 47 | AC21: 47 | AD21: 46 | AE21: 46 | AF21: 47 | AG21: 47 | AI21: 10 | AJ21: 27 | AK21: 35 | AL21: 45 | AM21: 56 | AN21: 33 | AO21: 39 | AP21: 39 | AQ21: 58 | AR21: 96 | AS21: 97 | AT21: 97 | AU21: 97 | AV21: 99 | AW21: 97 | AX21: 98 | AY21: 96 | AZ21: 47 | BA21: 51 | BB21: 54 | BC21: 58 | BD21: 49 | BE21: 51 | BF21: 52 | BG21: 58
B22: Boys | C22: 2 | D22: 3 | E22: 4 | F22: 5 | I22: 9 | J22: 38 | K22: 40 | L22: 42 | M22: 43 | N22: 40 | O22: 41 | P22: 41 | Q22: 44 | R22: 63 | S22: 63 | T22: 63 | U22: 63 | V22: 64 | W22: 64 | X22: 65 | Y22: 65 | Z22: 42 | AA22: 43 | AB22: 44 | AC22: 44 | AD22: 43 | AE22: 43 | AF22: 43 | AG22: 44 | AI22: 9 | AJ22: 19 | AK22: 24 | AL22: 35 | AM22: 42 | AN22: 20 | AO22: 24 | AP22: 30 | AQ22: 48 | AR22: 95 | AS22: 90 | AT22: 94 | AU22: 93 | AV22: 96 | AW22: 91 | AX22: 96 | AY22: 93 | AZ22: 34 | BA22: 36 | BB22: 42 | BC22: 48 | BD22: 36 | BE22: 37 | BF22: 39 | BG22: 43
B23: Girls | C23: 6 | D23: 7 | E23: 8 | F23: 9 | I23: 8 | J23: 36 | K23: 38 | L23: 39 | M23: 40 | N23: 36 | O23: 37 | P23: 38 | Q23: 41 | R23: 58 | S23: 58 | T23: 59 | U23: 59 | V23: 59 | W23: 59 | X23: 60 | Y23: 60 | Z23: 39 | AA23: 39 | AB23: 41 | AC23: 41 | AD23: 39 | AE23: 39 | AF23: 40 | AG23: 40 | AI23: 8 | AJ23: 10 | AK23: 12 | AL23: 14 | AM23: 23 | AN23: 12 | AO23: 12 | AP23: 15 | AQ23: 28 | AR23: 90 | AS23: 87 | AT23: 87 | AU23: 84 | AV23: 91 | AW23: 89 | AX23: 87 | AY23: 89 | AZ23: 21 | BA23: 20 | BB23: 31 | BC23: 31 | BD23: 22 | BE23: 20 | BF23: 26 | BG23: 26
I24: 7 | R24: 53 | S24: 54 | T24: 54 | U24: 54 | V24: 54 | W24: 54 | X24: 54 | Y24: 55 | AI24: 7 | AR24: 71 | AS24: 75 | AT24: 71 | AU24: 70 | AV24: 78 | AW24: 72 | AX24: 74 | AY24: 79
B25: Final Column: | C25: =IFERROR(INDEX(B21:F23,MATCH(C4,B21:B23,0),MATCH(C3,B21:F21,0)),"") -> 2 | I25: 6 | R25: 48 | S25: 49 | T25: 49 | U25: 49 | V25: 49 | W25: 49 | X25: 49 | Y25: 50 | AI25: 6 | AR25: 50 | AS25: 60 | AT25: 61 | AU25: 57 | AV25: 62 | AW25: 61 | AX25: 58 | AY25: 64
I26: 5 | R26: 43 | S26: 44 | T26: 44 | U26: 44 | V26: 44 | W26: 44 | X26: 44 | Y26: 45 | AI26: 5 | AR26: 37 | AS26: 45 | AT26: 46 | AU26: 46 | AV26: 48 | AW26: 47 | AX26: 45 | AY26: 50
I27: 4 | R27: 38 | S27: 39 | T27: 39 | U27: 39 | V27: 39 | W27: 39 | X27: 39 | Y27: 40 | AI27: 4 | AR27: 23 | AS27: 25 | AT27: 22 | AU27: 28 | AV27: 26 | AW27: 28 | AX27: 26 | AY27: 29
I28: CI | J28: 6 | K28: 6 | L28: 6 | M28: 6 | N28: 7 | O28: 7 | P28: 7 | Q28: 6 | R28: 7 | S28: 7 | T28: 8 | U28: 7 | V28: 9 | W28: 7 | X28: 8 | Y28: 8 | Z28: 6 | AA28: 7 | AB28: 6 | AC28: 6 | AD28: 7 | AE28: 7 | AF28: 7 | AG28: 7
J29: Emotional Control - T-Scores | R29: Initiate - T-Scores | Z29: Working Memory - T-Scores | AJ29: Emotional Control - Percentiles | AR29: Initiate - Percentiles | AZ29: Working Memory - Percentiles
J30: Boys | N30: Girls | R30: Boys | V30: Girls | Z30: Boys | AD30: Girls | AJ30: Boys | AN30: Girls | AR30: Boys | AV30: Girls | AZ30: Boys | BD30: Girls
I31: Raw | J31: 5-7 | K31: 8-10 | L31: 11-13 | M31: 14-18 | N31: 5-7 | O31: 8-10 | P31: 11-13 | Q31: 14-18 | R31: 5-7 | S31: 8-10 | T31: 11-13 | U31: 14-18 | V31: 5-7 | W31: 8-10 | X31: 11-13 | Y31: 14-18 | Z31: 5-7 | AA31: 8-10 | AB31: 11-13 | AC31: 14-18 | AD31: 5-7 | AE31: 8-10 | AF31: 11-13 | AG31: 14-18 | AI31: Raw | AJ31: 5-7 | AK31: 8-10 | AL31: 11-13 | AM31: 14-18 | AN31: 5-7 | AO31: 8-10 | AP31: 11-13 | AQ31: 14-18 | AR31: 5-7 | AS31: 8-10 | AT31: 11-13 | AU31: 14-18 | AV31: 5-7 | AW31: 8-10 | AX31: 11-13 | AY31: 14-18 | AZ31: 5-7 | BA31: 8-10 | BB31: 11-13 | BC31: 14-18 | BD31: 5-7 | BE31: 8-10 | BF31: 11-13 | BG31: 14-18
I32: 24 | J32: 82 | K32: 84 | L32: 84 | M32: 84 | N32: 83 | O32: 83 | P32: 83 | Q32: 83 | Z32: 80 | AA32: 80 | AB32: 85 | AC32: 85 | AD32: 83 | AE32: 83 | AF32: 83 | AG32: 87 | AI32: 24 | AJ32: >99 | AK32: >99 | AL32: >99 | AM32: >99 | AN32: >99 | AO32: >99 | AP32: >99 | AQ32: >99 | AZ32: >99 | BA32: >99 | BB32: >99 | BC32: >99 | BD32: >99 | BE32: >99 | BF32: >99 | BG32: >99
I33: 23 | J33: 79 | K33: 81 | L33: 82 | M33: 82 | N33: 80 | O33: 80 | P33: 80 | Q33: 80 | Z33: 77 | AA33: 77 | AB33: 82 | AC33: 82 | AD33: 80 | AE33: 80 | AF33: 80 | AG33: 84 | AI33: 23 | AJ33: 99 | AK33: >99 | AL33: 99 | AM33: >99 | AN33: >99 | AO33: >99 | AP33: >99 | AQ33: 99 | AZ33: >99 | BA33: >99 | BB33: >99 | BC33: >99 | BD33: >99 | BE33: 99 | BF33: 99 | BG33: >99
I34: 22 | J34: 77 | K34: 78 | L34: 80 | M34: 80 | N34: 77 | O34: 77 | P34: 78 | Q34: 78 | Z34: 74 | AA34: 74 | AB34: 77 | AC34: 77 | AD34: 77 | AE34: 77 | AF34: 78 | AG34: 82 | AI34: 22 | AJ34: 99 | AK34: >99 | AL34: 99 | AM34: 99 | AN34: 99 | AO34: >99 | AP34: 99 | AQ34: 98 | AZ34: >99 | BA34: 99 | BB34: 99 | BC34: 99 | BD34: >99 | BE34: 99 | BF34: 99 | BG34: >99
I35: 21 | J35: 74 | K35: 76 | L35: 76 | M35: 76 | N35: 75 | O35: 75 | P35: 75 | Q35: 75 | Z35: 72 | AA35: 72 | AB35: 76 | AC35: 76 | AD35: 75 | AE35: 75 | AF35: 75 | AG35: 79 | AI35: 21 | AJ35: 98 | AK35: 97 | AL35: 97 | AM35: 98 | AN35: 99 | AO35: 98 | AP35: 99 | AQ35: 97 | AZ35: >99 | BA35: 97 | BB35: 99 | BC35: 98 | BD35: 99 | BE35: 99 | BF35: 99 | BG35: 99
I36: 20 | J36: 71 | K36: 73 | L36: 74 | M36: 74 | N36: 72 | O36: 72 | P36: 74 | Q36: 74 | Z36: 69 | AA36: 69 | AB36: 72 | AC36: 72 | AD36: 72 | AE36: 72 | AF36: 72 | AG36: 76 | AI36: 20 | AJ36: 97 | AK36: 96 | AL36: 96 | AM36: 96 | AN36: 98 | AO36: 97 | AP36: 99 | AQ36: 96 | AZ36: 99 | BA36: 94 | BB36: 97 | BC36: 98 | BD36: 97 | BE36: 98 | BF36: 99 | BG36: 98
I37: 19 | J37: 69 | K37: 70 | L37: 72 | M37: 72 | N37: 70 | O37: 70 | P37: 71 | Q37: 71 | Z37: 66 | AA37: 66 | AB37: 71 | AC37: 71 | AD37: 69 | AE37: 69 | AF37: 70 | AG37: 73 | AI37: 19 | AJ37: 95 | AK37: 96 | AL37: 95 | AM37: 96 | AN37: 96 | AO37: 94 | AP37: 99 | AQ37: 94 | AZ37: 96 | BA37: 90 | BB37: 96 | BC37: 96 | BD37: 97 | BE37: 96 | BF37: 97 | BG37: 97
I38: 18 | J38: 66 | K38: 67 | L38: 68 | M38: 68 | N38: 67 | O38: 67 | P38: 68 | Q38: 68 | Z38: 64 | AA38: 64 | AB38: 67 | AC38: 67 | AD38: 66 | AE38: 66 | AF38: 67 | AG38: 70 | AI38: 18 | AJ38: 94 | AK38: 93 | AL38: 94 | AM38: 94 | AN38: 95 | AO38: 93 | AP38: 95 | AQ38: 92 | AZ38: 93 | BA38: 86 | BB38: 95 | BC38: 94 | BD38: 94 | BE38: 92 | BF38: 95 | BG38: 95
I39: 17 | J39: 64 | K39: 65 | L39: 66 | M39: 66 | N39: 64 | O39: 64 | P39: 65 | Q39: 65 | Z39: 63 | AA39: 63 | AB39: 65 | AC39: 65 | AD39: 64 | AE39: 64 | AF39: 64 | AG39: 67 | AI39: 17 | AJ39: 91 | AK39: 93 | AL39: 94 | AM39: 94 | AN39: 92 | AO39: 92 | AP39: 93 | AQ39: 89 | AZ39: 92 | BA39: 84 | BB39: 94 | BC39: 92 | BD39: 94 | BE39: 89 | BF39: 92 | BG39: 92
I40: 16 | J40: 61 | K40: 62 | L40: 64 | M40: 64 | N40: 62 | O40: 62 | P40: 62 | Q40: 62 | Z40: 59 | AA40: 59 | AB40: 61 | AC40: 61 | AD40: 61 | AE40: 61 | AF40: 61 | AG40: 64 | AI40: 16 | AJ40: 89 | AK40: 88 | AL40: 92 | AM40: 90 | AN40: 91 | AO40: 88 | AP40: 90 | AQ40: 86 | AZ40: 88 | BA40: 78 | BB40: 92 | BC40: 88 | BD40: 92 | BE40: 84 | BF40: 88 | BG40: 90
I41: 15 | J41: 59 | K41: 59 | L41: 60 | M41: 60 | N41: 59 | O41: 59 | P41: 60 | Q41: 60 | R41: 79 | S41: 79 | T41: 79 | U41: 79 | V41: 84 | W41: 84 | X41: 84 | Y41: 84 | Z41: 55 | AA41: 55 | AB41: 59 | AC41: 59 | AD41: 58 | AE41: 58 | AF41: 59 | AG41: 62 | AI41: 15 | AJ41: 86 | AK41: 84 | AL41: 86 | AM41: 84 | AN41: 85 | AO41: 83 | AP41: 82 | AQ41: 81 | AR41: >99 | AS41: >99 | AT41: >99 | AU41: >99 | AV41: >99 | AW41: >99 | AX41: >99 | AY41: >99 | AZ41: 80 | BA41: 74 | BB41: 85 | BC41: 81 | BD41: 90 | BE41: 84 | BF41: 85 | BG41: 88
I42: 14 | J42: 56 | K42: 57 | L42: 58 | M42: 58 | N42: 56 | O42: 56 | P42: 56 | Q42: 56 | R42: 75 | S42: 75 | T42: 75 | U42: 75 | V42: 79 | W42: 79 | X42: 79 | Y42: 79 | Z42: 52 | AA42: 52 | AB42: 56 | AC42: 56 | AD42: 55 | AE42: 55 | AF42: 56 | AG42: 59 | AI42: 14 | AJ42: 75 | AK42: 79 | AL42: 81 | AM42: 80 | AN42: 80 | AO42: 79 | AP42: 75 | AQ42: 76 | AR42: >99 | AS42: >99 | AT42: 99 | AU42: >99 | AV42: >99 | AW42: 99 | AX42: 99 | AY42: 99 | AZ42: 76 | BA42: 68 | BB42: 78 | BC42: 74 | BD42: 86 | BE42: 77 | BF42: 78 | BG42: 85
...

Sheet Calc - Teacher
B3: Age: | C3: =IF(Parent!K4="Select:","",Parent!K4) -> 5-7
B4: Gender: | C4: =IF(Parent!K5="Select:","",Parent!K5) -> Boys | D4: Column Adjust: | F4: =IF(C4="Girls",4,0) -> 0 | J4: Inhibition - T-Scores | R4: Self-Montor - T-Scores | Z4: Shift - T-Scores | AJ4: Inhibition - Percentiles | AR4: Self-Montor - Percentiles | AZ4: Shift - Percentiles
J5: Boys | N5: Girls | R5: Boys | V5: Girls | Z5: Boys | AD5: Girls | AJ5: Boys | AN5: Girls | AR5: Boys | AV5: Girls | AZ5: Boys | BD5: Girls
B6: Scale | C6: Raw | D6: T Score | E6: %ile | F6: 90% CI | I6: Raw | J6: 5-7 | K6: 8-10 | L6: 11-13 | M6: 14-18 | N6: 5-7 | O6: 8-10 | P6: 11-13 | Q6: 14-18 | R6: 5-7 | S6: 8-10 | T6: 11-13 | U6: 14-18 | V6: 5-7 | W6: 8-10 | X6: 11-13 | Y6: 14-18 | Z6: 5-7 | AA6: 8-10 | AB6: 11-13 | AC6: 14-18 | AD6: 5-7 | AE6: 8-10 | AF6: 11-13 | AG6: 14-18 | AI6: Raw | AJ6: 5-7 | AK6: 8-10 | AL6: 11-13 | AM6: 14-18 | AN6: 5-7 | AO6: 8-10 | AP6: 11-13 | AQ6: 14-18 | AR6: 5-7 | AS6: 8-10 | AT6: 11-13 | AU6: 14-18 | AV6: 5-7 | AW6: 8-10 | AX6: 11-13 | AY6: 14-18 | AZ6: 5-7 | BA6: 8-10 | BB6: 11-13 | BC6: 14-18 | BD6: 5-7 | BE6: 8-10 | BF6: 11-13 | BG6: 14-18
B7: Inhibit | C7: =Teacher!P10 -> 0 | D7: =IFERROR(VLOOKUP(C7,I6:AG27,C25,FALSE),"") | E7: =IFERROR(VLOOKUP(C7,AI6:BG27,C25,FALSE),"") | F7: =D7-(VLOOKUP("CI",I28:AG28,C25,FALSE)) -> #VALUE! | G7: =D7+(VLOOKUP("CI",I28:AG28,C25,FALSE)) -> #VALUE! | I7: 24 | AI7: 24
B8: Self-Mon. | C8: =Teacher!P11 -> 0 | D8: =IFERROR(VLOOKUP(C8,I6:AG27,C25+8,FALSE),"") | E8: =IFERROR(VLOOKUP(C8,AI6:BG27,C25+8,FALSE),"") | F8: =D8-(VLOOKUP("CI",I28:AG28,C25+8,FALSE)) -> #VALUE! | G8: =D8+(VLOOKUP("CI",I28:AG28,C25+8,FALSE)) -> #VALUE! | I8: 23 | AI8: 23
B9: BRI | C9: =Teacher!P12 -> 0 | D9: =IFERROR(VLOOKUP(C9,I81:AG166,C25,FALSE),"") | E9: =IFERROR(VLOOKUP(C9,AI81:BG166,C25,FALSE),"") | F9: =D9-(VLOOKUP("CI",I167:AG167,C25,FALSE)) -> #VALUE! | G9: =D9+(VLOOKUP("CI",I167:AG167,C25,FALSE)) -> #VALUE! | I9: 22 | AI9: 22
B10: Shift | C10: =Teacher!P13 -> 0 | D10: =IFERROR(VLOOKUP(C10,I6:AG27,C25+16,FALSE),"") | E10: =IFERROR(VLOOKUP(C10,AI6:BG27,C25+16,FALSE),"") | F10: =D10-(VLOOKUP("CI",I28:AG28,C25+16,FALSE)) -> #VALUE! | G10: =D10+(VLOOKUP("CI",I28:AG28,C25+16,FALSE)) -> #VALUE! | I10: 21 | AI10: 21
B11: Emo Ctrl. | C11: =Teacher!P14 -> 0 | D11: =IFERROR(VLOOKUP(C11,I31:AG52,C25,FALSE),"") | E11: =IFERROR(VLOOKUP(C11,AI31:BG52,C25,FALSE),"") | F11: =D11-(VLOOKUP("CI",I53:AG53,C25,FALSE)) -> #VALUE! | G11: =D11+(VLOOKUP("CI",I53:AG53,C25,FALSE)) -> #VALUE! | I11: 20 | AI11: 20
B12: ERI | C12: =Teacher!P15 -> 0 | D12: =IFERROR(VLOOKUP(C12,I81:AG166,C25+8,FALSE),"") | E12: =IFERROR(VLOOKUP(C12,AI81:BG166,C25+8,FALSE),"") | F12: =D12-(VLOOKUP("CI",I167:AG167,C25+8,FALSE)) -> #VALUE! | G12: =D12+(VLOOKUP("CI",I167:AG167,C25+8,FALSE)) -> #VALUE! | I12: 19 | AI12: 19
B13: Initiate | C13: =Teacher!P16 -> 0 | D13: =IFERROR(VLOOKUP(C13,I31:AG52,C25+8,FALSE),"") | E13: =IFERROR(VLOOKUP(C13,AI31:BG52,C25+8,FALSE),"") | F13: =D13-(VLOOKUP("CI",I53:AG53,C25+8,FALSE)) -> #VALUE! | G13: =D13+(VLOOKUP("CI",I53:AG53,C25+8,FALSE)) -> #VALUE! | I13: 18 | AI13: 18
B14: Work Mem. | C14: =Teacher!P17 -> 0 | D14: =IFERROR(VLOOKUP(C14,I31:AG52,C25+16,FALSE),"") | E14: =IFERROR(VLOOKUP(C14,AI31:BG52,C25+16,FALSE),"") | F14: =D14-(VLOOKUP("CI",I53:AG53,C25+16,FALSE)) -> #VALUE! | G14: =D14+(VLOOKUP("CI",I53:AG53,C25+16,FALSE)) -> #VALUE! | I14: 17 | AI14: 17
B15: Plan/Org. | C15: =Teacher!P18 -> 0 | D15: =IFERROR(VLOOKUP(C15,I56:AG77,C25,FALSE),"") | E15: =IFERROR(VLOOKUP(C15,AI56:BG77,C25,FALSE),"") | F15: =D15-(VLOOKUP("CI",I78:AG78,C25,FALSE)) -> #VALUE! | G15: =D15+(VLOOKUP("CI",I78:AG78,C25,FALSE)) -> #VALUE! | I15: 16 | AI15: 16
B16: Task-Mon. | C16: =Teacher!P19 -> 0 | D16: =IFERROR(VLOOKUP(C16,I56:AG77,C25+8,FALSE),"") | E16: =IFERROR(VLOOKUP(C16,AI56:BG77,C25+8,FALSE),"") | F16: =D16-(VLOOKUP("CI",I78:AG78,C25+8,FALSE)) -> #VALUE! | G16: =D16+(VLOOKUP("CI",I78:AG78,C25+8,FALSE)) -> #VALUE! | I16: 15 | AI16: 15
B17: Org. Mat. | C17: =Teacher!P20 -> 0 | D17: =IFERROR(VLOOKUP(C17,I56:AG77,C25+16,FALSE),"") | E17: =IFERROR(VLOOKUP(C17,AI56:BG77,C25+16,FALSE),"") | F17: =D17-(VLOOKUP("CI",I78:AG78,C25+16,FALSE)) -> #VALUE! | G17: =D17+(VLOOKUP("CI",I78:AG78,C25+16,FALSE)) -> #VALUE! | I17: 14 | AI17: 14
B18: CRI | C18: =Teacher!P21 -> 0 | D18: =IFERROR(VLOOKUP(C18,I81:AG166,C25+16,FALSE),"") | E18: =IFERROR(VLOOKUP(C18,AI81:BG166,C25+16,FALSE),"") | F18: =D18-(VLOOKUP("CI",I167:AG167,C25+16,FALSE)) -> #VALUE! | G18: =D18+(VLOOKUP("CI",I167:AG167,C25+16,FALSE)) -> #VALUE! | I18: 13 | AI18: 13
B19: GEC | C19: =Teacher!P22 -> 0 | D19: =IFERROR(VLOOKUP(C19,I170:Q291,C25,FALSE),"") | E19: =IFERROR(VLOOKUP(C19,AI170:AQ291,C25,FALSE),"") | F19: =D19-(VLOOKUP("CI",I292:Q292,C25,FALSE)) -> #VALUE! | G19: =D19+(VLOOKUP("CI",I292:Q292,C25,FALSE)) -> #VALUE! | I19: 12 | AI19: 12
I20: 11 | AI20: 11
C21: 5-7 | D21: 8-10 | E21: 11-13 | F21: 14-18 | I21: 10 | AI21: 10
B22: Boys | C22: 2 | D22: 3 | E22: 4 | F22: 5 | I22: 9 | AI22: 9
B23: Girls | C23: 6 | D23: 7 | E23: 8 | F23: 9 | I23: 8 | AI23: 8
I24: 7 | AI24: 7
B25: Final Column: | C25: =IFERROR(INDEX(B21:F23,MATCH(C4,B21:B23,0),MATCH(C3,B21:F21,0)),"") -> 2 | I25: 6 | AI25: 6
I26: 5 | AI26: 5
I27: 4 | AI27: 4
I28: CI
J29: Emotional Control - T-Scores | R29: Initiate - T-Scores | Z29: Working Memory - T-Scores | AJ29: Emotional Control - Percentiles | AR29: Initiate - Percentiles | AZ29: Working Memory - Percentiles
J30: Boys | N30: Girls | R30: Boys | V30: Girls | Z30: Boys | AD30: Girls | AJ30: Boys | AN30: Girls | AR30: Boys | AV30: Girls | AZ30: Boys | BD30: Girls
I31: Raw | J31: 5-7 | K31: 8-10 | L31: 11-13 | M31: 14-18 | N31: 5-7 | O31: 8-10 | P31: 11-13 | Q31: 14-18 | R31: 5-7 | S31: 8-10 | T31: 11-13 | U31: 14-18 | V31: 5-7 | W31: 8-10 | X31: 11-13 | Y31: 14-18 | Z31: 5-7 | AA31: 8-10 | AB31: 11-13 | AC31: 14-18 | AD31: 5-7 | AE31: 8-10 | AF31: 11-13 | AG31: 14-18 | AI31: Raw | AJ31: 5-7 | AK31: 8-10 | AL31: 11-13 | AM31: 14-18 | AN31: 5-7 | AO31: 8-10 | AP31: 11-13 | AQ31: 14-18 | AR31: 5-7 | AS31: 8-10 | AT31: 11-13 | AU31: 14-18 | AV31: 5-7 | AW31: 8-10 | AX31: 11-13 | AY31: 14-18 | AZ31: 5-7 | BA31: 8-10 | BB31: 11-13 | BC31: 14-18 | BD31: 5-7 | BE31: 8-10 | BF31: 11-13 | BG31: 14-18
I32: 24 | AI32: 24
I33: 23 | AI33: 23
I34: 22 | AI34: 22
I35: 21 | AI35: 21
I36: 20 | AI36: 20
I37: 19 | AI37: 19
I38: 18 | AI38: 18
I39: 17 | AI39: 17
I40: 16 | AI40: 16
I41: 15 | AI41: 15
I42: 14 | AI42: 14
...

Sheet Calc - Self
B3: Age: | C3: =IF(Self!K4="Select:","",Self!K4) -> 14-18
B4: Gender: | C4: =IF(Self!K5="Select:","",Self!K5) -> Boys | D4: Column Adjust: | F4: =IF(C4="Girls",4,0) -> 0 | J4: Inhibition - T-Scores | R4: Self-Montor - T-Scores | Z4: Shift - T-Scores | AJ4: Inhibition - Percentiles | AR4: Self-Montor - Percentiles | AZ4: Shift - Percentiles
J5: Boys | N5: Girls | R5: Boys | V5: Girls | Z5: Boys | AD5: Girls | AJ5: Boys | AN5: Girls | AR5: Boys | AV5: Girls | AZ5: Boys | BD5: Girls
B6: Scale | C6: Raw | D6: T Score | E6: %ile | F6: 90% CI | I6: Raw | J6: 5-7 | K6: 8-10 | L6: 11-13 | M6: 14-18 | N6: 5-7 | O6: 8-10 | P6: 11-13 | Q6: 14-18 | R6: 5-7 | S6: 8-10 | T6: 11-13 | U6: 14-18 | V6: 5-7 | W6: 8-10 | X6: 11-13 | Y6: 14-18 | Z6: 5-7 | AA6: 8-10 | AB6: 11-13 | AC6: 14-18 | AD6: 5-7 | AE6: 8-10 | AF6: 11-13 | AG6: 14-18 | AI6: Raw | AJ6: 5-7 | AK6: 8-10 | AL6: 11-13 | AM6: 14-18 | AN6: 5-7 | AO6: 8-10 | AP6: 11-13 | AQ6: 14-18 | AR6: 5-7 | AS6: 8-10 | AT6: 11-13 | AU6: 14-18 | AV6: 5-7 | AW6: 8-10 | AX6: 11-13 | AY6: 14-18 | AZ6: 5-7 | BA6: 8-10 | BB6: 11-13 | BC6: 14-18 | BD6: 5-7 | BE6: 8-10 | BF6: 11-13 | BG6: 14-18
B7: Inhibit | C7: =Self!P24 -> 0 | D7: =IFERROR(VLOOKUP(C7,I6:AG26,C25,FALSE),"") | E7: =IFERROR(VLOOKUP(C7,AI6:BG26,C25,FALSE),"") | F7: =D7-(VLOOKUP("CI",I27:AG27,C25,FALSE)) -> #VALUE! | G7: =D7+(VLOOKUP("CI",I27:AG27,C25,FALSE)) -> #VALUE! | I7: 24 | L7: 84 | M7: >90 | P7: 85 | Q7: 90 | AB7: 88 | AC7: >90 | AF7: >90 | AG7: >90 | AI7: 24 | AL7: >99 | AM7: >99 | AP7: >99 | AQ7: >99 | BB7: >99 | BC7: >99 | BF7: >99 | BG7: >99
B8: Self-Mon. | C8: =Self!P25 -> 0 | D8: =IFERROR(VLOOKUP(C8,I6:AG26,C25+8,FALSE),"") | E8: =IFERROR(VLOOKUP(C8,AI6:BG26,C25+8,FALSE),"") | F8: =D8-(VLOOKUP("CI",I27:AG27,C25+8,FALSE)) -> #VALUE! | G8: =D8+(VLOOKUP("CI",I27:AG27,C25+8,FALSE)) -> #VALUE! | I8: 23 | L8: 81 | M8: 88 | P8: 82 | Q8: 86 | AB8: 84 | AC8: >90 | AF8: 85 | AG8: 85 | AI8: 23 | AL8: 99 | AM8: >99 | AP8: >99 | AQ8: >99 | BB8: >99 | BC8: >99 | BF8: >99 | BG8: >99
B9: BRI | C9: =Self!P26 -> 0 | D9: =IFERROR(VLOOKUP(C9,I78:AG141,C25,FALSE),"") | E9: =IFERROR(VLOOKUP(C9,AI78:BG141,C25,FALSE),"") | F9: =D9-(VLOOKUP("CI",I142:AG142,C25,FALSE)) -> #VALUE! | G9: =D9+(VLOOKUP("CI",I142:AG142,C25,FALSE)) -> #VALUE! | I9: 22 | L9: 78 | M9: 85 | P9: 79 | Q9: 83 | AB9: 81 | AC9: 89 | AF9: 84 | AG9: 84 | AI9: 22 | AL9: 99 | AM9: >99 | AP9: >99 | AQ9: >99 | BB9: >99 | BC9: >99 | BF9: >99 | BG9: >99
B10: Shift | C10: =Self!P27 -> 0 | D10: =IFERROR(VLOOKUP(C10,I6:AG26,C25+16,FALSE),"") | E10: =IFERROR(VLOOKUP(C10,AI6:BG26,C25+16,FALSE),"") | F10: =D10-(VLOOKUP("CI",I27:AG27,C25+16,FALSE)) -> #VALUE! | G10: =D10+(VLOOKUP("CI",I27:AG27,C25+16,FALSE)) -> #VALUE! | I10: 21 | L10: 75 | M10: 82 | P10: 76 | Q10: 80 | AB10: 78 | AC10: 86 | AF10: 79 | AG10: 79 | AI10: 21 | AL10: 99 | AM10: >99 | AP10: >99 | AQ10: >99 | BB10: >99 | BC10: >99 | BF10: >99 | BG10: 99
B11: Emo Ctrl. | C11: =Self!P28 -> 0 | D11: =IFERROR(VLOOKUP(C11,I30:AG49,C25,FALSE),"") | E11: =IFERROR(VLOOKUP(C11,AI30:BG49,C25,FALSE),"") | F11: =D11-(VLOOKUP("CI",I50:AG50,C25,FALSE)) -> #VALUE! | G11: =D11+(VLOOKUP("CI",I50:AG50,C25,FALSE)) -> #VALUE! | I11: 20 | L11: 72 | M11: 78 | P11: 73 | Q11: 77 | AB11: 75 | AC11: 83 | AF11: 78 | AG11: 78 | AI11: 20 | AL11: 99 | AM11: >99 | AP11: 99 | AQ11: 98 | BB11: >99 | BC11: >99 | BF11: >99 | BG11: 99
B12: ERI | C12: =Self!P29 -> 0 | D12: =IFERROR(VLOOKUP(C12,I78:AG141,C25+8,FALSE),"") | E12: =IFERROR(VLOOKUP(C12,AI78:BG141,C25+8,FALSE),"") | F12: =D12-(VLOOKUP("CI",I142:AG142,C25+8,FALSE)) -> #VALUE! | G12: =D12+(VLOOKUP("CI",I142:AG142,C25+8,FALSE)) -> #VALUE! | I12: 19 | L12: 69 | M12: 75 | P12: 70 | Q12: 74 | AB12: 72 | AC12: 79 | AF12: 73 | AG12: 73 | AI12: 19 | AL12: 97 | AM12: >99 | AP12: 97 | AQ12: 98 | BB12: 99 | BC12: >99 | BF12: >99 | BG12: 98
B13: Task Com. | C13: =Self!P30 -> 0 | D13: =IFERROR(VLOOKUP(C13,I30:AG49,C25+8,FALSE),"") | E13: =IFERROR(VLOOKUP(C13,AI30:BG49,C25+8,FALSE),"") | F13: =D13-(VLOOKUP("CI",I50:AG50,C25+8,FALSE)) -> #VALUE! | G13: =D13+(VLOOKUP("CI",I50:AG50,C25+8,FALSE)) -> #VALUE! | I13: 18 | L13: 67 | M13: 72 | P13: 67 | Q13: 70 | AB13: 69 | AC13: 76 | AF13: 71 | AG13: 71 | AI13: 18 | AL13: 94 | AM13: 98 | AP13: 95 | AQ13: 97 | BB13: 97 | BC13: >99 | BF13: 99 | BG13: 97
B14: Work Mem. | C14: =Self!P31 -> 0 | D14: =IFERROR(VLOOKUP(C14,I30:AG49,C25+16,FALSE),"") | E14: =IFERROR(VLOOKUP(C14,AI30:BG49,C25+16,FALSE),"") | F14: =D14-(VLOOKUP("CI",I50:AG50,C25+16,FALSE)) -> #VALUE! | G14: =D14+(VLOOKUP("CI",I50:AG50,C25+16,FALSE)) -> #VALUE! | I14: 17 | L14: 64 | M14: 69 | P14: 64 | Q14: 67 | AB14: 66 | AC14: 72 | AF14: 67 | AG14: 67 | AI14: 17 | AL14: 92 | AM14: 96 | AP14: 92 | AQ14: 96 | BB14: 93 | BC14: 98 | BF14: 97 | BG14: 94
B15: Plan/Org. | C15: =Self!P32 -> 0 | D15: =IFERROR(VLOOKUP(C15,I53:AG74,C25,FALSE),"") | E15: =IFERROR(VLOOKUP(C15,AI53:BG74,C25,FALSE),"") | F15: =D15-(VLOOKUP("CI",I75:AG75,C25,FALSE)) -> #VALUE! | G15: =D15+(VLOOKUP("CI",I75:AG75,C25,FALSE)) -> #VALUE! | I15: 16 | L15: 61 | M15: 66 | P15: 61 | Q15: 64 | AB15: 63 | AC15: 69 | AF15: 64 | AG15: 64 | AI15: 16 | AL15: 89 | AM15: 94 | AP15: 88 | AQ15: 93 | BB15: 90 | BC15: 96 | BF15: 95 | BG15: 92
B16: CRI | C16: =Self!P33 -> 0 | D16: =IFERROR(VLOOKUP(C16,I78:AG141,C25+16,FALSE),"") | E16: =IFERROR(VLOOKUP(C16,AI78:BG141,C25+16,FALSE),"") | F16: =D16-(VLOOKUP("CI",I142:AG142,C25+16,FALSE)) -> #VALUE! | G16: =D16+(VLOOKUP("CI",I142:AG142,C25+16,FALSE)) -> #VALUE! | I16: 15 | L16: 58 | M16: 62 | P16: 58 | Q16: 61 | T16: 85 | U16: 89 | X16: 85 | Y16: 88 | AB16: 60 | AC16: 65 | AF16: 61 | AG16: 61 | AI16: 15 | AL16: 85 | AM16: 85 | AP16: 83 | AQ16: 90 | AT16: >99 | AU16: >99 | AX16: >99 | AY16: >99 | BB16: 84 | BC16: 90 | BF16: 86 | BG16: 87
B17: GEC | C17: =Self!P34 -> 0 | D17: =IFERROR(VLOOKUP(C17,I145:Q250,C25,FALSE),"") | E17: =IFERROR(VLOOKUP(C17,AI145:AQ250,C25,FALSE),"") | F17: =D17-(VLOOKUP("CI",I251:Q251,C25,FALSE)) -> #VALUE! | G17: =D17+(VLOOKUP("CI",I251:Q251,C25,FALSE)) -> #VALUE! | I17: 14 | L17: 55 | M17: 59 | P17: 55 | Q17: 58 | T17: 81 | U17: 84 | X17: 81 | Y17: 84 | AB17: 57 | AC17: 62 | AF17: 57 | AG17: 58 | AI17: 14 | AL17: 74 | AM17: 80 | AP17: 73 | AQ17: 81 | AT17: >99 | AU17: >99 | AX17: 99 | AY17: 99 | BB17: 80 | BC17: 87 | BF17: 77 | BG17: 81
I18: 13 | L18: 52 | M18: 56 | P18: 52 | Q18: 55 | T18: 76 | U18: 79 | X18: 76 | Y18: 79 | AB18: 54 | AC18: 58 | AF18: 54 | AG18: 55 | AI18: 13 | AL18: 65 | AM18: 77 | AP18: 63 | AQ18: 73 | AT18: 99 | AU18: 99 | AX18: 99 | AY18: 98 | BB18: 72 | BC18: 82 | BF18: 69 | BG18: 74
I19: 12 | L19: 49 | M19: 53 | P19: 49 | Q19: 51 | T19: 72 | U19: 75 | X19: 72 | Y19: 74 | AB19: 51 | AC19: 55 | AF19: 51 | AG19: 52 | AI19: 12 | AL19: 56 | AM19: 71 | AP19: 54 | AQ19: 65 | AT19: 98 | AU19: 98 | AX19: 97 | AY19: 98 | BB19: 65 | BC19: 73 | BF19: 58 | BG19: 64
I20: 11 | L20: 46 | M20: 50 | P20: 46 | Q20: 48 | T20: 67 | U20: 70 | X20: 67 | Y20: 70 | AB20: 48 | AC20: 52 | AF20: 47 | AG20: 49 | AI20: 11 | AL20: 45 | AM20: 66 | AP20: 46 | AQ20: 55 | AT20: 95 | AU20: 96 | AX20: 96 | AY20: 97 | BB20: 55 | BC20: 67 | BF20: 48 | BG20: 58
C21: 5-7 | D21: 8-10 | E21: 11-13 | F21: 14-18 | I21: 10 | L21: 43 | M21: 46 | P21: 43 | Q21: 45 | T21: 63 | U21: 65 | X21: 63 | Y21: 65 | AB21: 45 | AC21: 48 | AF21: 44 | AG21: 46 | AI21: 10 | AL21: 37 | AM21: 55 | AP21: 35 | AQ21: 47 | AT21: 91 | AU21: 94 | AX21: 94 | AY21: 94 | BB21: 48 | BC21: 59 | BF21: 39 | BG21: 49
B22: Boys | C22: 2 | D22: 3 | E22: 4 | F22: 5 | I22: 9 | L22: 40 | M22: 43 | P22: 40 | Q22: 42 | T22: 58 | U22: 61 | X22: 58 | Y22: 60 | AB22: 42 | AC22: 45 | AF22: 41 | AG22: 43 | AI22: 9 | AL22: 28 | AM22: 40 | AP22: 22 | AQ22: 33 | AT22: 81 | AU22: 86 | AX22: 84 | AY22: 87 | BB22: 37 | BC22: 53 | BF22: 31 | BG22: 37
