Workbook

Sheet Scores Summary
A2: Score Summaries
A5: Instructions: Enter in values in the light blue boxes.
A7: Name: | G7: DOB: | H7: 29722
A8: Date of Testing: | C8: 44704 | G8: Years of Ed: | H8: 18
B9: Race/Ethnic.: | G9: Gender Norms:
B10: Age: | C10: =IF(H7="","",IF(C8="","",DATEDIF(H7,C8,"y"))) -> 41 | D10: years | F10: Handedness Norms:
C11: =IF(H7="","",IF(C8="","",DATEDIF(H7,C8,"m")-(C10*12))) -> 0 | D11: months
B14: Stroop:
D15: Raw | E15: Predicted | F15: Residual | G15: T-Score | H15: Percentile
B16: Word Score (W) | D16: 88 | E16: ='Stroop Word Predicted'!I24 -> 112 | F16: =IF(D16="","",IF(E16="","",D16-E16)) -> -24 | G16: =IF(F16="","",IF(F16>50,">85",IF(F16<-50,"<15",VLOOKUP(F16,'Stroop T-Score Calc'!A1:G102,2,FALSE)))) -> 33 | H16: =IF(G16="<15","<1",IF(G16="","",IF(G16>76,">99",IF(G16<25,"<1",ROUND(NORMDIST(G16,50,10,TRUE)*100,0))))) -> 4
B17: Color Score (C) | D17: 80 | E17: ='Stroop Color Predicted'!I24 -> 82 | F17: =IF(D17="","",IF(E17="","",D17-E17)) -> -2 | G17: =IF(F17="","",IF(F17>50,">92",IF(F17<-50,"<8",VLOOKUP(F17,'Stroop T-Score Calc'!A1:E102,3,FALSE)))) -> 48 | H17: =IF(G17="<8","<1",IF(G17="","",IF(G17>76,">99",IF(G17<25,"<1",ROUND(NORMDIST(G17,50,10,TRUE)*100,0))))) -> 42
B18: Color-Word (CW) | D18: 41 | E18: ='Stroop Inhibition Predicted'!I24 -> 47 | F18: =IF(D18="","",IF(E18="","",D18-E18)) -> -6 | G18: =IF(F18="","",IF(F18>50,">98",IF(F18<-50,"<3",VLOOKUP(F18,'Stroop T-Score Calc'!A1:E102,4,FALSE)))) -> 44 | H18: =IF(G18="<3","<1",IF(G18="","",IF(G18>76,">99",IF(G18<25,"<1",ROUND(NORMDIST(G18,50,10,TRUE)*100,0))))) -> 27
B19: Interference | D19: =IF(D16="","",IF(D17="","",IF(D18="","",D18-('Stroop Inter. Pred.'!V37)))) -> 0 | G19: =IF(D19="","",IF(D19<-29,"<21",IF(D19>30,">80",VLOOKUP(D19,'Stroop T-Score Calc'!A1:G103,5,FALSE)))) -> 50 | H19: =IF(G19="","",IF(G19="<21","<1",IF(G19>76,">99",IF(G19<25,"<1",ROUND(NORMDIST(G19,50,10,TRUE)*100,0))))) -> 50
B21: Judgment of Line Orientation (Benton)
D22: Raw | E22: Corrected | F22: Percentile | G22: Range
C23: Total | E23: =IF(D23="","",JOLO!B24) | F23: =IF(D23="","",JOLO!B25) | G23: =IF(D23="","",JOLO!B26)
B25: Visual Form Discrimination (Benton)
C26: Raw | E26: Range
E27: =IF(C27>=26,"Within Normal Limits",IF(C27>=24,"Borderline (Mildly Defective)",IF(C27=23,"Moderately Defective",IF(C27="","","Severely Defective"))))
B29: Beery VMI (18+)
D30: Raw | E30: Standard | F30: T-Score | G30: Percentile | H30: A-E
B31: Beery VMI | E31: =IFERROR('Beery VMI'!E4,"") | F31: =IF(E31="<45","<13",IF(E31="","",(((E31-100)/15)*10)+50)) | G31: =IF(E31="<45","<1",IF(E31="","",IF(E31>138,">99",IF(E31<62,"<1",ROUND(NORMDIST(E31,100,15,TRUE)*100,0))))) | H31: ='Beery VMI'!E5
B32: Visual Perception | E32: =IFERROR('Beery VMI'!H4,"") | F32: =IF(E32="<45","<13",IF(E32="","",(((E32-100)/15)*10)+50)) | G32: =IF(E32="<45","<1",IF(E32="","",IF(E32>138,">99",IF(E32<62,"<1",ROUND(NORMDIST(E32,100,15,TRUE)*100,0))))) | H32: ='Beery VMI'!H5
B33: Motor Coordination | E33: =IFERROR('Beery VMI'!K4,"") | F33: =IF(E33="<45","<13",IF(E33="","",(((E33-100)/15)*10)+50)) | G33: =IF(E33="<45","<1",IF(E33="","",IF(E33>138,">99",IF(E33<62,"<1",ROUND(NORMDIST(E33,100,15,TRUE)*100,0))))) | H33: ='Beery VMI'!K5

Sheet Scores Summary 2
A2: Score Summaries
A5: Instructions: Enter in values in the light blue boxes.
A7: Name: | B7: =IF('Scores Summary'!B7:E7="","",'Scores Summary'!B7:E7) | G7: DOB: | H7: =IF('Scores Summary'!H7:I7="","",'Scores Summary'!H7:I7) -> 29722
A8: Date of Testing: | C8: =IF('Scores Summary'!C8:D8="","",'Scores Summary'!C8:D8) -> 44704 | G8: Years of Ed: | H8: =IF('Scores Summary'!H8="","",'Scores Summary'!H8) -> 18
B9: Race/Ethnic.: | C9: =IF('Scores Summary'!C9:E9="","",'Scores Summary'!C9:E9) | G9: Gender Norms: | H9: =IF('Scores Summary'!H9:I9="","",'Scores Summary'!H9:I9)
B10: Age: | C10: =IF('Scores Summary'!C10="","",'Scores Summary'!C10) -> 41 | D10: years | F10: Handedness Norms: | H10: =IF('Scores Summary'!H10:I10="","",'Scores Summary'!H10:I10)
C11: =IF('Scores Summary'!C11="","",'Scores Summary'!C11) -> 0 | D11: months
B14: Heaton Scores:
B15: Test | D15: Raw | E15: Scaled | F15: T-Score | G15: Percentile
B16: FAS Naming | E16: =IF(D16="","",IF(D16>=79,19,VLOOKUP(D16,'Heaton Appx C'!D4:E83,2,FALSE))) | G16: =IF(F16="","",ROUND(NORMDIST(F16,50,10,TRUE)*100,0))
B17: Animal Naming | E17: =IF(D17="","",IF(D17>=39,19,VLOOKUP(D17,'Heaton Appx C'!G4:H43,2,FALSE))) | G17: =IF(F17="","",ROUND(NORMDIST(F17,50,10,TRUE)*100,0))
B18: Trails A | E18: =IF(D18="","",IF(ROUND(D18,0)>=92,1,VLOOKUP('Heaton Appx C'!K2,'Heaton Appx C'!J4:K96,2,FALSE))) | G18: =IF(F18="","",ROUND(NORMDIST(F18,50,10,TRUE)*100,0))
B19: Trails B | E19: =IF(D19="","",IF('Heaton Appx C'!N2<=24,19,VLOOKUP('Heaton Appx C'!N2,'Heaton Appx C'!M4:N280,2,FALSE))) | G19: =IF(F19="","",ROUND(NORMDIST(F19,50,10,TRUE)*100,0))
B20: Boston Naming | E20: =IF(D20="","",VLOOKUP(D20,'Heaton Appx C'!A4:B65,2,FALSE)) | G20: =IF(F20="","",ROUND(NORMDIST(F20,50,10,TRUE)*100,0))
B21: Grooved PB - DH | E21: =IF(D21="","",IF('Heaton Appx C'!Q2<=45,19,VLOOKUP('Heaton Appx C'!Q2,'Heaton Appx C'!P4:Q125,2,FALSE))) | G21: =IF(F21="","",ROUND(NORMDIST(F21,50,10,TRUE)*100,0))
B22: Grooed PB - NDH | E22: =IF(D22="","",IF('Heaton Appx C'!T2<=44,19,VLOOKUP('Heaton Appx C'!T2,'Heaton Appx C'!S4:T162,2,FALSE))) | G22: =IF(F22="","",ROUND(NORMDIST(F22,50,10,TRUE)*100,0))
B23: Finger Tapping - DH | E23: =IF(D23="","",'Heaton Appx C'!W3) | G23: =IF(F23="","",ROUND(NORMDIST(F23,50,10,TRUE)*100,0))
B24: Finger Tapping - NDH | E24: =IF(D24="","",'Heaton Appx C'!Z3) | G24: =IF(F24="","",ROUND(NORMDIST(F24,50,10,TRUE)*100,0))
B25: Grip Strength - DH | G25: =IF(F25="","",ROUND(NORMDIST(F25,50,10,TRUE)*100,0))
B26: Grip Strengh - NDH | G26: =IF(F26="","",ROUND(NORMDIST(F26,50,10,TRUE)*100,0))

Sheet Scores Summary 3
A2: Score Summaries
A5: Instructions: Enter in values in the light blue boxes.
A7: Name: | B7: =IF('Scores Summary'!B7:E7="","",'Scores Summary'!B7:E7) | G7: DOB: | H7: =IF('Scores Summary'!H7:I7="","",'Scores Summary'!H7:I7) -> 29722
A8: Date of Testing: | C8: =IF('Scores Summary'!C8:D8="","",'Scores Summary'!C8:D8) -> 44704 | G8: Years of Ed: | H8: =IF('Scores Summary'!H8="","",'Scores Summary'!H8) -> 18
B9: Race/Ethnic.: | C9: =IF('Scores Summary'!C9:E9="","",'Scores Summary'!C9:E9) | G9: Gender Norms: | H9: =IF('Scores Summary'!H9:I9="","",'Scores Summary'!H9:I9)
B10: Age: | C10: =IF('Scores Summary'!C10="","",'Scores Summary'!C10) -> 41 | D10: years | F10: Handedness Norms: | H10: =IF('Scores Summary'!H10:I10="","",'Scores Summary'!H10:I10)
C11: =IF('Scores Summary'!C11="","",'Scores Summary'!C11) -> 0 | D11: months
B14: CVLT-3 Standard Form
B15: Score | D15: Raw | E15: Scaled Score | G15: Percentile
B16: Trial 1 Correct | D16: 6 | E16: =IFERROR('CVLT Standard'!D6,"") -> 10 | G16: =IF(E16<3,"<1",IF(E16="","",IF(E16>17,">99",ROUND(NORMDIST(E16,10,3,TRUE)*100,0)))) -> 50
B17: Trial 2 Correct | D17: 8 | E17: =IFERROR('CVLT Standard'!D7,"") -> 9 | G17: =IF(E17<3,"<1",IF(E17="","",IF(E17>17,">99",ROUND(NORMDIST(E17,10,3,TRUE)*100,0)))) -> 37
B18: Trial 3 Correct | D18: 12 | E18: =IFERROR('CVLT Standard'!D8,"") -> 11 | G18: =IF(E18<3,"<1",IF(E18="","",IF(E18>17,">99",ROUND(NORMDIST(E18,10,3,TRUE)*100,0)))) -> 63
B19: Trial 4 Correct | D19: 11 | E19: =IFERROR('CVLT Standard'!D9,"") -> 9 | G19: =IF(E19<3,"<1",IF(E19="","",IF(E19>17,">99",ROUND(NORMDIST(E19,10,3,TRUE)*100,0)))) -> 37
B20: Trial 5 Correct | D20: 12 | E20: =IFERROR('CVLT Standard'!D10,"") -> 9 | G20: =IF(E20<3,"<1",IF(E20="","",IF(E20>17,">99",ROUND(NORMDIST(E20,10,3,TRUE)*100,0)))) -> 37
B21: List B Correct | D21: 7 | E21: =IFERROR('CVLT Standard'!D11,"") -> 13 | G21: =IF(E21<3,"<1",IF(E21="","",IF(E21>17,">99",ROUND(NORMDIST(E21,10,3,TRUE)*100,0)))) -> 84
B22: SD Free Recall | D22: 7 | E22: =IFERROR('CVLT Standard'!D12,"") -> 7 | G22: =IF(E22<3,"<1",IF(E22="","",IF(E22>17,">99",ROUND(NORMDIST(E22,10,3,TRUE)*100,0)))) -> 16
B23: SD Cued Recall | D23: 7 | E23: =IFERROR('CVLT Standard'!D13,"") -> 6 | G23: =IF(E23<3,"<1",IF(E23="","",IF(E23>17,">99",ROUND(NORMDIST(E23,10,3,TRUE)*100,0)))) -> 9
B24: LD Free Recall | D24: 9 | E24: =IFERROR('CVLT Standard'!D14,"") -> 8 | G24: =IF(E24<3,"<1",IF(E24="","",IF(E24>17,">99",ROUND(NORMDIST(E24,10,3,TRUE)*100,0)))) -> 25
B25: LD Cued Recall | D25: 9 | E25: =IFERROR('CVLT Standard'!D15,"") -> 7 | G25: =IF(E25<3,"<1",IF(E25="","",IF(E25>17,">99",ROUND(NORMDIST(E25,10,3,TRUE)*100,0)))) -> 16
B26: Trials 1-5 Intrusions | D26: 4 | E26: =IFERROR('CVLT Standard'!D16,"") -> 6 | G26: =IF(E26<3,"<1",IF(E26="","",IF(E26>17,">99",ROUND(NORMDIST(E26,10,3,TRUE)*100,0)))) -> 9
B27: Free Recall Intrus. | D27: 3 | E27: =IFERROR('CVLT Standard'!D17,"") -> 9 | G27: =IF(E27<3,"<1",IF(E27="","",IF(E27>17,">99",ROUND(NORMDIST(E27,10,3,TRUE)*100,0)))) -> 37
B28: Cued Recall Intrus. | D28: 5 | E28: =IFERROR('CVLT Standard'!D18,"") -> 6 | G28: =IF(E28<3,"<1",IF(E28="","",IF(E28>17,">99",ROUND(NORMDIST(E28,10,3,TRUE)*100,0)))) -> 9
B29: Total Intrusions | D29: =SUM(D27:D28) -> 8 | E29: =IFERROR('CVLT Standard'!D19,"") -> 7 | G29: =IF(E29<3,"<1",IF(E29="","",IF(E29>17,">99",ROUND(NORMDIST(E29,10,3,TRUE)*100,0)))) -> 16
B30: Total Repetitions | D30: 9 | E30: =IFERROR('CVLT Standard'!D20,"") -> 8 | G30: =IF(E30<3,"<1",IF(E30="","",IF(E30>17,">99",ROUND(NORMDIST(E30,10,3,TRUE)*100,0)))) -> 25
B31: Y/N Recog. Hits | D31: 12 | E31: =IFERROR('CVLT Standard'!D21,"") -> 5 | G31: =IF(E31<3,"<1",IF(E31="","",IF(E31>17,">99",ROUND(NORMDIST(E31,10,3,TRUE)*100,0)))) -> 5
B32: Y/N Recog. FPs | D32: 2 | E32: =IFERROR('CVLT Standard'!D22,"") -> 9 | G32: =IF(E32<3,"<1",IF(E32="","",IF(E32>17,">99",ROUND(NORMDIST(E32,10,3,TRUE)*100,0)))) -> 37
A33: Y/N Recog. Discrim NP | D33: =ROUND((1-((D32+(16-D31))/48))*100,0) -> 88 | E33: =IFERROR('CVLT Standard'!D23,"") -> 8 | G33: =IF(E33<3,"<1",IF(E33="","",IF(E33>17,">99",ROUND(NORMDIST(E33,10,3,TRUE)*100,0)))) -> 25
C34: Forced Choice Raw | D34: 15 | E34: =IF(D34="","",IFERROR('CVLT Standard'!D27,"")) -> 3 | F34: (base rate)
B36: Index Score | D36: Raw | E36: Standard Score | G36: Percentile
B37: Trials 1-5 Correct | D37: =SUM(E16:F20) -> 48 | E37: =IFERROR('CVLT Standard'!D24,"") -> 98 | G37: =IF(E37<62,"<1",IF(E37="","",IF(E37>138,">99",ROUND(NORMDIST(E37,100,15,TRUE)*100,0)))) -> 45
A38: Delayed Recall Correct | D38: =SUM(E22:F25) -> 28 | E38: =IFERROR('CVLT Standard'!D25,"") -> 84 | G38: =IF(E38<62,"<1",IF(E38="","",IF(E38>138,">99",ROUND(NORMDIST(E38,100,15,TRUE)*100,0)))) -> 14
B39: Total Recall Correct | D39: =SUM(E16:F25) -> 89 | E39: =IFERROR('CVLT Standard'!D26,"") -> 94 | G39: =IF(E39<62,"<1",IF(E39="","",IF(E39>138,">99",ROUND(NORMDIST(E39,100,15,TRUE)*100,0)))) -> 34
B41: Contrast Scores | D41: Score 1 | E41: Score 2 | F41: Contrast | G41: Percentile
B42: List B vs. T1 | D42: =E21 -> 13 | E42: =E16 -> 10 | F42: ='CVLT-3 (Contrast)'!C9 -> 13 | G42: =IF(F42="","",ROUND(NORMDIST(F42,10,3,TRUE)*100,0)) -> 84
B43: SDFR vs. T5 | D43: =E22 -> 7 | E43: =E20 -> 9 | F43: ='CVLT-3 (Contrast)'!C10 -> 7 | G43: =IF(F43="","",ROUND(NORMDIST(F43,10,3,TRUE)*100,0)) -> 16
B44: LDFR vs. T5 | D44: =E24 -> 8 | E44: =E20 -> 9 | F44: ='CVLT-3 (Contrast)'!C11 -> 9 | G44: =IF(F44="","",ROUND(NORMDIST(F44,10,3,TRUE)*100,0)) -> 37
B45: LDFR vs. SDFR | D45: =E24 -> 8 | E45: =E22 -> 7 | F45: ='CVLT-3 (Contrast)'!C12 -> 12 | G45: =IF(F45="","",ROUND(NORMDIST(F45,10,3,TRUE)*100,0)) -> 75
B46: LDFR vs. Recog. | D46: =E24 -> 8 | E46: =E33 -> 8 | F46: ='CVLT-3 (Contrast)'!C13 -> 9 | G46: =IF(F46="","",ROUND(NORMDIST(F46,10,3,TRUE)*100,0)) -> 37

Sheet CVLT Standard
F1: STANDARD FORM
A2: Truncated Age | C2: ='Scores Summary'!C10 -> 41
A3: Age Range for CVLT | C3: =IF(C2="","",IF(C2>90,"N/A",IF(C2>=80,"80-90",IF(C2>=70,"70-79",IF(C2>=60,"60-69",IF(C2>=45,"45-59",IF(C2>=30,"30-44",IF(C2>=20,"20-29",IF(C2>=16,"16-19","N/A"))))))))) -> 30-44
C5: Raw | D5: ss/SS | G5: T1 Correct | N5: T2 Correct | U5: T3 Correct
A6: Trial 1 Correct | C6: ='Scores Summary 3'!D16 -> 6 | D6: =VLOOKUP(C6,F6:AA23,(VLOOKUP(C3,A28:B35,2,FALSE)),FALSE) -> 10 | F6: Raw | G6: 16-19 | H6: 20-29 | I6: 30-44 | J6: 45-59 | K6: 60-69 | L6: 70-79 | M6: 80-90 | N6: 16-19 | O6: 20-29 | P6: 30-44 | Q6: 45-59 | R6: 60-69 | S6: 70-79 | T6: 80-90 | U6: 16-19 | V6: 20-29 | W6: 30-44 | X6: 45-59 | Y6: 60-69 | Z6: 70-79 | AA6: 80-90 | AB6: Raw | AC6: Trials 1-5 | AD6: Delayed | AE6: Total Rec
A7: Trial 2 Correct | C7: ='Scores Summary 3'!D17 -> 8 | D7: =VLOOKUP(C7,F6:AA23,(VLOOKUP(C3,A28:B35,2,FALSE)+7),FALSE) -> 9 | F7: 0 | G7: 1 | H7: 1 | I7: 1 | J7: 1 | K7: 1 | L7: 1 | M7: 2 | N7: 1 | O7: 1 | P7: 1 | Q7: 1 | R7: 1 | S7: 1 | T7: 1 | U7: 1 | V7: 1 | W7: 1 | X7: 1 | Y7: 1 | Z7: 1 | AA7: 1 | AB7: 4 | AD7: 45
A8: Trial 3 Correct | C8: ='Scores Summary 3'!D18 -> 12 | D8: =VLOOKUP(C8,F6:AA23,(VLOOKUP(C3,A28:B35,2,FALSE)+14),FALSE) -> 11 | F8: 1 | G8: 1 | H8: 1 | I8: 1 | J8: 2 | K8: 2 | L8: 2 | M8: 4 | N8: 1 | O8: 1 | P8: 1 | Q8: 1 | R8: 2 | S8: 2 | T8: 2 | U8: 1 | V8: 1 | W8: 1 | X8: 1 | Y8: 1 | Z8: 1 | AA8: 1 | AB8: =AB7+1 -> 5 | AC8: 45 | AD8: 47
A9: Trial 4 Correct | C9: ='Scores Summary 3'!D19 -> 11 | D9: =VLOOKUP(C9,F26:AA43,(VLOOKUP(C3,A28:B35,2,FALSE)),FALSE) -> 9 | F9: 2 | G9: 2 | H9: 2 | I9: 2 | J9: 4 | K9: 4 | L9: 4 | M9: 6 | N9: 2 | O9: 2 | P9: 2 | Q9: 2 | R9: 3 | S9: 3 | T9: 3 | U9: 1 | V9: 1 | W9: 1 | X9: 1 | Y9: 2 | Z9: 2 | AA9: 2 | AB9: =AB8+1 -> 6 | AC9: 45 | AD9: 49
A10: Trial 5 Correct | C10: ='Scores Summary 3'!D20 -> 12 | D10: =VLOOKUP(C10,F26:AA43,(VLOOKUP(C3,A28:B35,2,FALSE)+7),FALSE) -> 9 | F10: 3 | G10: 4 | H10: 4 | I10: 4 | J10: 5 | K10: 6 | L10: 6 | M10: 8 | N10: 3 | O10: 3 | P10: 3 | Q10: 3 | R10: 4 | S10: 5 | T10: 5 | U10: 2 | V10: 1 | W10: 1 | X10: 2 | Y10: 3 | Z10: 4 | AA10: 4 | AB10: =AB9+1 -> 7 | AC10: 45 | AD10: 51
A11: List B Correct | C11: ='Scores Summary 3'!D21 -> 7 | D11: =VLOOKUP(C11,F26:AA43,(VLOOKUP(C3,A28:B35,2,FALSE)+14),FALSE) -> 13 | F11: 4 | G11: 6 | H11: 6 | I11: 6 | J11: 7 | K11: 8 | L11: 8 | M11: 10 | N11: 4 | O11: 4 | P11: 4 | Q11: 4 | R11: 5 | S11: 6 | T11: 7 | U11: 3 | V11: 2 | W11: 2 | X11: 3 | Y11: 4 | Z11: 5 | AA11: 5 | AB11: =AB10+1 -> 8 | AC11: 46 | AD11: 53
A12: SD Free Recall | C12: ='Scores Summary 3'!D22 -> 7 | D12: =VLOOKUP(C12,F46:AA63,(VLOOKUP(C3,A28:B35,2,FALSE)),FALSE) -> 7 | F12: 5 | G12: 8 | H12: 8 | I12: 8 | J12: 8 | K12: 10 | L12: 10 | M12: 12 | N12: 5 | O12: 5 | P12: 5 | Q12: 5 | R12: 6 | S12: 7 | T12: 8 | U12: 4 | V12: 3 | W12: 3 | X12: 4 | Y12: 5 | Z12: 6 | AA12: 6 | AB12: =AB11+1 -> 9 | AC12: 47 | AD12: 55
A13: SD Cued Recall | C13: ='Scores Summary 3'!D23 -> 7 | D13: =VLOOKUP(C13,F46:AA63,(VLOOKUP(C3,A28:B35,2,FALSE)+7),FALSE) -> 6 | F13: 6 | G13: 10 | H13: 10 | I13: 10 | J13: 10 | K13: 11 | L13: 12 | M13: 14 | N13: 7 | O13: 6 | P13: 6 | Q13: 6 | R13: 7 | S13: 8 | T13: 10 | U13: 5 | V13: 4 | W13: 4 | X13: 5 | Y13: 6 | Z13: 7 | AA13: 8 | AB13: =AB12+1 -> 10 | AC13: 48 | AD13: 57 | AE13: 40
A14: LD Free Recall | C14: ='Scores Summary 3'!D24 -> 9 | D14: =VLOOKUP(C14,F46:AA63,(VLOOKUP(C3,A28:B35,2,FALSE)+14),FALSE) -> 8 | F14: 7 | G14: 11 | H14: 11 | I14: 11 | J14: 11 | K14: 13 | L14: 14 | M14: 15 | N14: 8 | O14: 8 | P14: 8 | Q14: 8 | R14: 9 | S14: 10 | T14: 11 | U14: 6 | V14: 5 | W14: 5 | X14: 6 | Y14: 7 | Z14: 8 | AA14: 10 | AB14: =AB13+1 -> 11 | AC14: 50 | AD14: 58 | AE14: 40
A15: LD Cued Recall | C15: ='Scores Summary 3'!D25 -> 9 | D15: =VLOOKUP(C15,F66:T83,(VLOOKUP(C3,A28:B35,2,FALSE)),FALSE) -> 7 | F15: 8 | G15: 13 | H15: 13 | I15: 13 | J15: 13 | K15: 14 | L15: 15 | M15: 16 | N15: 9 | O15: 9 | P15: 9 | Q15: 9 | R15: 10 | S15: 11 | T15: 13 | U15: 7 | V15: 7 | W15: 7 | X15: 7 | Y15: 9 | Z15: 10 | AA15: 11 | AB15: =AB14+1 -> 12 | AC15: 51 | AD15: 59 | AE15: 40
A16: Trials 1-5 Intrusions | C16: ='Scores Summary 3'!D26 -> 4 | D16: =IF(C16>36,1,VLOOKUP(C16,F86:AA123,(VLOOKUP(C3,A28:B35,2,FALSE)),FALSE)) -> 6 | F16: 9 | G16: 15 | H16: 14 | I16: 14 | J16: 14 | K16: 15 | L16: 16 | M16: 17 | N16: 10 | O16: 10 | P16: 10 | Q16: 10 | R16: 11 | S16: 12 | T16: 14 | U16: 8 | V16: 8 | W16: 8 | X16: 8 | Y16: 10 | Z16: 11 | AA16: 12 | AB16: =AB15+1 -> 13 | AC16: 52 | AD16: 61 | AE16: 40
A17: Free Recall Intrus. | C17: ='Scores Summary 3'!D27 -> 3 | D17: =IF(C17>26,1,VLOOKUP(C17,F86:AA123,(VLOOKUP(C3,A28:B35,2,FALSE)+7),FALSE)) -> 9 | F17: 10 | G17: 17 | H17: 15 | I17: 15 | J17: 15 | K17: 16 | L17: 17 | M17: 18 | N17: 12 | O17: 11 | P17: 11 | Q17: 11 | R17: 12 | S17: 14 | T17: 15 | U17: 9 | V17: 9 | W17: 9 | X17: 10 | Y17: 11 | Z17: 12 | AA17: 13 | AB17: =AB16+1 -> 14 | AC17: 54 | AD17: 63 | AE17: 40
A18: Cued Recall Intrus. | C18: ='Scores Summary 3'!D28 -> 5 | D18: =IF(C18>36,1,VLOOKUP(C18,F86:AA123,(VLOOKUP(C3,A28:B35,2,FALSE)+14),FALSE)) -> 6 | F18: 11 | G18: 18 | H18: 17 | I18: 16 | J18: 16 | K18: 17 | L18: 18 | M18: 19 | N18: 13 | O18: 12 | P18: 12 | Q18: 12 | R18: 13 | S18: 15 | T18: 16 | U18: 10 | V18: 10 | W18: 10 | X18: 11 | Y18: 12 | Z18: 13 | AA18: 14 | AB18: =AB17+1 -> 15 | AC18: 55 | AD18: 65 | AE18: 40
A19: Total Intrusions | C19: ='Scores Summary 3'!D29 -> 8 | D19: =IF(C19>37,1,VLOOKUP(C19,F126:AA164,(VLOOKUP(C3,A28:B35,2,FALSE)),FALSE)) -> 7 | F19: 12 | G19: 19 | H19: 18 | I19: 17 | J19: 17 | K19: 18 | L19: 19 | M19: 19 | N19: 14 | O19: 13 | P19: 13 | Q19: 13 | R19: 15 | S19: 16 | T19: 18 | U19: 11 | V19: 11 | W19: 11 | X19: 12 | Y19: 13 | Z19: 14 | AA19: 15 | AB19: =AB18+1 -> 16 | AC19: 57 | AD19: 67 | AE19: 40
A20: Total Repetitions | C20: ='Scores Summary 3'!D30 -> 9 | D20: =IF(C20>37,1,VLOOKUP(C20,F126:AA164,(VLOOKUP(C3,A28:B35,2,FALSE)+7),FALSE)) -> 8 | F20: 13 | G20: 19 | H20: 19 | I20: 18 | J20: 18 | K20: 19 | L20: 19 | M20: 19 | N20: 15 | O20: 15 | P20: 15 | Q20: 15 | R20: 16 | S20: 18 | T20: 19 | U20: 13 | V20: 12 | W20: 12 | X20: 13 | Y20: 14 | Z20: 15 | AA20: 16 | AB20: =AB19+1 -> 17 | AC20: 58 | AD20: 68 | AE20: 41
A21: Y/N Recog. Hits | C21: ='Scores Summary 3'!D31 -> 12 | D21: =VLOOKUP(C21,F66:T83,(VLOOKUP(C3,A28:B35,2,FALSE)+7),FALSE) -> 5 | F21: 14 | G21: 19 | H21: 19 | I21: 19 | J21: 19 | K21: 19 | L21: 19 | M21: 19 | N21: 16 | O21: 16 | P21: 16 | Q21: 16 | R21: 18 | S21: 19 | T21: 19 | U21: 15 | V21: 13 | W21: 13 | X21: 14 | Y21: 15 | Z21: 16 | AA21: 17 | AB21: =AB20+1 -> 18 | AC21: 60 | AD21: 69 | AE21: 42
A22: Y/N Recog. FPs | C22: ='Scores Summary 3'!D32 -> 2 | D22: =IF(C22>37,1,VLOOKUP(C22,F126:AA164,(VLOOKUP(C3,A28:B35,2,FALSE)+14),FALSE)) -> 9 | F22: 15 | G22: 19 | H22: 19 | I22: 19 | J22: 19 | K22: 19 | L22: 19 | M22: 19 | N22: 18 | O22: 18 | P22: 18 | Q22: 18 | R22: 19 | S22: 19 | T22: 19 | U22: 16 | V22: 15 | W22: 15 | X22: 15 | Y22: 16 | Z22: 17 | AA22: 18 | AB22: =AB21+1 -> 19 | AC22: 61 | AD22: 71 | AE22: 43
A23: Y/N Recog Discrim NP | C23: =ROUND('Scores Summary 3'!D33,0) -> 88 | D23: =IF(C23<44,1,VLOOKUP(C23,F167:M224,(VLOOKUP(C3,A28:B35,2,FALSE)),FALSE)) -> 8 | F23: 16 | G23: 19 | H23: 19 | I23: 19 | J23: 19 | K23: 19 | L23: 19 | M23: 19 | N23: 19 | O23: 19 | P23: 19 | Q23: 19 | R23: 19 | S23: 19 | T23: 19 | U23: 17 | V23: 16 | W23: 16 | X23: 16 | Y23: 17 | Z23: 18 | AA23: 19 | AB23: =AB22+1 -> 20 | AC23: 63 | AD23: 72 | AE23: 44
A24: Trials 1-5 Correct | C24: ='Scores Summary 3'!D37 -> 48 | D24: =VLOOKUP(C24,AB6:AE193,2,FALSE) -> 98 | AB24: =AB23+1 -> 21 | AC24: 64 | AD24: 74 | AE24: 45
A25: Delayed Recall Correct | C25: ='Scores Summary 3'!D38 -> 28 | D25: =VLOOKUP(C25,AB6:AE193,3,FALSE) -> 84 | G25: T4 Correct | N25: T5 Correct | U25: List B Correct | AB25: =AB24+1 -> 22 | AC25: 66 | AD25: 75 | AE25: 45
A26: Total Recall Correct | C26: ='Scores Summary 3'!D39 -> 89 | D26: =VLOOKUP(C26,AB6:AE193,4,FALSE) -> 94 | F26: Raw | G26: 16-19 | H26: 20-29 | I26: 30-44 | J26: 45-59 | K26: 60-69 | L26: 70-79 | M26: 80-90 | N26: 16-19 | O26: 20-29 | P26: 30-44 | Q26: 45-59 | R26: 60-69 | S26: 70-79 | T26: 80-90 | U26: 16-19 | V26: 20-29 | W26: 30-44 | X26: 45-59 | Y26: 60-69 | Z26: 70-79 | AA26: 80-90 | AB26: =AB25+1 -> 23 | AC26: 67 | AD26: 77 | AE26: 46
A27: Forced Choice Raw | C27: ='Scores Summary 3'!D34 -> 15 | D27: =IF(C27<12,0,VLOOKUP(C27,O167:V172,(VLOOKUP(C3,A28:B35,2,FALSE)),FALSE)) -> 3 | F27: 0 | G27: 1 | H27: 1 | I27: 1 | J27: 1 | K27: 1 | L27: 1 | M27: 1 | N27: 1 | O27: 1 | P27: 1 | Q27: 1 | R27: 1 | S27: 1 | T27: 1 | U27: 1 | V27: 1 | W27: 1 | X27: 1 | Y27: 3 | Z27: 3 | AA27: 3 | AB27: =AB26+1 -> 24 | AC27: 69 | AD27: 79 | AE27: 47
A28: Age | B28: Column | F28: 1 | G28: 1 | H28: 1 | I28: 1 | J28: 1 | K28: 1 | L28: 1 | M28: 2 | N28: 1 | O28: 1 | P28: 1 | Q28: 1 | R28: 1 | S28: 1 | T28: 2 | U28: 2 | V28: 2 | W28: 2 | X28: 2 | Y28: 5 | Z28: 5 | AA28: 5 | AB28: =AB27+1 -> 25 | AC28: 70 | AD28: 80 | AE28: 48
A29: 16-19 | B29: 2 | F29: 2 | G29: 1 | H29: 1 | I29: 1 | J29: 1 | K29: 1 | L29: 2 | M29: 3 | N29: 1 | O29: 1 | P29: 1 | Q29: 1 | R29: 1 | S29: 2 | T29: 3 | U29: 4 | V29: 4 | W29: 4 | X29: 4 | Y29: 6 | Z29: 6 | AA29: 7 | AB29: =AB28+1 -> 26 | AC29: 71 | AD29: 81 | AE29: 49
A30: 20-29 | B30: 3 | F30: 3 | G30: 1 | H30: 1 | I30: 1 | J30: 1 | K30: 2 | L30: 3 | M30: 4 | N30: 1 | O30: 1 | P30: 1 | Q30: 1 | R30: 2 | S30: 3 | T30: 4 | U30: 6 | V30: 6 | W30: 6 | X30: 6 | Y30: 7 | Z30: 7 | AA30: 9 | AB30: =AB29+1 -> 27 | AC30: 72 | AD30: 83 | AE30: 50
A31: 30-44 | B31: 4 | F31: 4 | G31: 2 | H31: 2 | I31: 2 | J31: 2 | K31: 3 | L31: 4 | M31: 5 | N31: 1 | O31: 1 | P31: 1 | Q31: 2 | R31: 3 | S31: 4 | T31: 5 | U31: 7 | V31: 7 | W31: 8 | X31: 8 | Y31: 9 | Z31: 9 | AA31: 11 | AB31: =AB30+1 -> 28 | AC31: 73 | AD31: 84 | AE31: 50
A32: 45-59 | B32: 5 | F32: 5 | G32: 3 | H32: 3 | I32: 3 | J32: 3 | K32: 4 | L32: 5 | M32: 6 | N32: 2 | O32: 2 | P32: 2 | Q32: 3 | R32: 4 | S32: 5 | T32: 6 | U32: 9 | V32: 9 | W32: 10 | X32: 10 | Y32: 11 | Z32: 11 | AA32: 13 | AB32: =AB31+1 -> 29 | AC32: 75 | AD32: 86 | AE32: 51
A33: 60-69 | B33: 6 | F33: 6 | G33: 4 | H33: 4 | I33: 4 | J33: 4 | K33: 5 | L33: 6 | M33: 7 | N33: 3 | O33: 3 | P33: 3 | Q33: 4 | R33: 5 | S33: 6 | T33: 7 | U33: 11 | V33: 10 | W33: 11 | X33: 11 | Y33: 13 | Z33: 13 | AA33: 14 | AB33: =AB32+1 -> 30 | AC33: 76 | AD33: 87 | AE33: 52
A34: 70-79 | B34: 7 | F34: 7 | G34: 5 | H34: 5 | I34: 5 | J34: 5 | K34: 6 | L34: 7 | M34: 8 | N34: 4 | O34: 4 | P34: 4 | Q34: 5 | R34: 6 | S34: 7 | T34: 8 | U34: 13 | V34: 11 | W34: 13 | X34: 13 | Y34: 14 | Z34: 14 | AA34: 16 | AB34: =AB33+1 -> 31 | AC34: 77 | AD34: 89 | AE34: 53
A35: 80-90 | B35: 8 | F35: 8 | G35: 6 | H35: 6 | I35: 6 | J35: 6 | K35: 7 | L35: 8 | M35: 9 | N35: 5 | O35: 5 | P35: 5 | Q35: 6 | R35: 7 | S35: 8 | T35: 9 | U35: 14 | V35: 13 | W35: 14 | X35: 14 | Y35: 16 | Z35: 16 | AA35: 17 | AB35: =AB34+1 -> 32 | AC35: 79 | AD35: 90 | AE35: 53
F36: 9 | G36: 7 | H36: 7 | I36: 7 | J36: 7 | K36: 8 | L36: 9 | M36: 10 | N36: 6 | O36: 6 | P36: 6 | Q36: 7 | R36: 8 | S36: 9 | T36: 10 | U36: 15 | V36: 14 | W36: 15 | X36: 16 | Y36: 17 | Z36: 17 | AA36: 18 | AB36: =AB35+1 -> 33 | AC36: 80 | AD36: 92 | AE36: 54
F37: 10 | G37: 8 | H37: 8 | I37: 8 | J37: 8 | K37: 10 | L37: 10 | M37: 12 | N37: 7 | O37: 7 | P37: 7 | Q37: 8 | R37: 9 | S37: 10 | T37: 11 | U37: 16 | V37: 15 | W37: 16 | X37: 17 | Y37: 18 | Z37: 18 | AA37: 19 | AB37: =AB36+1 -> 34 | AC37: 81 | AD37: 93 | AE37: 55
F38: 11 | G38: 9 | H38: 9 | I38: 9 | J38: 10 | K38: 11 | L38: 12 | M38: 13 | N38: 8 | O38: 8 | P38: 8 | Q38: 9 | R38: 10 | S38: 11 | T38: 12 | U38: 17 | V38: 16 | W38: 17 | X38: 18 | Y38: 19 | Z38: 19 | AA38: 19 | AB38: =AB37+1 -> 35 | AC38: 82 | AD38: 94 | AE38: 56
F39: 12 | G39: 10 | H39: 10 | I39: 10 | J39: 11 | K39: 12 | L39: 13 | M39: 14 | N39: 9 | O39: 9 | P39: 9 | Q39: 10 | R39: 11 | S39: 12 | T39: 13 | U39: 18 | V39: 17 | W39: 18 | X39: 19 | Y39: 19 | Z39: 19 | AA39: 19 | AB39: =AB38+1 -> 36 | AC39: 83 | AD39: 96 | AE39: 56
F40: 13 | G40: 12 | H40: 11 | I40: 11 | J40: 12 | K40: 13 | L40: 14 | M40: 15 | N40: 10 | O40: 10 | P40: 10 | Q40: 11 | R40: 12 | S40: 13 | T40: 14 | U40: 19 | V40: 18 | W40: 19 | X40: 19 | Y40: 19 | Z40: 19 | AA40: 19 | AB40: =AB39+1 -> 37 | AC40: 85 | AD40: 97 | AE40: 57
F41: 14 | G41: 13 | H41: 13 | I41: 12 | J41: 13 | K41: 14 | L41: 15 | M41: 16 | N41: 12 | O41: 12 | P41: 12 | Q41: 12 | R41: 13 | S41: 14 | T41: 15 | U41: 19 | V41: 19 | W41: 19 | X41: 19 | Y41: 19 | Z41: 19 | AA41: 19 | AB41: =AB40+1 -> 38 | AC41: 86 | AD41: 98 | AE41: 58
...

Sheet CVLT Alt
F1: ALTERNATE FORM
A2: Truncated Age | C2: ='Scores Summary'!C10 -> 41
A3: Age Range for CVLT | C3: =IF(C2="","",IF(C2>90,"N/A",IF(C2>=80,"80-90",IF(C2>=70,"70-79",IF(C2>=60,"60-69",IF(C2>=45,"45-59",IF(C2>=30,"30-44",IF(C2>=20,"20-29",IF(C2>=16,"16-19","N/A"))))))))) -> 30-44
C5: Raw | D5: ss/SS | G5: T1 Correct | N5: T2 Correct | U5: T3 Correct
A6: Trial 1 Correct | C6: ='Scores Summary 3'!D16 -> 6 | D6: =VLOOKUP(C6,F6:AA23,(VLOOKUP(C3,A28:B35,2,FALSE)),FALSE) -> 10 | F6: Raw | G6: 16-19 | H6: 20-29 | I6: 30-44 | J6: 45-59 | K6: 60-69 | L6: 70-79 | M6: 80-90 | N6: 16-19 | O6: 20-29 | P6: 30-44 | Q6: 45-59 | R6: 60-69 | S6: 70-79 | T6: 80-90 | U6: 16-19 | V6: 20-29 | W6: 30-44 | X6: 45-59 | Y6: 60-69 | Z6: 70-79 | AA6: 80-90 | AB6: Raw | AC6: Trials 1-5 | AD6: Delayed | AE6: Total Rec
A7: Trial 2 Correct | C7: ='Scores Summary 3'!D17 -> 8 | D7: =VLOOKUP(C7,F6:AA23,(VLOOKUP(C3,A28:B35,2,FALSE)+7),FALSE) -> 9 | F7: 0 | G7: 1 | H7: 1 | I7: 1 | J7: 1 | K7: 1 | L7: 1 | M7: 2 | N7: 1 | O7: 1 | P7: 1 | Q7: 1 | R7: 1 | S7: 1 | T7: 1 | U7: 1 | V7: 1 | W7: 1 | X7: 1 | Y7: 1 | Z7: 1 | AA7: 1 | AB7: 4 | AD7: 45
A8: Trial 3 Correct | C8: ='Scores Summary 3'!D18 -> 12 | D8: =VLOOKUP(C8,F6:AA23,(VLOOKUP(C3,A28:B35,2,FALSE)+14),FALSE) -> 11 | F8: 1 | G8: 1 | H8: 1 | I8: 1 | J8: 2 | K8: 2 | L8: 2 | M8: 4 | N8: 1 | O8: 1 | P8: 1 | Q8: 1 | R8: 2 | S8: 2 | T8: 2 | U8: 1 | V8: 1 | W8: 1 | X8: 1 | Y8: 1 | Z8: 1 | AA8: 1 | AB8: =AB7+1 -> 5 | AC8: 45 | AD8: 47
A9: Trial 4 Correct | C9: ='Scores Summary 3'!D19 -> 11 | D9: =VLOOKUP(C9,F26:AA43,(VLOOKUP(C3,A28:B35,2,FALSE)),FALSE) -> 9 | F9: 2 | G9: 2 | H9: 2 | I9: 2 | J9: 4 | K9: 4 | L9: 4 | M9: 6 | N9: 2 | O9: 2 | P9: 2 | Q9: 2 | R9: 3 | S9: 3 | T9: 3 | U9: 1 | V9: 1 | W9: 1 | X9: 1 | Y9: 2 | Z9: 2 | AA9: 2 | AB9: =AB8+1 -> 6 | AC9: 45 | AD9: 49
A10: Trial 5 Correct | C10: ='Scores Summary 3'!D20 -> 12 | D10: =VLOOKUP(C10,F26:AA43,(VLOOKUP(C3,A28:B35,2,FALSE)+7),FALSE) -> 9 | F10: 3 | G10: 4 | H10: 4 | I10: 4 | J10: 5 | K10: 6 | L10: 6 | M10: 8 | N10: 3 | O10: 3 | P10: 3 | Q10: 3 | R10: 4 | S10: 5 | T10: 5 | U10: 2 | V10: 1 | W10: 1 | X10: 2 | Y10: 3 | Z10: 4 | AA10: 4 | AB10: =AB9+1 -> 7 | AC10: 45 | AD10: 51
A11: List B Correct | C11: ='Scores Summary 3'!D21 -> 7 | D11: =VLOOKUP(C11,F26:AA43,(VLOOKUP(C3,A28:B35,2,FALSE)+14),FALSE) -> 13 | F11: 4 | G11: 6 | H11: 6 | I11: 6 | J11: 7 | K11: 8 | L11: 8 | M11: 10 | N11: 4 | O11: 4 | P11: 4 | Q11: 4 | R11: 5 | S11: 6 | T11: 7 | U11: 3 | V11: 2 | W11: 2 | X11: 3 | Y11: 4 | Z11: 5 | AA11: 5 | AB11: =AB10+1 -> 8 | AC11: 46 | AD11: 53
A12: SD Free Recall | C12: ='Scores Summary 3'!D22 -> 7 | D12: =VLOOKUP(C12,F46:AA63,(VLOOKUP(C3,A28:B35,2,FALSE)),FALSE) -> 7 | F12: 5 | G12: 8 | H12: 8 | I12: 8 | J12: 8 | K12: 10 | L12: 10 | M12: 12 | N12: 5 | O12: 5 | P12: 5 | Q12: 5 | R12: 6 | S12: 7 | T12: 8 | U12: 4 | V12: 3 | W12: 3 | X12: 4 | Y12: 5 | Z12: 6 | AA12: 6 | AB12: =AB11+1 -> 9 | AC12: 47 | AD12: 55
A13: SD Cued Recall | C13: ='Scores Summary 3'!D23 -> 7 | D13: =VLOOKUP(C13,F46:AA63,(VLOOKUP(C3,A28:B35,2,FALSE)+7),FALSE) -> 6 | F13: 6 | G13: 10 | H13: 10 | I13: 10 | J13: 10 | K13: 11 | L13: 12 | M13: 14 | N13: 7 | O13: 6 | P13: 6 | Q13: 6 | R13: 7 | S13: 8 | T13: 10 | U13: 5 | V13: 4 | W13: 4 | X13: 5 | Y13: 6 | Z13: 7 | AA13: 8 | AB13: =AB12+1 -> 10 | AC13: 48 | AD13: 57 | AE13: 40
A14: LD Free Recall | C14: ='Scores Summary 3'!D24 -> 9 | D14: =VLOOKUP(C14,F46:AA63,(VLOOKUP(C3,A28:B35,2,FALSE)+14),FALSE) -> 8 | F14: 7 | G14: 11 | H14: 11 | I14: 11 | J14: 11 | K14: 13 | L14: 14 | M14: 15 | N14: 8 | O14: 8 | P14: 8 | Q14: 8 | R14: 9 | S14: 10 | T14: 11 | U14: 6 | V14: 5 | W14: 5 | X14: 6 | Y14: 7 | Z14: 8 | AA14: 10 | AB14: =AB13+1 -> 11 | AC14: 50 | AD14: 58 | AE14: 40
A15: LD Cued Recall | C15: ='Scores Summary 3'!D25 -> 9 | D15: =VLOOKUP(C15,F66:T83,(VLOOKUP(C3,A28:B35,2,FALSE)),FALSE) -> 7 | F15: 8 | G15: 13 | H15: 13 | I15: 13 | J15: 13 | K15: 14 | L15: 15 | M15: 16 | N15: 9 | O15: 9 | P15: 9 | Q15: 9 | R15: 10 | S15: 11 | T15: 13 | U15: 7 | V15: 7 | W15: 7 | X15: 7 | Y15: 9 | Z15: 10 | AA15: 11 | AB15: =AB14+1 -> 12 | AC15: 51 | AD15: 59 | AE15: 40
A16: Trials 1-5 Intrusions | C16: ='Scores Summary 3'!D26 -> 4 | D16: =IF(C16>36,1,VLOOKUP(C16,F86:AA123,(VLOOKUP(C3,A28:B35,2,FALSE)),FALSE)) -> 6 | F16: 9 | G16: 15 | H16: 14 | I16: 14 | J16: 14 | K16: 15 | L16: 16 | M16: 17 | N16: 10 | O16: 10 | P16: 10 | Q16: 10 | R16: 11 | S16: 12 | T16: 14 | U16: 8 | V16: 8 | W16: 8 | X16: 8 | Y16: 10 | Z16: 11 | AA16: 12 | AB16: =AB15+1 -> 13 | AC16: 52 | AD16: 61 | AE16: 40
A17: Free Recall Intrus. | C17: ='Scores Summary 3'!D27 -> 3 | D17: =IF(C17>26,1,VLOOKUP(C17,F86:AA123,(VLOOKUP(C3,A28:B35,2,FALSE)+7),FALSE)) -> 9 | F17: 10 | G17: 17 | H17: 15 | I17: 15 | J17: 15 | K17: 16 | L17: 17 | M17: 18 | N17: 12 | O17: 11 | P17: 11 | Q17: 11 | R17: 12 | S17: 14 | T17: 15 | U17: 9 | V17: 9 | W17: 9 | X17: 10 | Y17: 11 | Z17: 12 | AA17: 13 | AB17: =AB16+1 -> 14 | AC17: 54 | AD17: 63 | AE17: 40
A18: Cued Recall Intrus. | C18: ='Scores Summary 3'!D28 -> 5 | D18: =IF(C18>36,1,VLOOKUP(C18,F86:AA123,(VLOOKUP(C3,A28:B35,2,FALSE)+14),FALSE)) -> 6 | F18: 11 | G18: 18 | H18: 17 | I18: 16 | J18: 16 | K18: 17 | L18: 18 | M18: 19 | N18: 13 | O18: 12 | P18: 12 | Q18: 12 | R18: 13 | S18: 15 | T18: 16 | U18: 10 | V18: 10 | W18: 10 | X18: 11 | Y18: 12 | Z18: 13 | AA18: 14 | AB18: =AB17+1 -> 15 | AC18: 55 | AD18: 65 | AE18: 40
A19: Total Intrusions | C19: ='Scores Summary 3'!D29 -> 8 | D19: =IF(C19>37,1,VLOOKUP(C19,F126:AA164,(VLOOKUP(C3,A28:B35,2,FALSE)),FALSE)) -> 7 | F19: 12 | G19: 19 | H19: 18 | I19: 17 | J19: 17 | K19: 18 | L19: 19 | M19: 19 | N19: 14 | O19: 13 | P19: 13 | Q19: 13 | R19: 15 | S19: 16 | T19: 18 | U19: 11 | V19: 11 | W19: 11 | X19: 12 | Y19: 13 | Z19: 14 | AA19: 15 | AB19: =AB18+1 -> 16 | AC19: 57 | AD19: 67 | AE19: 40
A20: Total Repetitions | C20: ='Scores Summary 3'!D30 -> 9 | D20: =IF(C20>37,1,VLOOKUP(C20,F126:AA164,(VLOOKUP(C3,A28:B35,2,FALSE)+7),FALSE)) -> 8 | F20: 13 | G20: 19 | H20: 19 | I20: 18 | J20: 18 | K20: 19 | L20: 19 | M20: 19 | N20: 15 | O20: 15 | P20: 15 | Q20: 15 | R20: 16 | S20: 18 | T20: 19 | U20: 13 | V20: 12 | W20: 12 | X20: 13 | Y20: 14 | Z20: 15 | AA20: 16 | AB20: =AB19+1 -> 17 | AC20: 58 | AD20: 68 | AE20: 41
A21: Y/N Recog. Hits | C21: ='Scores Summary 3'!D31 -> 12 | D21: =VLOOKUP(C21,F66:T83,(VLOOKUP(C3,A28:B35,2,FALSE)+7),FALSE) -> 5 | F21: 14 | G21: 19 | H21: 19 | I21: 19 | J21: 19 | K21: 19 | L21: 19 | M21: 19 | N21: 16 | O21: 16 | P21: 16 | Q21: 16 | R21: 18 | S21: 19 | T21: 19 | U21: 15 | V21: 13 | W21: 13 | X21: 14 | Y21: 15 | Z21: 16 | AA21: 17 | AB21: =AB20+1 -> 18 | AC21: 60 | AD21: 69 | AE21: 42
A22: Y/N Recog. FPs | C22: ='Scores Summary 3'!D32 -> 2 | D22: =IF(C22>37,1,VLOOKUP(C22,F126:AA164,(VLOOKUP(C3,A28:B35,2,FALSE)+14),FALSE)) -> 9 | F22: 15 | G22: 19 | H22: 19 | I22: 19 | J22: 19 | K22: 19 | L22: 19 | M22: 19 | N22: 18 | O22: 18 | P22: 18 | Q22: 18 | R22: 19 | S22: 19 | T22: 19 | U22: 16 | V22: 15 | W22: 15 | X22: 15 | Y22: 16 | Z22: 17 | AA22: 18 | AB22: =AB21+1 -> 19 | AC22: 61 | AD22: 71 | AE22: 43
A23: Y/N Recog Discrim NP | C23: =ROUND('Scores Summary 3'!D33,0) -> 88 | D23: =IF(C23<44,1,VLOOKUP(C23,F167:M224,(VLOOKUP(C3,A28:B35,2,FALSE)),FALSE)) -> 8 | F23: 16 | G23: 19 | H23: 19 | I23: 19 | J23: 19 | K23: 19 | L23: 19 | M23: 19 | N23: 19 | O23: 19 | P23: 19 | Q23: 19 | R23: 19 | S23: 19 | T23: 19 | U23: 17 | V23: 16 | W23: 16 | X23: 16 | Y23: 17 | Z23: 18 | AA23: 19 | AB23: =AB22+1 -> 20 | AC23: 63 | AD23: 72 | AE23: 44
A24: Trials 1-5 Correct | C24: ='Scores Summary 3'!D37 -> 48 | D24: =VLOOKUP(C24,AB6:AE193,2,FALSE) -> 98 | AB24: =AB23+1 -> 21 | AC24: 64 | AD24: 74 | AE24: 45
A25: Delayed Recall Correct | C25: ='Scores Summary 3'!D38 -> 28 | D25: =VLOOKUP(C25,AB6:AE193,3,FALSE) -> 84 | G25: T4 Correct | N25: T5 Correct | U25: List B Correct | AB25: =AB24+1 -> 22 | AC25: 66 | AD25: 75 | AE25: 45
A26: Total Recall Correct | C26: ='Scores Summary 3'!D39 -> 89 | D26: =VLOOKUP(C26,AB6:AE193,4,FALSE) -> 94 | F26: Raw | G26: 16-19 | H26: 20-29 | I26: 30-44 | J26: 45-59 | K26: 60-69 | L26: 70-79 | M26: 80-90 | N26: 16-19 | O26: 20-29 | P26: 30-44 | Q26: 45-59 | R26: 60-69 | S26: 70-79 | T26: 80-90 | U26: 16-19 | V26: 20-29 | W26: 30-44 | X26: 45-59 | Y26: 60-69 | Z26: 70-79 | AA26: 80-90 | AB26: =AB25+1 -> 23 | AC26: 67 | AD26: 77 | AE26: 46
F27: 0 | G27: 1 | H27: 1 | I27: 1 | J27: 1 | K27: 1 | L27: 1 | M27: 1 | N27: 1 | O27: 1 | P27: 1 | Q27: 1 | R27: 1 | S27: 1 | T27: 1 | U27: 1 | V27: 1 | W27: 1 | X27: 1 | Y27: 3 | Z27: 3 | AA27: 3 | AB27: =AB26+1 -> 24 | AC27: 69 | AD27: 79 | AE27: 47
A28: Age | B28: Column | F28: 1 | G28: 1 | H28: 1 | I28: 1 | J28: 1 | K28: 1 | L28: 1 | M28: 2 | N28: 1 | O28: 1 | P28: 1 | Q28: 1 | R28: 1 | S28: 1 | T28: 2 | U28: 2 | V28: 2 | W28: 2 | X28: 2 | Y28: 5 | Z28: 5 | AA28: 5 | AB28: =AB27+1 -> 25 | AC28: 70 | AD28: 80 | AE28: 48
A29: 16-19 | B29: 2 | F29: 2 | G29: 1 | H29: 1 | I29: 1 | J29: 1 | K29: 1 | L29: 2 | M29: 3 | N29: 1 | O29: 1 | P29: 1 | Q29: 1 | R29: 1 | S29: 2 | T29: 3 | U29: 4 | V29: 4 | W29: 4 | X29: 4 | Y29: 6 | Z29: 6 | AA29: 7 | AB29: =AB28+1 -> 26 | AC29: 71 | AD29: 81 | AE29: 49
A30: 20-29 | B30: 3 | F30: 3 | G30: 1 | H30: 1 | I30: 1 | J30: 1 | K30: 2 | L30: 3 | M30: 4 | N30: 1 | O30: 1 | P30: 1 | Q30: 1 | R30: 2 | S30: 3 | T30: 4 | U30: 6 | V30: 6 | W30: 6 | X30: 6 | Y30: 7 | Z30: 7 | AA30: 9 | AB30: =AB29+1 -> 27 | AC30: 72 | AD30: 83 | AE30: 50
A31: 30-44 | B31: 4 | F31: 4 | G31: 2 | H31: 2 | I31: 2 | J31: 2 | K31: 3 | L31: 4 | M31: 5 | N31: 1 | O31: 1 | P31: 1 | Q31: 2 | R31: 3 | S31: 4 | T31: 5 | U31: 7 | V31: 7 | W31: 8 | X31: 8 | Y31: 9 | Z31: 9 | AA31: 11 | AB31: =AB30+1 -> 28 | AC31: 73 | AD31: 84 | AE31: 50
A32: 45-59 | B32: 5 | F32: 5 | G32: 3 | H32: 3 | I32: 3 | J32: 3 | K32: 4 | L32: 5 | M32: 6 | N32: 2 | O32: 2 | P32: 2 | Q32: 3 | R32: 4 | S32: 5 | T32: 6 | U32: 9 | V32: 9 | W32: 10 | X32: 10 | Y32: 11 | Z32: 11 | AA32: 13 | AB32: =AB31+1 -> 29 | AC32: 75 | AD32: 86 | AE32: 51
A33: 60-69 | B33: 6 | F33: 6 | G33: 4 | H33: 4 | I33: 4 | J33: 4 | K33: 5 | L33: 6 | M33: 7 | N33: 3 | O33: 3 | P33: 3 | Q33: 4 | R33: 5 | S33: 6 | T33: 7 | U33: 11 | V33: 10 | W33: 11 | X33: 11 | Y33: 13 | Z33: 13 | AA33: 14 | AB33: =AB32+1 -> 30 | AC33: 76 | AD33: 87 | AE33: 52
A34: 70-79 | B34: 7 | F34: 7 | G34: 5 | H34: 5 | I34: 5 | J34: 5 | K34: 6 | L34: 7 | M34: 8 | N34: 4 | O34: 4 | P34: 4 | Q34: 5 | R34: 6 | S34: 7 | T34: 8 | U34: 13 | V34: 11 | W34: 13 | X34: 13 | Y34: 14 | Z34: 14 | AA34: 16 | AB34: =AB33+1 -> 31 | AC34: 77 | AD34: 89 | AE34: 53
A35: 80-90 | B35: 8 | F35: 8 | G35: 6 | H35: 6 | I35: 6 | J35: 6 | K35: 7 | L35: 8 | M35: 9 | N35: 5 | O35: 5 | P35: 5 | Q35: 6 | R35: 7 | S35: 8 | T35: 9 | U35: 14 | V35: 13 | W35: 14 | X35: 14 | Y35: 16 | Z35: 16 | AA35: 17 | AB35: =AB34+1 -> 32 | AC35: 79 | AD35: 90 | AE35: 53
F36: 9 | G36: 7 | H36: 7 | I36: 7 | J36: 7 | K36: 8 | L36: 9 | M36: 10 | N36: 6 | O36: 6 | P36: 6 | Q36: 7 | R36: 8 | S36: 9 | T36: 10 | U36: 15 | V36: 14 | W36: 15 | X36: 16 | Y36: 17 | Z36: 17 | AA36: 18 | AB36: =AB35+1 -> 33 | AC36: 80 | AD36: 92 | AE36: 54
F37: 10 | G37: 8 | H37: 8 | I37: 8 | J37: 8 | K37: 10 | L37: 10 | M37: 12 | N37: 7 | O37: 7 | P37: 7 | Q37: 8 | R37: 9 | S37: 10 | T37: 11 | U37: 16 | V37: 15 | W37: 16 | X37: 17 | Y37: 18 | Z37: 18 | AA37: 19 | AB37: =AB36+1 -> 34 | AC37: 81 | AD37: 93 | AE37: 55
F38: 11 | G38: 9 | H38: 9 | I38: 9 | J38: 10 | K38: 11 | L38: 12 | M38: 13 | N38: 8 | O38: 8 | P38: 8 | Q38: 9 | R38: 10 | S38: 11 | T38: 12 | U38: 17 | V38: 16 | W38: 17 | X38: 18 | Y38: 19 | Z38: 19 | AA38: 19 | AB38: =AB37+1 -> 35 | AC38: 82 | AD38: 94 | AE38: 56
F39: 12 | G39: 10 | H39: 10 | I39: 10 | J39: 11 | K39: 12 | L39: 13 | M39: 14 | N39: 9 | O39: 9 | P39: 9 | Q39: 10 | R39: 11 | S39: 12 | T39: 13 | U39: 18 | V39: 17 | W39: 18 | X39: 19 | Y39: 19 | Z39: 19 | AA39: 19 | AB39: =AB38+1 -> 36 | AC39: 83 | AD39: 96 | AE39: 56
F40: 13 | G40: 12 | H40: 11 | I40: 11 | J40: 12 | K40: 13 | L40: 14 | M40: 15 | N40: 10 | O40: 10 | P40: 10 | Q40: 11 | R40: 12 | S40: 13 | T40: 14 | U40: 19 | V40: 18 | W40: 19 | X40: 19 | Y40: 19 | Z40: 19 | AA40: 19 | AB40: =AB39+1 -> 37 | AC40: 85 | AD40: 97 | AE40: 57
F41: 14 | G41: 13 | H41: 13 | I41: 12 | J41: 13 | K41: 14 | L41: 15 | M41: 16 | N41: 12 | O41: 12 | P41: 12 | Q41: 12 | R41: 13 | S41: 14 | T41: 15 | U41: 19 | V41: 19 | W41: 19 | X41: 19 | Y41: 19 | Z41: 19 | AA41: 19 | AB41: =AB40+1 -> 38 | AC41: 86 | AD41: 98 | AE41: 58
...

Sheet CVLT-3 (Contrast)
A1: Scale | C1: Scaled | E1: LIST B VS. T1 CONTRAST SCORES | O1: SDFR VS. T5 CONTRAST SCORES
A2: Trial 1 Correct | C2: ='Scores Summary 3'!E16 -> 10 | E2: List B | F2: 1-3 | G2: 4-5 | H2: 6-7 | I2: 8-9 | J2: 10-11 | K2: 12-13 | L2: 14-15 | M2: 16-19 | O2: SDFR | P2: 1-3 | Q2: 4-5 | R2: 6-7 | S2: 8-9 | T2: 10-11 | U2: 12-13 | V2: 14-15 | W2: 16-19
A3: Trial 5 Correct | C3: ='Scores Summary 3'!E20 -> 9 | E3: 1 | F3: 2 | G3: 1 | H3: 1 | I3: 1 | J3: 1 | K3: 1 | L3: 1 | M3: 1 | O3: 1 | P3: 3 | Q3: 2 | R3: 1 | S3: 1 | T3: 1 | U3: 1 | V3: 1 | W3: 1
A4: List B Correct | C4: ='Scores Summary 3'!E21 -> 13 | E4: 2 | F4: 4 | G4: 3 | H4: 2 | I4: 2 | J4: 1 | K4: 1 | L4: 1 | M4: 1 | O4: 2 | P4: 5 | Q4: 3 | R4: 2 | S4: 1 | T4: 1 | U4: 1 | V4: 1 | W4: 1
A5: SD Free Recall | C5: ='Scores Summary 3'!E22 -> 7 | E5: 3 | F5: 5 | G5: 4 | H5: 3 | I5: 3 | J5: 2 | K5: 2 | L5: 1 | M5: 1 | O5: 3 | P5: 7 | Q5: 5 | R5: 3 | S5: 2 | T5: 1 | U5: 1 | V5: 1 | W5: 1
A6: LD Free Recall | C6: ='Scores Summary 3'!E24 -> 8 | E6: 4 | F6: 7 | G6: 5 | H6: 4 | I6: 4 | J6: 3 | K6: 3 | L6: 2 | M6: 2 | O6: 4 | P6: 8 | Q6: 7 | R6: 5 | S6: 3 | T6: 2 | U6: 1 | V6: 1 | W6: 1
A7: Y/N Recog Discrim NP | C7: ='Scores Summary 3'!E33 -> 8 | E7: 5 | F7: 8 | G7: 7 | H7: 5 | I7: 5 | J7: 4 | K7: 4 | L7: 3 | M7: 3 | O7: 5 | P7: 10 | Q7: 8 | R7: 7 | S7: 5 | T7: 3 | U7: 1 | V7: 1 | W7: 1
E8: 6 | F8: 9 | G8: 8 | H8: 7 | I8: 6 | J8: 5 | K8: 5 | L8: 4 | M8: 4 | O8: 6 | P8: 12 | Q8: 10 | R8: 8 | S8: 6 | T8: 4 | U8: 2 | V8: 1 | W8: 1
A9: List B vs. T1 | C9: =IF(C4="","",IF(C2="","",VLOOKUP(C4,E3:M21,VLOOKUP(C2,E24:G42,3,FALSE)))) -> 13 | E9: 7 | F9: 9 | G9: 9 | H9: 8 | I9: 8 | J9: 6 | K9: 6 | L9: 5 | M9: 5 | O9: 7 | P9: 14 | Q9: 12 | R9: 9 | S9: 7 | T9: 5 | U9: 3 | V9: 2 | W9: 1
A10: SDFR vs. T5 | C10: =IF(C5="","",IF(C3="","",VLOOKUP(C5,O2:W21,VLOOKUP(C3,E24:G42,3,FALSE)))) -> 7 | E10: 8 | F10: 10 | G10: 10 | H10: 9 | I10: 9 | J10: 8 | K10: 7 | L10: 6 | M10: 6 | O10: 8 | P10: 16 | Q10: 14 | R10: 11 | S10: 9 | T10: 6 | U10: 4 | V10: 3 | W10: 2
A11: LDFR vs. T5 | C11: =IF(C6="","",IF(C3="","",VLOOKUP(C6,H23:P42,VLOOKUP(C3,E24:G42,3,FALSE)))) -> 9 | E11: 9 | F11: 11 | G11: 11 | H11: 10 | I11: 10 | J11: 9 | K11: 8 | L11: 7 | M11: 7 | O11: 9 | P11: 18 | Q11: 16 | R11: 13 | S11: 10 | T11: 8 | U11: 5 | V11: 4 | W11: 3
A12: LDFR vs. SDFR | C12: =IF(C6="","",IF(C5="","",VLOOKUP(C6,Q23:Y42,VLOOKUP(C5,E24:G42,3,FALSE)))) -> 12 | E12: 10 | F12: 12 | G12: 12 | H12: 12 | I12: 11 | J12: 10 | K12: 9 | L12: 8 | M12: 8 | O12: 10 | P12: 19 | Q12: 18 | R12: 15 | S12: 12 | T12: 9 | U12: 7 | V12: 5 | W12: 4
A13: LDFR vs. Recog. | C13: =IF(C6="","",IF(C7="","",VLOOKUP(C6,Z23:AH42,VLOOKUP(C7,E24:G42,3,FALSE)))) -> 9 | E13: 11 | F13: 13 | G13: 13 | H13: 13 | I13: 12 | J13: 11 | K13: 10 | L13: 9 | M13: 9 | O13: 11 | P13: 19 | Q13: 19 | R13: 17 | S13: 13 | T13: 11 | U13: 9 | V13: 7 | W13: 6
E14: 12 | F14: 14 | G14: 14 | H14: 14 | I14: 13 | J14: 12 | K14: 11 | L14: 10 | M14: 10 | O14: 12 | P14: 19 | Q14: 19 | R14: 19 | S14: 15 | T14: 12 | U14: 10 | V14: 8 | W14: 7
E15: 13 | F15: 15 | G15: 15 | H15: 15 | I15: 14 | J15: 13 | K15: 12 | L15: 11 | M15: 11 | O15: 13 | P15: 19 | Q15: 19 | R15: 19 | S15: 17 | T15: 14 | U15: 12 | V15: 9 | W15: 8
E16: 14 | F16: 16 | G16: 16 | H16: 16 | I16: 15 | J16: 15 | K16: 13 | L16: 12 | M16: 12 | O16: 14 | P16: 19 | Q16: 19 | R16: 19 | S16: 19 | T16: 16 | U16: 13 | V16: 11 | W16: 10
E17: 15 | F17: 17 | G17: 17 | H17: 17 | I17: 16 | J17: 16 | K17: 14 | L17: 14 | M17: 14 | O17: 15 | P17: 19 | Q17: 19 | R17: 19 | S17: 19 | T17: 18 | U17: 15 | V17: 12 | W17: 11
E18: 16 | F18: 18 | G18: 18 | H18: 18 | I18: 17 | J18: 17 | K18: 15 | L18: 15 | M18: 15 | O18: 16 | P18: 19 | Q18: 19 | R18: 19 | S18: 19 | T18: 19 | U18: 17 | V18: 14 | W18: 13
E19: 17 | F19: 19 | G19: 19 | H19: 19 | I19: 18 | J19: 18 | K19: 16 | L19: 16 | M19: 16 | O19: 17 | P19: 19 | Q19: 19 | R19: 19 | S19: 19 | T19: 19 | U19: 19 | V19: 16 | W19: 15
E20: 18 | F20: 19 | G20: 19 | H20: 19 | I20: 19 | J20: 19 | K20: 18 | L20: 18 | M20: 18 | O20: 18 | P20: 19 | Q20: 19 | R20: 19 | S20: 19 | T20: 19 | U20: 19 | V20: 18 | W20: 17
E21: 19 | F21: 19 | G21: 19 | H21: 19 | I21: 19 | J21: 19 | K21: 19 | L21: 19 | M21: 19 | O21: 19 | P21: 19 | Q21: 19 | R21: 19 | S21: 19 | T21: 19 | U21: 19 | V21: 19 | W21: 19
I22: LDFR VS. T5 CONTRAST SCORES | R22: LDFR VS. SDFR CONTRAST SCORES | AA22: LDFR VS. RECOG CONTRAST SCORES
E23: LDFR | F23: Range | G23: Column | I23: 1-3 | J23: 4-5 | K23: 6-7 | L23: 8-9 | M23: 10-11 | N23: 12-13 | O23: 14-15 | P23: 16-19 | R23: 1-3 | S23: 4-5 | T23: 6-7 | U23: 8-9 | V23: 10-11 | W23: 12-13 | X23: 14-15 | Y23: 16-19 | AA23: 1-3 | AB23: 4-5 | AC23: 6-7 | AD23: 8-9 | AE23: 10-11 | AF23: 12-13 | AG23: 14-15 | AH23: 16-19
E24: 1 | F24: 1-3 | G24: 2 | H24: 1 | I24: 4 | J24: 2 | K24: 1 | L24: 1 | M24: 1 | N24: 1 | O24: 1 | P24: 1 | Q24: 1 | R24: 3 | S24: 1 | T24: 1 | U24: 1 | V24: 1 | W24: 1 | X24: 1 | Y24: 1 | Z24: 1 | AA24: 4 | AB24: 3 | AC24: 1 | AD24: 1 | AE24: 1 | AF24: 1 | AG24: 1 | AH24: 1
E25: 2 | F25: 1-3 | G25: 2 | H25: 2 | I25: 6 | J25: 4 | K25: 1 | L25: 1 | M25: 1 | N25: 1 | O25: 1 | P25: 1 | Q25: 2 | R25: 6 | S25: 3 | T25: 1 | U25: 1 | V25: 1 | W25: 1 | X25: 1 | Y25: 1 | Z25: 2 | AA25: 6 | AB25: 5 | AC25: 2 | AD25: 1 | AE25: 1 | AF25: 1 | AG25: 1 | AH25: 1
E26: 3 | F26: 1-3 | G26: 2 | H26: 3 | I26: 7 | J26: 6 | K26: 2 | L26: 1 | M26: 1 | N26: 1 | O26: 1 | P26: 1 | Q26: 3 | R26: 8 | S26: 5 | T26: 2 | U26: 1 | V26: 1 | W26: 1 | X26: 1 | Y26: 1 | Z26: 3 | AA26: 7 | AB26: 6 | AC26: 3 | AD26: 1 | AE26: 1 | AF26: 1 | AG26: 1 | AH26: 1
E27: 4 | F27: 4-5 | G27: 3 | H27: 4 | I27: 8 | J27: 7 | K27: 4 | L27: 1 | M27: 1 | N27: 1 | O27: 1 | P27: 1 | Q27: 4 | R27: 10 | S27: 7 | T27: 4 | U27: 1 | V27: 1 | W27: 1 | X27: 1 | Y27: 1 | Z27: 4 | AA27: 8 | AB27: 7 | AC27: 4 | AD27: 2 | AE27: 1 | AF27: 1 | AG27: 1 | AH27: 1
E28: 5 | F28: 4-5 | G28: 3 | H28: 5 | I28: 9 | J28: 8 | K28: 6 | L28: 3 | M28: 1 | N28: 1 | O28: 1 | P28: 1 | Q28: 5 | R28: 11 | S28: 9 | T28: 6 | U28: 3 | V28: 1 | W28: 1 | X28: 1 | Y28: 1 | Z28: 5 | AA28: 9 | AB28: 8 | AC28: 5 | AD28: 3 | AE28: 2 | AF28: 1 | AG28: 1 | AH28: 1
E29: 6 | F29: 6-7 | G29: 4 | H29: 6 | I29: 11 | J29: 10 | K29: 8 | L29: 5 | M29: 3 | N29: 1 | O29: 1 | P29: 1 | Q29: 6 | R29: 13 | S29: 11 | T29: 8 | U29: 5 | V29: 2 | W29: 1 | X29: 1 | Y29: 1 | Z29: 6 | AA29: 11 | AB29: 10 | AC29: 7 | AD29: 5 | AE29: 3 | AF29: 2 | AG29: 1 | AH29: 1
E30: 7 | F30: 6-7 | G30: 4 | H30: 7 | I30: 13 | J30: 12 | K30: 10 | L30: 7 | M30: 5 | N30: 3 | O30: 1 | P30: 1 | Q30: 7 | R30: 15 | S30: 13 | T30: 10 | U30: 7 | V30: 4 | W30: 2 | X30: 1 | Y30: 1 | Z30: 7 | AA30: 13 | AB30: 12 | AC30: 9 | AD30: 7 | AE30: 5 | AF30: 4 | AG30: 2 | AH30: 1
E31: 8 | F31: 8-9 | G31: 5 | H31: 8 | I31: 15 | J31: 14 | K31: 12 | L31: 9 | M31: 7 | N31: 5 | O31: 2 | P31: 1 | Q31: 8 | R31: 16 | S31: 15 | T31: 12 | U31: 9 | V31: 6 | W31: 4 | X31: 2 | Y31: 1 | Z31: 8 | AA31: 15 | AB31: 13 | AC31: 11 | AD31: 9 | AE31: 7 | AF31: 6 | AG31: 4 | AH31: 2
E32: 9 | F32: 8-9 | G32: 5 | H32: 9 | I32: 17 | J32: 15 | K32: 14 | L32: 11 | M32: 8 | N32: 6 | O32: 4 | P32: 3 | Q32: 9 | R32: 17 | S32: 16 | T32: 14 | U32: 11 | V32: 8 | W32: 5 | X32: 3 | Y32: 1 | Z32: 9 | AA32: 17 | AB32: 15 | AC32: 13 | AD32: 10 | AE32: 8 | AF32: 7 | AG32: 5 | AH32: 4
E33: 10 | F33: 10-11 | G33: 6 | H33: 10 | I33: 19 | J33: 17 | K33: 15 | L33: 12 | M33: 9 | N33: 7 | O33: 5 | P33: 4 | Q33: 10 | R33: 18 | S33: 17 | T33: 15 | U33: 12 | V33: 9 | W33: 6 | X33: 4 | Y33: 2 | Z33: 10 | AA33: 19 | AB33: 17 | AC33: 14 | AD33: 11 | AE33: 10 | AF33: 8 | AG33: 6 | AH33: 5
E34: 11 | F34: 10-11 | G34: 6 | H34: 11 | I34: 19 | J34: 19 | K34: 16 | L34: 13 | M34: 11 | N34: 8 | O34: 6 | P34: 5 | Q34: 11 | R34: 19 | S34: 18 | T34: 16 | U34: 14 | V34: 11 | W34: 8 | X34: 5 | Y34: 3 | Z34: 11 | AA34: 19 | AB34: 19 | AC34: 16 | AD34: 13 | AE34: 11 | AF34: 9 | AG34: 7 | AH34: 6
E35: 12 | F35: 12-13 | G35: 7 | H35: 12 | I35: 19 | J35: 19 | K35: 19 | L35: 15 | M35: 12 | N35: 10 | O35: 7 | P35: 6 | Q35: 12 | R35: 19 | S35: 19 | T35: 18 | U35: 15 | V35: 13 | W35: 10 | X35: 7 | Y35: 4 | Z35: 12 | AA35: 19 | AB35: 19 | AC35: 18 | AD35: 14 | AE35: 12 | AF35: 10 | AG35: 8 | AH35: 7
... E42: 19 | F42: 16-19 | G42: 9 | H42: 19 | I42: 19 | J42: 19 | K42: 19 | L42: 19 | M42: 19 | N42: 19 | O42: 19 | P42: 19 | Q42: 19 | R42: 19 | S42: 19 | T42: 19 | U42: 19 | V42: 19 | W42: 19 | X42: 19 | Y42: 19 | Z42: 19 | AA42: 19 | AB42: 19 | AC42: 19 | AD42: 19 | AE42: 19 | AF42: 19 | AG42: 19 | AH42: 19

Sheet Heaton Appx C
B1: Raw | E1: Raw | H1: Raw | K1: Rounded | N1: Rounded | Q1: Rounded | T1: Rounded | W1: Rounded | Z1: Rounded | AC1: Rounded | AF1: Rounded
A2: Boston Naming | B2: =IF('Scores Summary 2'!D20="","",'Scores Summary 2'!D20) | D2: FAS | E2: =IF('Scores Summary 2'!D16="","",'Scores Summary 2'!D16) | G2: Animals | H2: =IF('Scores Summary 2'!D17="","",'Scores Summary 2'!D17) | J2: Trails A | K2: =IF('Scores Summary 2'!D18="","",ROUND('Scores Summary 2'!D18,0)) | M2: Trails B | N2: =IF('Scores Summary 2'!D19="","",IF(ROUND('Scores Summary 2'!D19,0)>=300,"300+",ROUND('Scores Summary 2'!D19,0))) | P2: Grooved DH | Q2: =IF('Scores Summary 2'!D21="","",IF(ROUND('Scores Summary 2'!D21,0)>=166,"166+",ROUND('Scores Summary 2'!D21,0))) | S2: Grooved NDH | T2: =IF('Scores Summary 2'!D22="","",IF(ROUND('Scores Summary 2'!D22,0)>=202,"202+",ROUND('Scores Summary 2'!D22,0))) | V2: FTT DH | W2: =IF('Scores Summary 2'!D23="","",IF(ROUND('Scores Summary 2'!D23,1)>=71.1,"71.1+",ROUND('Scores Summary 2'!D23,1))) | Y2: FTT NDH | Z2: =IF('Scores Summary 2'!D24="","",IF(ROUND('Scores Summary 2'!D24,1)>=68.1,"68.1+",ROUND('Scores Summary 2'!D24,1))) | AB2: Grip DH | AE2: Grip NDH
V3: SS | W3: =IF(W2="","",IF(W2="71.1+",19,IF(W2>=70.1,18,IF(W2>=67.6,17,IF(W2>=64.9,16,IF(W2>=62.5,15,IF(W2>=59.5,14,IF(W2>=57.3,13,IF(W2>=55.3,12,IF(W2>=53.2,11,IF(W2>=51.3,10,IF(W2>=47.8,9,IF(W2>=45.1,8,IF(W2>=42.1,7,IF(W2>=38.3,6,IF(W2>=35.1,5,IF(W2>=32.1,4,IF(W2>=27.1,3,IF(W2>=23.1,2,IF(W2>=21.3,1,IF(W2>=0,0,""))))))))))))))))))))) | Y3: SS | Z3: =IF(Z2="","",IF(Z2="68.1+",19,IF(Z2>=64,18,IF(Z2>=63,17,IF(Z2>=58.1,16,IF(Z2>=57,15,IF(Z2>=54,14,IF(Z2>=52,13,IF(Z2>=50.1,12,IF(Z2>=48,11,IF(Z2>=45.1,10,IF(Z2>=43,9,IF(Z2>=40.1,8,IF(Z2>=37.1,7,IF(Z2>=35,6,IF(Z2>=31.1,5,IF(Z2>=29,4,IF(Z2>=25.1,3,IF(Z2>=23.1,2,IF(Z2>=22.1,1,IF(Z2>=0,0,"")))))))))))))))))))))
A4: Boston Naming | B4: Scaled | D4: FAS | E4: Scaled | G4: Animals | H4: Scaled | J4: Trails A | K4: Scaled | M4: Trails B | N4: Scaled | P4: GPB DH | Q4: Scaled | S4: GBP NDH | T4: Scaled
A5: 60 | B5: 16 | D5: 78 | E5: 18 | G5: 38 | H5: 18 | J5: 91 | K5: 2 | M5: 25 | N5: 18 | P5: 46 | Q5: 18 | S5: 45 | T5: 18
A6: =A5-1 -> 59 | B6: 14 | D6: =D5-1 -> 77 | E6: 18 | G6: =G5-1 -> 37 | H6: 18 | J6: =J5-1 -> 90 | K6: 2 | M6: =M5+1 -> 26 | N6: 18 | P6: =P5+1 -> 47 | Q6: 17 | S6: =S5+1 -> 46 | T6: 18
A7: =A6-1 -> 58 | B7: 13 | D7: =D6-1 -> 76 | E7: 18 | G7: =G6-1 -> 36 | H7: 18 | J7: =J6-1 -> 89 | K7: 2 | M7: =M6+1 -> 27 | N7: 18 | P7: =P6+1 -> 48 | Q7: 16 | S7: =S6+1 -> 47 | T7: 18
A8: =A7-1 -> 57 | B8: 11 | D8: =D7-1 -> 75 | E8: 18 | G8: =G7-1 -> 35 | H8: 17 | J8: =J7-1 -> 88 | K8: 2 | M8: =M7+1 -> 28 | N8: 17 | P8: =P7+1 -> 49 | Q8: 16 | S8: =S7+1 -> 48 | T8: 18
A9: =A8-1 -> 56 | B9: 10 | D9: =D8-1 -> 74 | E9: 18 | G9: =G8-1 -> 34 | H9: 17 | J9: =J8-1 -> 87 | K9: 2 | M9: =M8+1 -> 29 | N9: 16 | P9: =P8+1 -> 50 | Q9: 15 | S9: =S8+1 -> 49 | T9: 17
A10: =A9-1 -> 55 | B10: 9 | D10: =D9-1 -> 73 | E10: 18 | G10: =G9-1 -> 33 | H10: 16 | J10: =J9-1 -> 86 | K10: 2 | M10: =M9+1 -> 30 | N10: 16 | P10: =P9+1 -> 51 | Q10: 15 | S10: =S9+1 -> 50 | T10: 17
A11: =A10-1 -> 54 | B11: 9 | D11: =D10-1 -> 72 | E11: 17 | G11: =G10-1 -> 32 | H11: 16 | J11: =J10-1 -> 85 | K11: 2 | M11: =M10+1 -> 31 | N11: 16 | P11: =P10+1 -> 52 | Q11: 14 | S11: =S10+1 -> 51 | T11: 17
A12: =A11-1 -> 53 | B12: 8 | D12: =D11-1 -> 71 | E12: 17 | G12: =G11-1 -> 31 | H12: 15 | J12: =J11-1 -> 84 | K12: 2 | M12: =M11+1 -> 32 | N12: 16 | P12: =P11+1 -> 53 | Q12: 14 | S12: =S11+1 -> 52 | T12: 16
A13: =A12-1 -> 52 | B13: 8 | D13: =D12-1 -> 70 | E13: 17 | G13: =G12-1 -> 30 | H13: 15 | J13: =J12-1 -> 83 | K13: 2 | M13: =M12+1 -> 33 | N13: 16 | P13: =P12+1 -> 54 | Q13: 13 | S13: =S12+1 -> 53 | T13: 15
A14: =A13-1 -> 51 | B14: 8 | D14: =D13-1 -> 69 | E14: 17 | G14: =G13-1 -> 29 | H14: 14 | J14: =J13-1 -> 82 | K14: 2 | M14: =M13+1 -> 34 | N14: 15 | P14: =P13+1 -> 55 | Q14: 13 | S14: =S13+1 -> 54 | T14: 15
A15: =A14-1 -> 50 | B15: 7 | D15: =D14-1 -> 68 | E15: 17 | G15: =G14-1 -> 28 | H15: 14 | J15: =J14-1 -> 81 | K15: 2 | M15: =M14+1 -> 35 | N15: 15 | P15: =P14+1 -> 56 | Q15: 13 | S15: =S14+1 -> 55 | T15: 15
A16: =A15-1 -> 49 | B16: 7 | D16: =D15-1 -> 67 | E16: 17 | G16: =G15-1 -> 27 | H16: 13 | J16: =J15-1 -> 80 | K16: 3 | M16: =M15+1 -> 36 | N16: 15 | P16: =P15+1 -> 57 | Q16: 12 | S16: =S15+1 -> 56 | T16: 14
A17: =A16-1 -> 48 | B17: 7 | D17: =D16-1 -> 66 | E17: 16 | G17: =G16-1 -> 26 | H17: 13 | J17: =J16-1 -> 79 | K17: 3 | M17: =M16+1 -> 37 | N17: 15 | P17: =P16+1 -> 58 | Q17: 12 | S17: =S16+1 -> 57 | T17: 14
... A43: =A42-1 -> 22 | B43: 2 | D43: =D42-1 -> 40 | E43: 10 | G43: =G42-1 -> 0 | H43: 0 | J43: =J42-1 -> 53 | K43: 5 | M43: =M42+1 -> 63 | N43: 11 | P43: =P42+1 -> 84 | Q43: 6 | S43: =S42+1 -> 83 | T43: 7
A44: =A43-1 -> 21 | B44: 2 | D44: =D43-1 -> 39 | E44: 10 | J44: =J43-1 -> 52 | K44: 6 | M44: =M43+1 -> 64 | N44: 10 | P44: =P43+1 -> 85 | Q44: 6 | S44: =S43+1 -> 84 | T44: 7
A45: =A44-1 -> 20 | B45: 2 | D45: =D44-1 -> 38 | E45: 10 | J45: =J44-1 -> 51 | K45: 6 | M45: =M44+1 -> 65 | N45: 10 | P45: =P44+1 -> 86 | Q45: 6 | S45: =S44+1 -> 85 | T45: 7
A46: =A45-1 -> 19 | B46: 2 | D46: =D45-1 -> 37 | E46: 9 | J46: =J45-1 -> 50 | K46: 6 | M46: =M45+1 -> 66 | N46: 10 | P46: =P45+1 -> 87 | Q46: 6 | S46: =S45+1 -> 86 | T46: 7
A47: =A46-1 -> 18 | B47: 2 | D47: =D46-1 -> 36 | E47: 9 | J47: =J46-1 -> 49 | K47: 6 | M47: =M46+1 -> 67 | N47: 10 | P47: =P46+1 -> 88 | Q47: 6 | S47: =S46+1 -> 87 | T47: 7
A48: =A47-1 -> 17 | B48: 2 | D48: =D47-1 -> 35 | E48: 9 | J48: =J47-1 -> 48 | K48: 6 | M48: =M47+1 -> 68 | N48: 10 | P48: =P47+1 -> 89 | Q48: 5 | S48: =S47+1 -> 88 | T48: 7
A49: =A48-1 -> 16 | B49: 2 | D49: =D48-1 -> 34 | E49: 9 | J49: =J48-1 -> 47 | K49: 6 | M49: =M48+1 -> 69 | N49: 10 | P49: =P48+1 -> 90 | Q49: 5 | S49: =S48+1 -> 89 | T49: 6
A50: =A49-1 -> 15 | B50: 2 | D50: =D49-1 -> 33 | E50: 8 | J50: =J49-1 -> 46 | K50: 6 | M50: =M49+1 -> 70 | N50: 10 | P50: =P49+1 -> 91 | Q50: 5 | S50: =S49+1 -> 90 | T50: 6
A51: =A50-1 -> 14 | B51: 2 | D51: =D50-1 -> 32 | E51: 8 | J51: =J50-1 -> 45 | K51: 6 | M51: =M50+1 -> 71 | N51: 10 | P51: =P50+1 -> 92 | Q51: 5 | S51: =S50+1 -> 91 | T51: 6
A52: =A51-1 -> 13 | B52: 1 | D52: =D51-1 -> 31 | E52: 8 | J52: =J51-1 -> 44 | K52: 7 | M52: =M51+1 -> 72 | N52: 10 | P52: =P51+1 -> 93 | Q52: 5 | S52: =S51+1 -> 92 | T52: 6
A53: =A52-1 -> 12 | B53: 1 | D53: =D52-1 -> 30 | E53: 8 | J53: =J52-1 -> 43 | K53: 7 | M53: =M52+1 -> 73 | N53: 10 | P53: =P52+1 -> 94 | Q53: 5 | S53: =S52+1 -> 93 | T53: 6
A54: =A53-1 -> 11 | B54: 1 | D54: =D53-1 -> 29 | E54: 8 | J54: =J53-1 -> 42 | K54: 7 | M54: =M53+1 -> 74 | N54: 10 | P54: =P53+1 -> 95 | Q54: 5 | S54: =S53+1 -> 94 | T54: 6
A55: =A54-1 -> 10 | B55: 1 | D55: =D54-1 -> 28 | E55: 7 | J55: =J54-1 -> 41 | K55: 7 | M55: =M54+1 -> 75 | N55: 9 | P55: =P54+1 -> 96 | Q55: 5 | S55: =S54+1 -> 95 | T55: 6
... A65: =A64-1 -> 0 | B65: 1 | D65: =D64-1 -> 18 | E65: 5 | J65: =J64-1 -> 31 | K65: 9 | M65: =M64+1 -> 85 | N65: 9 | P65: =P64+1 -> 106 | Q65: 4 | S65: =S64+1 -> 105 | T65: 5
D66: =D65-1 -> 17 | E66: 4 | J66: =J65-1 -> 30 | K66: 9 | M66: =M65+1 -> 86 | N66: 9 | P66: =P65+1 -> 107 | Q66: 4 | S66: =S65+1 -> 106 | T66: 5
D67: =D66-1 -> 16 | E67: 4 | J67: =J66-1 -> 29 | K67: 9 | M67: =M66+1 -> 87 | N67: 9 | P67: =P66+1 -> 108 | Q67: 4 | S67: =S66+1 -> 107 | T67: 5
D68: =D67-1 -> 15 | E68: 4 | J68: =J67-1 -> 28 | K68: 10 | M68: =M67+1 -> 88 | N68: 9 | P68: =P67+1 -> 109 | Q68: 4 | S68: =S67+1 -> 108 | T68: 5
D69: =D68-1 -> 14 | E69: 3 | J69: =J68-1 -> 27 | K69: 10 | M69: =M68+1 -> 89 | N69: 8 | P69: =P68+1 -> 110 | Q69: 4 | S69: =S68+1 -> 109 | T69: 5
D70: =D69-1 -> 13 | E70: 3 | J70: =J69-1 -> 26 | K70: 10 | M70: =M69+1 -> 90 | N70: 8 | P70: =P69+1 -> 111 | Q70: 4 | S70: =S69+1 -> 110 | T70: 5
D71: =D70-1 -> 12 | E71: 2 | J71: =J70-1 -> 25 | K71: 10 | M71: =M70+1 -> 91 | N71: 8 | P71: =P70+1 -> 112 | Q71: 4 | S71: =S70+1 -> 111 | T71: 5
D72: =D71-1 -> 11 | E72: 2 | J72: =J71-1 -> 24 | K72: 11 | M72: =M71+1 -> 92 | N72: 8 | P72: =P71+1 -> 113 | Q72: 4 | S72: =S71+1 -> 112 | T72: 5
D73: =D72-1 -> 10 | E73: 2 | J73: =J72-1 -> 23 | K73: 11 | M73: =M72+1 -> 93 | N73: 8 | P73: =P72+1 -> 114 | Q73: 4 | S73: =S72+1 -> 113 | T73: 5
D74: =D73-1 -> 9 | E74: 1 | J74: =J73-1 -> 22 | K74: 11 | M74: =M73+1 -> 94 | N74: 8 | P74: =P73+1 -> 115 | Q74: 4 | S74: =S73+1 -> 114 | T74: 4
...

Sheet Beery VMI
A2: Age: | B2: =IF('Scores Summary'!C10="","",'Scores Summary'!C10) -> 41 | D2: VMI Age: | E2: =IF(B2="","",IF(B2>=95,"95-99",IF(B2>=90,"90-94",IF(B2>=85,"85-89",IF(B2>=80,"80-84",IF(B2>=75,"75-79",IF(B2>=70,"70-74",IF(B2>=65,"65-69",IF(B2>=60,"60-64",IF(B2>=55,"55-59",IF(B2>=50,"50-54",IF(B2>=40,"40-49",IF(B2>=19,"19-39",18))))))))))))) -> 40-49 | G2: VP Age: | H2: =IF(B2="","",IF(B2>69,"N/A",IF(B2>=60,"60-69",IF(B2>=50,"50-59",IF(B2>=19,"19-49",IF(B2=18,18,"")))))) -> 19-49 | J2: MC Age: | K2: =H2 -> 19-49
D3: Score: | E3: =IF('Scores Summary'!D31="","",'Scores Summary'!D31) | G3: Score: | H3: =IF('Scores Summary'!D32="","",'Scores Summary'!D32) | J3: Score: | K3: =IF('Scores Summary'!D33="","",'Scores Summary'!D33)
D4: SS: | E4: =IF(E3="","",VLOOKUP(E3,A7:N38,Q20,FALSE)) | G4: SS: | H4: =IF(H3="","",VLOOKUP(H3,A40:E71,Q44,FALSE)) | J4: SS: | K4: =IF(K3="","",VLOOKUP(K3,H40:L71,Q44,FALSE))
D5: A-E: | E5: =IF(E3="","",VLOOKUP(E3,A7:O38,15,FALSE)) | G5: A-E: | H5: =IF(H3="","",VLOOKUP(H3,A40:F71,6,FALSE)) | J5: A-E: | K5: =IF(K3="","",VLOOKUP(K3,H40:M71,6,FALSE))
A7: VMI Score | B7: 18 | C7: 19-39 | D7: 40-49 | E7: 50-54 | F7: 55-59 | G7: 60-64 | H7: 65-69 | I7: 70-74 | J7: 75-79 | K7: 80-84 | L7: 85-89 | M7: 90-94 | N7: 95-99 | O7: A-E | P7: 18 | Q7: 2
A8: 30 | B8: 106 | C8: 107 | D8: 113 | E8: 116 | F8: 119 | G8: 120 | H8: 121 | I8: 124 | J8: 126 | K8: 129 | L8: 132 | M8: 135 | N8: 138 | O8: >18.5 | P8: 19-39 | Q8: 3
A9: 29 | B9: 101 | C9: 103 | D9: 108 | E9: 110 | F9: 113 | G9: 115 | H9: 117 | I9: 119 | J9: 121 | K9: 124 | L9: 127 | M9: 130 | N9: 134 | O9: 18:5 | P9: 40-49 | Q9: 4
A10: 28 | B10: 98 | C10: 98 | D10: 103 | E10: 105 | F10: 108 | G10: 111 | H10: 113 | I10: 114 | J10: 116 | K10: 119 | L10: 122 | M10: 125 | N10: 128 | O10: 16:0 | P10: 50-54 | Q10: 5
A11: 27 | B11: 94 | C11: 92 | D11: 97 | E11: 100 | F11: 104 | G11: 106 | H11: 108 | I11: 109 | J11: 111 | K11: 114 | L11: 116 | M11: 119 | N11: 121 | O11: 13:5 | P11: 55-59 | Q11: 6
A12: 26 | B12: 90 | C12: 87 | D12: 92 | E12: 95 | F12: 99 | G12: 101 | H12: 104 | I12: 105 | J12: 106 | K12: 108 | L12: 111 | M12: 114 | N12: 117 | O12: 12:3 | P12: 60-64 | Q12: 7
A13: 25 | B13: 86 | C13: 83 | D13: 87 | E13: 90 | F13: 94 | G13: 96 | H13: 98 | I13: 99 | J13: 100 | K13: 101 | L13: 105 | M13: 109 | N13: 113 | O13: 11:1 | P13: 65-69 | Q13: 8
A14: 24 | B14: 82 | C14: 77 | D14: 84 | E14: 85 | F14: 89 | G14: 91 | H14: 94 | I14: 95 | J14: 96 | K14: 99 | L14: 101 | M14: 105 | N14: 108 | O14: 10:3 | P14: 70-74 | Q14: 9
A15: 23 | B15: 78 | C15: 72 | D15: 77 | E15: 80 | F15: 84 | G15: 86 | H15: 88 | I15: 89 | J15: 91 | K15: 94 | L15: 96 | M15: 99 | N15: 103 | O15: 9:7 | P15: 75-79 | Q15: 10
A16: 22 | B16: 74 | C16: 66 | D16: 72 | E16: 75 | F16: 79 | G16: 82 | H16: 84 | I16: 85 | J16: 86 | K16: 89 | L16: 91 | M16: 94 | N16: 98 | O16: 8:7 | P16: 80-84 | Q16: 11
A17: 21 | B17: 71 | C17: 57 | D17: 65 | E17: 69 | F17: 74 | G17: 77 | H17: 79 | I17: 80 | J17: 81 | K17: 84 | L17: 86 | M17: 89 | N17: 93 | O17: 8:1 | P17: 85-89 | Q17: 12
A18: 20 | B18: 64 | C18: 50 | D18: 58 | E18: 63 | F18: 69 | G18: 72 | H18: 74 | I18: 75 | J18: 76 | K18: 79 | L18: 81 | M18: 84 | N18: 88 | O18: 7:6 | P18: 90-94 | Q18: 13
A19: 19 | B19: 58 | C19: 45 | D19: 50 | E19: 55 | F19: 61 | G19: 64 | H19: 67 | I19: 69 | J19: 71 | K19: 74 | L19: 76 | M19: 79 | N19: 83 | O19: 7:1 | P19: 95-99 | Q19: 14
A20: 18 | B20: 54 | C20: <45 | D20: 45 | E20: 49 | F20: 51 | G20: 56 | H20: 61 | I20: 64 | J20: 66 | K20: 69 | L20: 71 | M20: 74 | N20: 78 | O20: 6:7 | P20: =E2 -> 40-49 | Q20: =VLOOKUP(P20,P7:Q19,2,FALSE) -> 4
A21: 17 | B21: 46 | C21: <45 | D21: <45 | E21: 45 | F21: 45 | G21: 49 | H21: 53 | I21: 54 | J21: 58 | K21: 61 | L21: 64 | M21: 69 | N21: 74 | O21: 6:3
A22: 16 | B22: 45 | C22: <45 | D22: <45 | E22: <45 | F22: <45 | G22: 45 | H22: 45 | I22: 45 | J22: 50 | K22: 53 | L22: 56 | M22: 61 | N22: 67 | O22: 5:11
A23: 15 | B23: <45 | C23: <45 | D23: <45 | E23: <45 | F23: <45 | G23: <45 | H23: <45 | I23: <45 | J23: 45 | K23: 45 | L23: 48 | M23: 53 | N23: 59 | O23: 5:6
A24: 14 | B24: <45 | C24: <45 | D24: <45 | E24: <45 | F24: <45 | G24: <45 | H24: <45 | I24: <45 | J24: <45 | K24: <45 | L24: 45 | M24: 45 | N24: 51 | O24: 5:2
A25: 13 | B25: <45 | C25: <45 | D25: <45 | E25: <45 | F25: <45 | G25: <45 | H25: <45 | I25: <45 | J25: <45 | K25: <45 | L25: <45 | M25: <45 | N25: 45 | O25: 4:10
A26: 12 | B26: <45 | C26: <45 | D26: <45 | E26: <45 | F26: <45 | G26: <45 | H26: <45 | I26: <45 | J26: <45 | K26: <45 | L26: <45 | M26: <45 | N26: <45 | O26: 4:6
A27: 11 | B27: <45 | C27: <45 | D27: <45 | E27: <45 | F27: <45 | G27: <45 | H27: <45 | I27: <45 | J27: <45 | K27: <45 | L27: <45 | M27: <45 | N27: <45 | O27: 4:3
A28: 10 | B28: <45 | C28: <45 | D28: <45 | E28: <45 | F28: <45 | G28: <45 | H28: <45 | I28: <45 | J28: <45 | K28: <45 | L28: <45 | M28: <45 | N28: <45 | O28: 4:0
A29: 9 | B29: <45 | C29: <45 | D29: <45 | E29: <45 | F29: <45 | G29: <45 | H29: <45 | I29: <45 | J29: <45 | K29: <45 | L29: <45 | M29: <45 | N29: <45 | O29: 3:8
A30: 8 | B30: <45 | C30: <45 | D30: <45 | E30: <45 | F30: <45 | G30: <45 | H30: <45 | I30: <45 | J30: <45 | K30: <45 | L30: <45 | M30: <45 | N30: <45 | O30: 3:5
A31: 7 | B31: <45 | C31: <45 | D31: <45 | E31: <45 | F31: <45 | G31: <45 | H31: <45 | I31: <45 | J31: <45 | K31: <45 | L31: <45 | M31: <45 | N31: <45 | O31: 3:1
A32: 6 | B32: <45 | C32: <45 | D32: <45 | E32: <45 | F32: <45 | G32: <45 | H32: <45 | I32: <45 | J32: <45 | K32: <45 | L32: <45 | M32: <45 | N32: <45 | O32: 2:10
A33: 5 | B33: <45 | C33: <45 | D33: <45 | E33: <45 | F33: <45 | G33: <45 | H33: <45 | I33: <45 | J33: <45 | K33: <45 | L33: <45 | M33: <45 | N33: <45 | O33: 2:5
A34: 4 | B34: <45 | C34: <45 | D34: <45 | E34: <45 | F34: <45 | G34: <45 | H34: <45 | I34: <45 | J34: <45 | K34: <45 | L34: <45 | M34: <45 | N34: <45 | O34: <2:4
A35: 3 | B35: <45 | C35: <45 | D35: <45 | E35: <45 | F35: <45 | G35: <45 | H35: <45 | I35: <45 | J35: <45 | K35: <45 | L35: <45 | M35: <45 | N35: <45 | O35: <2:4
A36: 2 | B36: <45 | C36: <45 | D36: <45 | E36: <45 | F36: <45 | G36: <45 | H36: <45 | I36: <45 | J36: <45 | K36: <45 | L36: <45 | M36: <45 | N36: <45 | O36: <2:4
A37: 1 | B37: <45 | C37: <45 | D37: <45 | E37: <45 | F37: <45 | G37: <45 | H37: <45 | I37: <45 | J37: <45 | K37: <45 | L37: <45 | M37: <45 | N37: <45 | O37: <2:4
A38: 0 | B38: <45 | C38: <45 | D38: <45 | E38: <45 | F38: <45 | G38: <45 | H38: <45 | I38: <45 | J38: <45 | K38: <45 | L38: <45 | M38: <45 | N38: <45 | O38: <2:4
A40: VP Score | B40: 18 | C40: 19-49 | D40: 50-59 | E40: 60-69 | F40: A-E | H40: MC Score | I40: 18 | J40: 19-49 | K40: 50-59 | L40: 60-69 | M40: A-E | P40: 18 | Q40: 2
