Workbook

Sheet Score Summary
A1: ABAS-3, Adult Form (Ages 16-89)
C5: Age Range: | D5: 16-21 | F5: Include Work? | G5: No | I5: =IF(AND(D5="75-89",G5="Yes"),"N/A for this age range!","")
C6: Rater: | D6: Self | F6: Prefered C.I.: | G6: 0.95
B8: Adaptive Skill Area | D8: Raw | E8: Scaled Scores
B9: Communication | E9: =IF(D9="","",Calculation!D10) | F9: =E9
B10: Community Use | E10: =IF(D10="","",Calculation!D11) | H10: =E10
B11: Func. Academics | E11: =IF(D11="","",Calculation!D12) | F11: =E11
B12: Home Living | E12: =IF(D12="","",Calculation!D13) | H12: =E12
B13: Health & Safety | E13: =IF(D13="","",Calculation!D14) | H13: =E13
B14: Leisure | E14: =IF(D14="","",Calculation!D15) | G14: =E14
B15: Self-Care | E15: =IF(D15="","",Calculation!D16) | H15: =E15
B16: Self-Direction | E16: =IF(D16="","",Calculation!D17) | F16: =E16
B17: Social | E17: =IF(D17="","",Calculation!D18) | G17: =E17
B18: (Work) | E18: =IF(D18="","",Calculation!D19) | H18: =E18
B19: Sum of ss: | E19: =IF(G5="Yes",(IF(COUNTIF(E9:E18,"")>0,"",SUM(E9:E18))),(IF(COUNTIF(E9:E17,"")>0,"",SUM(E9:E17)))) | F19: =IF(SUMPRODUCT((F9="")+(F11="")+(F16=""))>0,"",SUM(F9,F11,F16)) | G19: =IF(SUMPRODUCT((G14="")+(G17=""))>0,"",SUM(G14,G17)) | H19: =IF(G5="yes",(IF(SUMPRODUCT((H10="")+(H12="")+(H13="")+(H15="")+(H18=""))>0,"",SUM(H10,H12,H13,H15,H18))),(IF(SUMPRODUCT((H10="")+(H12="")+(H13="")+(H15=""))>0,"",SUM(H10,H12,H13,H15))))
E20: GAC | F20: Conceptual | G20: Social | H20: Practical
B22: Composite | D22: Sum of Scaled | E22: Standard Score | F22: Percentile | G22: =IF(G6="","",G6) -> 0.95 | H22: Conf. Int.
A23: General Adaptive Composite | D23: =IF(E19="","",E19) | E23: =IF(D23="","",IF(G5="Yes",Calc2!D11,Calc2!D10)) | F23: =IFERROR(VLOOKUP(E23,Calc2!G44:CN124,86,FALSE),"") | G23: =IFERROR(IF(E23<40,"",IF(G5="Yes",E23-Calc2!F11,IF(G5="No",E23-Calc2!F10,""))),"") | H23: - | I23: =IFERROR(IF(E23<40,"",IF(G5="Yes",E23+Calc2!F11,IF(G5="No",E23+Calc2!F10,""))),"")
B24: Conceptual | D24: =IF(F19="","",F19) | E24: =IF(D24="","",Calc2!D12) | F24: =IFERROR(VLOOKUP(E24,Calc2!G44:CN124,86,FALSE),"") | G24: =IFERROR(IF(E24<40,"",E24-Calc2!F12),"") | H24: - | I24: =IFERROR(IF(E24<40,"",E24+Calc2!F12),"")
B25: Social | D25: =IF(G19="","",G19) | E25: =IF(D25="","",Calc2!D13) | F25: =IFERROR(VLOOKUP(E25,Calc2!G44:CN124,86,FALSE),"") | G25: =IFERROR(IF(E25<40,"",E25-Calc2!F13),"") | H25: - | I25: =IFERROR(IF(E25<40,"",E25+Calc2!F13),"")
B26: Practical | D26: =IF(H19="","",H19) | E26: =IF(D26="","",IF(G5="Yes",Calc2!D15,Calc2!D14)) | F26: =IFERROR(VLOOKUP(E26,Calc2!G44:CN124,86,FALSE),"") | G26: =IFERROR(IF(E26<40,"",IF(G5="Yes",E26-Calc2!F15,IF(G5="No",E26-Calc2!F14,""))),"") | H26: - | I26: =IFERROR(IF(E26<40,"",IF(G5="Yes",E26+Calc2!F15,IF(G5="No",E26+Calc2!F14,""))),"")

Sheet Optional
A1: Optional Analyses
A3: Adaptive Domain Comparisons
A4: Domain comparison | B4: SS 1 | C4: SS 2 | D4: Difference | E4: Crit Value. | G4: .05 level? | H4: Base rate
A5: Conceptual-Social | B5: ='Score Summary'!E24 | C5: ='Score Summary'!E25 | D5: =IFERROR(ABS(B5-C5),"") | E5: =IF('Score Summary'!$D$6="Self",Calc3!AL39,Calc3!AL45) -> 8.32 | G5: =IF(D5="","",IF(D5>=E5,"Yes","No")) | H5: =IF(D5="","",IF('Score Summary'!$D$6="Self",Calc3!AM39,Calc3!AM45))
A6: Conceptual-Practical* | B6: ='Score Summary'!E24 | C6: =Calc2!D14 -> 44 | D6: =IFERROR(ABS(B6-C6),"") | E6: =IF('Score Summary'!$D$6="Self",Calc3!AL40,Calc3!AL46) -> 7.78 | G6: =IF(D6="","",IF(D6>=E6,"Yes","No")) | H6: =IF(D5="","",IF('Score Summary'!$D$6="Self",Calc3!AM40,Calc3!AM46))
A7: Social-Practical* | B7: ='Score Summary'!E25 | C7: =Calc2!D14 -> 44 | D7: =IFERROR(ABS(B7-C7),"") | E7: =IF('Score Summary'!$D$6="Self",Calc3!AL41,Calc3!AL47) -> 7.78 | G7: =IF(D7="","",IF(D7>=E7,"Yes","No")) | H7: =IF(D5="","",IF('Score Summary'!$D$6="Self",Calc3!AM41,Calc3!AM47))
A8: *Only w/o Work available for this analysis; Practical calculated w/o Work
A9: Scatter in Adaptive Skill Area Scaled Scores
A10: Comparison Used: | B10: General Adaptive Composite (GAC) (all skill areas)
A11: GAC/Domain | B11: Highest Skill Area | D11: Lowest Skill Area | F11: Difference | G11: Crit Value. | H11: .05 level? | I11: Base Rate
B12: Name | C12: ss | D12: Name | E12: ss
A13: GAC: All skill areas | B13: =IFERROR(IF('Score Summary'!D6="Self",IF(I19="No",Calc3!G108,Calc3!G64),IF(I19="No",Calc3!P108,Calc3!P64)),"") | C13: =IF(B13="","",IF('Score Summary'!G5="No",MAX('Score Summary'!E9:E17),MAX('Score Summary'!E9:E18))) | D13: =IFERROR(IF('Score Summary'!D6="Self",IF(I19="No",Calc3!I108,Calc3!I64),IF(I19="No",Calc3!R108,Calc3!R64)),"") | E13: =IF(D13="","",IF('Score Summary'!G5="No",MIN('Score Summary'!E9:E17),MIN('Score Summary'!E9:E18))) | F13: =IFERROR(ABS(C13-E13),"") | G13: =IFERROR(IF('Score Summary'!D6="Self",IF(I19="No",Calc3!K108,Calc3!K64),IF(I19="No",Calc3!T108,Calc3!T64)),"") | H13: =IF(F13="","",IF(F13>=G13,"Yes","No")) | I13: =IF(F13="","",Calc3!M7)
A14: Conceptual skills | B14: =IFERROR(IF('Score Summary'!D6="Self",Calc3!G120,Calc3!P120),"") | C14: =IF(B14="","",MAX('Score Summary'!E9,'Score Summary'!E11,'Score Summary'!E16)) | D14: =IFERROR(IF('Score Summary'!D6="Self",Calc3!I120,Calc3!R120),"") | E14: =IF(D14="","",MIN('Score Summary'!E9,'Score Summary'!E11,'Score Summary'!E16)) | F14: =IFERROR(ABS(C14-E14),"") | G14: =IFERROR(IF('Score Summary'!D6="Self",Calc3!K120,Calc3!T120),"") | H14: =IF(F14="","",IF(F14>=G14,"Yes","No")) | I14: =IF(F14="","",Calc3!M8)
A15: Social skill areas | B15: =IFERROR(IF('Score Summary'!D6="Self",Calc3!G125,Calc3!P125),"") | C15: =IF(B15="","",MAX('Score Summary'!E14,'Score Summary'!E17)) | D15: =IFERROR(IF('Score Summary'!D6="Self",Calc3!I125,Calc3!R125),"") | E15: =IF(D15="","",MIN('Score Summary'!E14,'Score Summary'!E17)) | F15: =IFERROR(ABS(C15-E15),"") | G15: =IFERROR(IF('Score Summary'!D6="Self",Calc3!J124,Calc3!S124),"") -> 2.04 | H15: =IF(F15="","",IF(F15>=G15,"Yes","No")) | I15: =IF(F15="","",Calc3!M9)
A16: Practical skill areas | B16: =IFERROR(IF('Score Summary'!D6="Self",IF(I19="No",Calc3!G158,Calc3!G144),IF(I19="No",Calc3!P158,Calc3!P144)),"") | C16: =IF(B16="","",IF('Score Summary'!G5="No",MAX('Score Summary'!E10,'Score Summary'!E12,'Score Summary'!E13,'Score Summary'!E15),MAX('Score Summary'!E10,'Score Summary'!E12,'Score Summary'!E13,'Score Summary'!E15,'Score Summary'!E18))) | D16: =IFERROR(IF('Score Summary'!D6="Self",IF(I19="No",Calc3!I158,Calc3!I144),IF(I19="No",Calc3!R158,Calc3!R144)),"") | E16: =IF(D16="","",IF('Score Summary'!G5="No",MIN('Score Summary'!E10,'Score Summary'!E12,'Score Summary'!E13,'Score Summary'!E15),MIN('Score Summary'!E10,'Score Summary'!E12,'Score Summary'!E13,'Score Summary'!E15,'Score Summary'!E18))) | F16: =IFERROR(ABS(C16-E16),"") | G16: =IFERROR(IF('Score Summary'!D6="Self",IF(I19="No",Calc3!K158,Calc3!K144),IF(I19="No",Calc3!T158,Calc3!T144)),"") | H16: =IF(F16="","",IF(F16>=G16,"Yes","No")) | I16: =IF(F16="","",Calc3!M10)
A18: Strengths and Weaknesses in Adaptive Skill Areas
A19: Comparison Used?: | B19: General Adaptive Composite (GAC) (all skill areas) | H19: Include Work? | I19: ='Score Summary'!G5 -> No
B20: GAC | D20: Conceptual | F20: Social | H20: Practical
A21: Sum of scaled scores | B21: ='Score Summary'!D23 | D21: ='Score Summary'!D24 | F21: ='Score Summary'!D25 | H21: ='Score Summary'!D26
A22: Mean scaled score | B22: =IFERROR(IF(I19="No",B21/9,B21/10),"") | D22: =IFERROR(D21/3,"") | F22: =IFERROR(F21/2,"") | H22: =IFERROR(IF(I19="No",H21/4,H21/5),"")
A24: Determine Strengths and Weaknesses in Adaptive Skill Areas
A25: Skill area | B25: Scaled Score | D25: Mean | E25: Difference | G25: Crit Value. | H25: .05 level? | I25: Base Rate
A26: Communication | B26: ='Score Summary'!E9 | D26: =IF(B19="Adaptive domains",D22,B22) | E26: =IFERROR(ABS(B26-D26),"") | G26: =IF(E26="","",IF('Score Summary'!$D$6="Self",Calc3!AL13,Calc3!AL26)) | H26: =IF(E26="","",IF(E26>=G26,"Yes","No")) | I26: =IFERROR(IF('Score Summary'!$D$6="Self",Calc3!AM13,Calc3!AM26),"")
A27: Func. Academics | B27: ='Score Summary'!E11 | D27: =IF(B19="Adaptive domains",D22,B22) | E27: =IFERROR(ABS(B27-D27),"") | G27: =IF(E27="","",IF('Score Summary'!$D$6="Self",Calc3!AL14,Calc3!AL27)) | H27: =IF(E27="","",IF(E27>=G27,"Yes","No")) | I27: =IFERROR(IF('Score Summary'!$D$6="Self",Calc3!AM14,Calc3!AM27),"")
A28: Self-Direction | B28: ='Score Summary'!E16 | D28: =IF(B19="Adaptive domains",D22,B22) | E28: =IFERROR(ABS(B28-D28),"") | G28: =IF(E28="","",IF('Score Summary'!$D$6="Self",Calc3!AL15,Calc3!AL28)) | H28: =IF(E28="","",IF(E28>=G28,"Yes","No")) | I28: =IFERROR(IF('Score Summary'!$D$6="Self",Calc3!AM15,Calc3!AM28),"")
A29: Leisure | B29: ='Score Summary'!E14 | D29: =IF(B19="Adaptive domains",F22,B22) | E29: =IFERROR(ABS(B29-D29),"") | G29: =IF(E29="","",IF('Score Summary'!$D$6="Self",Calc3!AL16,Calc3!AL29)) | H29: =IF(E29="","",IF(E29>=G29,"Yes","No")) | I29: =IFERROR(IF('Score Summary'!$D$6="Self",Calc3!AM16,Calc3!AM29),"")
A30: Social | B30: ='Score Summary'!E17 | D30: =IF(B19="Adaptive domains",F22,B22) | E30: =IFERROR(ABS(B30-D30),"") | G30: =IF(E30="","",IF('Score Summary'!$D$6="Self",Calc3!AL17,Calc3!AL30)) | H30: =IF(E30="","",IF(E30>=G30,"Yes","No")) | I30: =IFERROR(IF('Score Summary'!$D$6="Self",Calc3!AM17,Calc3!AM30),"")
A31: Community Use | B31: ='Score Summary'!E10 | D31: =IF(B19="Adaptive domains",H22,B22) | E31: =IFERROR(ABS(B31-D31),"") | G31: =IF(E31="","",IF('Score Summary'!$D$6="Self",Calc3!AL18,Calc3!AL31)) | H31: =IF(E31="","",IF(E31>=G31,"Yes","No")) | I31: =IFERROR(IF('Score Summary'!$D$6="Self",Calc3!AM18,Calc3!AM31),"")
A32: Home Living | B32: ='Score Summary'!E12 | D32: =IF(B19="Adaptive domains",H22,B22) | E32: =IFERROR(ABS(B32-D32),"") | G32: =IF(E32="","",IF('Score Summary'!$D$6="Self",Calc3!AL19,Calc3!AL32)) | H32: =IF(E32="","",IF(E32>=G32,"Yes","No")) | I32: =IFERROR(IF('Score Summary'!$D$6="Self",Calc3!AM19,Calc3!AM32),"")
A33: Health & Safety | B33: ='Score Summary'!E13 | D33: =IF(B19="Adaptive domains",H22,B22) | E33: =IFERROR(ABS(B33-D33),"") | G33: =IF(E33="","",IF('Score Summary'!$D$6="Self",Calc3!AL20,Calc3!AL33)) | H33: =IF(E33="","",IF(E33>=G33,"Yes","No")) | I33: =IFERROR(IF('Score Summary'!$D$6="Self",Calc3!AM20,Calc3!AM33),"")
A34: Self-Care | B34: ='Score Summary'!E15 | D34: =IF(B19="Adaptive domains",H22,B22) | E34: =IFERROR(ABS(B34-D34),"") | G34: =IF(E34="","",IF('Score Summary'!$D$6="Self",Calc3!AL21,Calc3!AL34)) | H34: =IF(E34="","",IF(E34>=G34,"Yes","No")) | I34: =IFERROR(IF('Score Summary'!$D$6="Self",Calc3!AM21,Calc3!AM34),"")
A35: =IF(I19="No","","Work") | B35: =IF(I19="No","",'Score Summary'!E18) | D35: =IF(I19="No","",IF(B19="Adaptive domains",H22,B22)) | E35: =IFERROR(ABS(B35-D35),"") | G35: =IF(E35="","",IF(I19="No","",IF('Score Summary'!$D$6="Self",Calc3!AL22,Calc3!AL35))) | H35: =IF(E35="","",IF(I19="No","",IF(E35>=G35,"Yes","No"))) | I35: =IFERROR(IF(I19="No","",IF('Score Summary'!$D$6="Self",Calc3!AM22,Calc3!AM35)),"")

Sheet Calculation
H1: COMMUNICATION | V1: SELF-CARE | AJ1: SELF-DIRECTION | AX1: SOCIAL
H2: Rater: Self | O2: Rater: Other | V2: Rater: Self | AC2: Rater: Other | AJ2: Rater: Self | AQ2: Rater: Other | AX2: Rater: Self | BE2: Rater: Other
A3: Selections | C3: Col. Add | G3: Raw | H3: 16-21 | I3: 22-29 | J3: 30-39 | K3: 40-49 | L3: 50-64 | M3: 65-74 | N3: 75-89 | O3: 16-21 | P3: 22-29 | Q3: 30-39 | R3: 40-49 | S3: 50-64 | T3: 65-74 | U3: 75-89 | V3: 16-21 | W3: 22-29 | X3: 30-39 | Y3: 40-49 | Z3: 50-64 | AA3: 65-74 | AB3: 75-89 | AC3: 16-21 | AD3: 22-29 | AE3: 30-39 | AF3: 40-49 | AG3: 50-64 | AH3: 65-74 | AI3: 75-89 | AJ3: 16-21 | AK3: 22-29 | AL3: 30-39 | AM3: 40-49 | AN3: 50-64 | AO3: 65-74 | AP3: 75-89 | AQ3: 16-21 | AR3: 22-29 | AS3: 30-39 | AT3: 40-49 | AU3: 50-64 | AV3: 65-74 | AW3: 75-89 | AX3: 16-21 | AY3: 22-29 | AZ3: 30-39 | BA3: 40-49 | BB3: 50-64 | BC3: 65-74 | BD3: 75-89 | BE3: 16-21 | BF3: 22-29 | BG3: 30-39 | BH3: 40-49 | BI3: 50-64 | BJ3: 65-74 | BK3: 75-89
A4: Age: | B4: ='Score Summary'!D5 -> 16-21 | C4: =VLOOKUP(B4,A21:B28,2,FALSE) -> 0 | G4: 0 | H4: 1 | I4: 1 | J4: 1 | K4: 1 | L4: 1 | M4: 1 | N4: 1 | O4: 1 | P4: 1 | Q4: 1 | R4: 1 | S4: 1 | T4: 1 | U4: 1 | V4: 1 | W4: 1 | X4: 1 | Y4: 1 | Z4: 1 | AA4: 1 | AB4: 1 | AC4: 1 | AD4: 1 | AE4: 1 | AF4: 1 | AG4: 1 | AH4: 1 | AI4: 1 | AJ4: 1 | AK4: 1 | AL4: 1 | AM4: 1 | AN4: 1 | AO4: 1 | AP4: 1 | AQ4: 1 | AR4: 1 | AS4: 1 | AT4: 1 | AU4: 1 | AV4: 1 | AW4: 1 | AX4: 1 | AY4: 1 | AZ4: 1 | BA4: 1 | BB4: 1 | BC4: 1 | BD4: 1 | BE4: 1 | BF4: 1 | BG4: 1 | BH4: 1 | BI4: 1 | BJ4: 1 | BK4: 1
A5: Rater: | B5: ='Score Summary'!D6 -> Self | C5: =IF(B5="Self",0,IF(B5="Other",7,"")) -> 0 | G5: 1 | H5: 1 | I5: 1 | J5: 1 | K5: 1 | L5: 1 | M5: 1 | N5: 1 | O5: 1 | P5: 1 | Q5: 1 | R5: 1 | S5: 1 | T5: 1 | U5: 1 | V5: 1 | W5: 1 | X5: 1 | Y5: 1 | Z5: 1 | AA5: 1 | AB5: 1 | AC5: 1 | AD5: 1 | AE5: 1 | AF5: 1 | AG5: 1 | AH5: 1 | AI5: 1 | AJ5: 1 | AK5: 1 | AL5: 1 | AM5: 1 | AN5: 1 | AO5: 1 | AP5: 1 | AQ5: 1 | AR5: 1 | AS5: 1 | AT5: 1 | AU5: 1 | AV5: 1 | AW5: 1 | AX5: 1 | AY5: 1 | AZ5: 1 | BA5: 1 | BB5: 1 | BC5: 1 | BD5: 1 | BE5: 1 | BF5: 1 | BG5: 1 | BH5: 1 | BI5: 1 | BJ5: 1 | BK5: 1
A6: CI: | B6: ='Score Summary'!G6 -> 0.95 | G6: 2 | H6: 1 | I6: 1 | J6: 1 | K6: 1 | L6: 1 | M6: 1 | N6: 1 | O6: 1 | P6: 1 | Q6: 1 | R6: 1 | S6: 1 | T6: 1 | U6: 1 | V6: 1 | W6: 1 | X6: 1 | Y6: 1 | Z6: 1 | AA6: 1 | AB6: 1 | AC6: 1 | AD6: 1 | AE6: 1 | AF6: 1 | AG6: 1 | AH6: 1 | AI6: 1 | AJ6: 1 | AK6: 1 | AL6: 1 | AM6: 1 | AN6: 1 | AO6: 1 | AP6: 1 | AQ6: 1 | AR6: 1 | AS6: 1 | AT6: 1 | AU6: 1 | AV6: 1 | AW6: 1 | AX6: 1 | AY6: 1 | AZ6: 1 | BA6: 1 | BB6: 1 | BC6: 1 | BD6: 1 | BE6: 1 | BF6: 1 | BG6: 1 | BH6: 1 | BI6: 1 | BJ6: 1 | BK6: 1
A7: Work?: | B7: ='Score Summary'!G5 -> No | G7: 3 | H7: 1 | I7: 1 | J7: 1 | K7: 1 | L7: 1 | M7: 1 | N7: 1 | O7: 1 | P7: 1 | Q7: 1 | R7: 1 | S7: 1 | T7: 1 | U7: 1 | V7: 1 | W7: 1 | X7: 1 | Y7: 1 | Z7: 1 | AA7: 1 | AB7: 1 | AC7: 1 | AD7: 1 | AE7: 1 | AF7: 1 | AG7: 1 | AH7: 1 | AI7: 1 | AJ7: 1 | AK7: 1 | AL7: 1 | AM7: 1 | AN7: 1 | AO7: 1 | AP7: 1 | AQ7: 1 | AR7: 1 | AS7: 1 | AT7: 1 | AU7: 1 | AV7: 1 | AW7: 1 | AX7: 1 | AY7: 1 | AZ7: 1 | BA7: 1 | BB7: 1 | BC7: 1 | BD7: 1 | BE7: 1 | BF7: 1 | BG7: 1 | BH7: 1 | BI7: 1 | BJ7: 1 | BK7: 1
G8: 4 | H8: 1 | I8: 1 | J8: 1 | K8: 1 | L8: 1 | M8: 1 | N8: 1 | O8: 1 | P8: 1 | Q8: 1 | R8: 1 | S8: 1 | T8: 1 | U8: 1 | V8: 1 | W8: 1 | X8: 1 | Y8: 1 | Z8: 1 | AA8: 1 | AB8: 1 | AC8: 1 | AD8: 1 | AE8: 1 | AF8: 1 | AG8: 1 | AH8: 1 | AI8: 1 | AJ8: 1 | AK8: 1 | AL8: 1 | AM8: 1 | AN8: 1 | AO8: 1 | AP8: 1 | AQ8: 1 | AR8: 1 | AS8: 1 | AT8: 1 | AU8: 1 | AV8: 1 | AW8: 1 | AX8: 1 | AY8: 1 | AZ8: 1 | BA8: 1 | BB8: 1 | BC8: 1 | BD8: 1 | BE8: 1 | BF8: 1 | BG8: 1 | BH8: 1 | BI8: 1 | BJ8: 1 | BK8: 1
A9: Adaptive Skill Area | C9: Raw | D9: Scaled | E9: Col. | G9: 5 | H9: 1 | I9: 1 | J9: 1 | K9: 1 | L9: 1 | M9: 1 | N9: 1 | O9: 1 | P9: 1 | Q9: 1 | R9: 1 | S9: 1 | T9: 1 | U9: 1 | V9: 1 | W9: 1 | X9: 1 | Y9: 1 | Z9: 1 | AA9: 1 | AB9: 1 | AC9: 1 | AD9: 1 | AE9: 1 | AF9: 1 | AG9: 1 | AH9: 1 | AI9: 1 | AJ9: 1 | AK9: 1 | AL9: 1 | AM9: 1 | AN9: 1 | AO9: 1 | AP9: 1 | AQ9: 1 | AR9: 1 | AS9: 1 | AT9: 1 | AU9: 1 | AV9: 1 | AW9: 1 | AX9: 1 | AY9: 1 | AZ9: 1 | BA9: 1 | BB9: 1 | BC9: 1 | BD9: 1 | BE9: 1 | BF9: 1 | BG9: 1 | BH9: 1 | BI9: 1 | BJ9: 1 | BK9: 1
A10: Communication | C10: =IF('Score Summary'!D9="","",'Score Summary'!D9) | D10: =VLOOKUP(C10,G3:U79,SUM(C4,C5,E10),FALSE) -> #N/A | E10: 2 | G10: 6 | H10: 1 | I10: 1 | J10: 1 | K10: 1 | L10: 1 | M10: 1 | N10: 1 | O10: 1 | P10: 1 | Q10: 1 | R10: 1 | S10: 1 | T10: 1 | U10: 1 | V10: 1 | W10: 1 | X10: 1 | Y10: 1 | Z10: 1 | AA10: 1 | AB10: 1 | AC10: 1 | AD10: 1 | AE10: 1 | AF10: 1 | AG10: 1 | AH10: 1 | AI10: 1 | AJ10: 1 | AK10: 1 | AL10: 1 | AM10: 1 | AN10: 1 | AO10: 1 | AP10: 1 | AQ10: 1 | AR10: 1 | AS10: 1 | AT10: 1 | AU10: 1 | AV10: 1 | AW10: 1 | AX10: 1 | AY10: 1 | AZ10: 1 | BA10: 1 | BB10: 1 | BC10: 1 | BD10: 1 | BE10: 1 | BF10: 1 | BG10: 1 | BH10: 1 | BI10: 1 | BJ10: 1 | BK10: 1
A11: Community Use | C11: =IF('Score Summary'!D10="","",'Score Summary'!D10) | D11: =VLOOKUP(C11,G86:U159,SUM(E11,C4,C5),FALSE) -> #N/A | E11: 2 | G11: 7 | H11: 1 | I11: 1 | J11: 1 | K11: 1 | L11: 1 | M11: 1 | N11: 1 | O11: 1 | P11: 1 | Q11: 1 | R11: 1 | S11: 1 | T11: 1 | U11: 1 | V11: 1 | W11: 1 | X11: 1 | Y11: 1 | Z11: 1 | AA11: 1 | AB11: 1 | AC11: 1 | AD11: 1 | AE11: 1 | AF11: 1 | AG11: 1 | AH11: 1 | AI11: 1 | AJ11: 1 | AK11: 1 | AL11: 1 | AM11: 1 | AN11: 1 | AO11: 1 | AP11: 1 | AQ11: 1 | AR11: 1 | AS11: 1 | AT11: 1 | AU11: 1 | AV11: 1 | AW11: 1 | AX11: 1 | AY11: 1 | AZ11: 1 | BA11: 1 | BB11: 1 | BC11: 1 | BD11: 1 | BE11: 1 | BF11: 1 | BG11: 1 | BH11: 1 | BI11: 1 | BJ11: 1 | BK11: 1
A12: Func. Academics | C12: =IF('Score Summary'!D11="","",'Score Summary'!D11) | D12: =VLOOKUP(C12,G86:AI159,SUM(E12,C4,C5),FALSE) -> #N/A | E12: 16 | G12: 8 | H12: 1 | I12: 1 | J12: 1 | K12: 1 | L12: 1 | M12: 1 | N12: 1 | O12: 1 | P12: 1 | Q12: 1 | R12: 1 | S12: 1 | T12: 1 | U12: 1 | V12: 1 | W12: 1 | X12: 1 | Y12: 1 | Z12: 1 | AA12: 1 | AB12: 1 | AC12: 1 | AD12: 1 | AE12: 1 | AF12: 1 | AG12: 1 | AH12: 1 | AI12: 1 | AJ12: 1 | AK12: 1 | AL12: 1 | AM12: 1 | AN12: 1 | AO12: 1 | AP12: 1 | AQ12: 1 | AR12: 1 | AS12: 1 | AT12: 1 | AU12: 1 | AV12: 1 | AW12: 1 | AX12: 1 | AY12: 1 | AZ12: 1 | BA12: 1 | BB12: 1 | BC12: 1 | BD12: 1 | BE12: 1 | BF12: 1 | BG12: 1 | BH12: 1 | BI12: 1 | BJ12: 1 | BK12: 1
A13: Home Living | C13: =IF('Score Summary'!D12="","",'Score Summary'!D12) | D13: =VLOOKUP(C13,G86:AW159,SUM(E13,C4,C5),FALSE) -> #N/A | E13: 30 | G13: 9 | H13: 1 | I13: 1 | J13: 1 | K13: 1 | L13: 1 | M13: 1 | N13: 1 | O13: 1 | P13: 1 | Q13: 1 | R13: 1 | S13: 1 | T13: 1 | U13: 1 | V13: 1 | W13: 1 | X13: 1 | Y13: 1 | Z13: 1 | AA13: 1 | AB13: 1 | AC13: 1 | AD13: 1 | AE13: 1 | AF13: 1 | AG13: 1 | AH13: 1 | AI13: 1 | AJ13: 1 | AK13: 1 | AL13: 1 | AM13: 1 | AN13: 1 | AO13: 1 | AP13: 1 | AQ13: 1 | AR13: 1 | AS13: 1 | AT13: 1 | AU13: 1 | AV13: 1 | AW13: 1 | AX13: 1 | AY13: 1 | AZ13: 1 | BA13: 1 | BB13: 1 | BC13: 1 | BD13: 1 | BE13: 1 | BF13: 1 | BG13: 1 | BH13: 1 | BI13: 1 | BJ13: 1 | BK13: 1
A14: Health & Safety | C14: =IF('Score Summary'!D13="","",'Score Summary'!D13) | D14: =VLOOKUP(C14,G163:U224,SUM(E14,C4,C5),FALSE) -> #N/A | E14: 2 | G14: 10 | H14: 1 | I14: 1 | J14: 1 | K14: 1 | L14: 1 | M14: 1 | N14: 1 | O14: 1 | P14: 1 | Q14: 1 | R14: 1 | S14: 1 | T14: 1 | U14: 1 | V14: 1 | W14: 1 | X14: 1 | Y14: 1 | Z14: 1 | AA14: 1 | AB14: 1 | AC14: 1 | AD14: 1 | AE14: 1 | AF14: 1 | AG14: 1 | AH14: 1 | AI14: 1 | AJ14: 1 | AK14: 1 | AL14: 1 | AM14: 1 | AN14: 1 | AO14: 1 | AP14: 1 | AQ14: 1 | AR14: 1 | AS14: 1 | AT14: 1 | AU14: 1 | AV14: 1 | AW14: 1 | AX14: 1 | AY14: 1 | AZ14: 1 | BA14: 1 | BB14: 1 | BC14: 1 | BD14: 1 | BE14: 1 | BF14: 1 | BG14: 1 | BH14: 1 | BI14: 1 | BJ14: 1 | BK14: 1
A15: Leisure | C15: =IF('Score Summary'!D14="","",'Score Summary'!D14) | D15: =VLOOKUP(C15,G163:AI230,SUM(E15,C4,C5),FALSE) -> #N/A | E15: 16 | G15: 11 | H15: 1 | I15: 1 | J15: 1 | K15: 1 | L15: 1 | M15: 1 | N15: 1 | O15: 1 | P15: 1 | Q15: 1 | R15: 1 | S15: 1 | T15: 1 | U15: 1 | V15: 1 | W15: 1 | X15: 1 | Y15: 1 | Z15: 1 | AA15: 1 | AB15: 1 | AC15: 1 | AD15: 1 | AE15: 1 | AF15: 1 | AG15: 1 | AH15: 1 | AI15: 1 | AJ15: 1 | AK15: 1 | AL15: 1 | AM15: 1 | AN15: 1 | AO15: 1 | AP15: 1 | AQ15: 1 | AR15: 1 | AS15: 1 | AT15: 1 | AU15: 1 | AV15: 1 | AW15: 1 | AX15: 1 | AY15: 1 | AZ15: 1 | BA15: 1 | BB15: 1 | BC15: 1 | BD15: 1 | BE15: 1 | BF15: 1 | BG15: 1 | BH15: 1 | BI15: 1 | BJ15: 1 | BK15: 1
A16: Self-Care | C16: =IF('Score Summary'!D15="","",'Score Summary'!D15) | D16: =VLOOKUP(C16,G3:AI82,SUM(E16,C4,C5),FALSE) -> #N/A | E16: 16 | G16: 12 | H16: 1 | I16: 1 | J16: 1 | K16: 1 | L16: 1 | M16: 1 | N16: 1 | O16: 1 | P16: 1 | Q16: 1 | R16: 1 | S16: 1 | T16: 1 | U16: 1 | V16: 1 | W16: 1 | X16: 1 | Y16: 1 | Z16: 1 | AA16: 1 | AB16: 1 | AC16: 1 | AD16: 1 | AE16: 1 | AF16: 1 | AG16: 1 | AH16: 1 | AI16: 1 | AJ16: 1 | AK16: 1 | AL16: 1 | AM16: 1 | AN16: 1 | AO16: 1 | AP16: 1 | AQ16: 1 | AR16: 1 | AS16: 1 | AT16: 1 | AU16: 1 | AV16: 1 | AW16: 1 | AX16: 1 | AY16: 1 | AZ16: 1 | BA16: 1 | BB16: 1 | BC16: 1 | BD16: 1 | BE16: 1 | BF16: 1 | BG16: 1 | BH16: 1 | BI16: 1 | BJ16: 1 | BK16: 1
A17: Self-Direction | C17: =IF('Score Summary'!D16="","",'Score Summary'!D16) | D17: =VLOOKUP(C17,G3:AW79,SUM(E17,C4,C5),FALSE) -> #N/A | E17: 30 | G17: 13 | H17: 1 | I17: 1 | J17: 1 | K17: 1 | L17: 1 | M17: 1 | N17: 1 | O17: 1 | P17: 1 | Q17: 1 | R17: 1 | S17: 1 | T17: 1 | U17: 1 | V17: 1 | W17: 1 | X17: 1 | Y17: 1 | Z17: 1 | AA17: 1 | AB17: 1 | AC17: 1 | AD17: 1 | AE17: 1 | AF17: 1 | AG17: 1 | AH17: 1 | AI17: 1 | AJ17: 1 | AK17: 1 | AL17: 1 | AM17: 1 | AN17: 1 | AO17: 1 | AP17: 1 | AQ17: 1 | AR17: 1 | AS17: 1 | AT17: 1 | AU17: 1 | AV17: 1 | AW17: 1 | AX17: 1 | AY17: 1 | AZ17: 1 | BA17: 1 | BB17: 1 | BC17: 1 | BD17: 1 | BE17: 1 | BF17: 1 | BG17: 1 | BH17: 1 | BI17: 1 | BJ17: 1 | BK17: 1
A18: Social | C18: =IF('Score Summary'!D17="","",'Score Summary'!D17) | D18: =VLOOKUP(C18,G3:BK79,SUM(E18,C4,C5),FALSE) -> #N/A | E18: 44 | G18: 14 | H18: 1 | I18: 1 | J18: 1 | K18: 1 | L18: 1 | M18: 1 | N18: 1 | O18: 1 | P18: 1 | Q18: 1 | R18: 1 | S18: 1 | T18: 1 | U18: 1 | V18: 1 | W18: 1 | X18: 1 | Y18: 1 | Z18: 1 | AA18: 1 | AB18: 1 | AC18: 1 | AD18: 1 | AE18: 1 | AF18: 1 | AG18: 1 | AH18: 1 | AI18: 1 | AJ18: 1 | AK18: 1 | AL18: 1 | AM18: 1 | AN18: 1 | AO18: 1 | AP18: 1 | AQ18: 1 | AR18: 1 | AS18: 1 | AT18: 1 | AU18: 1 | AV18: 1 | AW18: 1 | AX18: 1 | AY18: 1 | AZ18: 1 | BA18: 1 | BB18: 1 | BC18: 1 | BD18: 1 | BE18: 1 | BF18: 1 | BG18: 1 | BH18: 1 | BI18: 1 | BJ18: 1 | BK18: 1
A19: (Work) | C19: =IF('Score Summary'!D18="","",'Score Summary'!D18) | D19: =VLOOKUP(C19,G86:BK159,SUM(E19,C4,C5),FALSE) -> #N/A | E19: 44 | G19: 15 | H19: 1 | I19: 1 | J19: 1 | K19: 1 | L19: 1 | M19: 1 | N19: 1 | O19: 1 | P19: 1 | Q19: 1 | R19: 1 | S19: 1 | T19: 1 | U19: 1 | V19: 1 | W19: 1 | X19: 1 | Y19: 1 | Z19: 1 | AA19: 1 | AB19: 1 | AC19: 1 | AD19: 1 | AE19: 1 | AF19: 1 | AG19: 1 | AH19: 1 | AI19: 1 | AJ19: 1 | AK19: 1 | AL19: 1 | AM19: 1 | AN19: 1 | AO19: 1 | AP19: 1 | AQ19: 1 | AR19: 1 | AS19: 1 | AT19: 1 | AU19: 1 | AV19: 1 | AW19: 1 | AX19: 1 | AY19: 1 | AZ19: 1 | BA19: 1 | BB19: 1 | BC19: 1 | BD19: 1 | BE19: 1 | BF19: 1 | BG19: 1 | BH19: 1 | BI19: 1 | BJ19: 1 | BK19: 1
G20: 16 | H20: 1 | I20: 1 | J20: 1 | K20: 1 | L20: 1 | M20: 1 | N20: 1 | O20: 1 | P20: 1 | Q20: 1 | R20: 1 | S20: 1 | T20: 1 | U20: 1 | V20: 1 | W20: 1 | X20: 1 | Y20: 1 | Z20: 1 | AA20: 1 | AB20: 1 | AC20: 1 | AD20: 1 | AE20: 1 | AF20: 1 | AG20: 1 | AH20: 1 | AI20: 1 | AJ20: 1 | AK20: 1 | AL20: 1 | AM20: 1 | AN20: 1 | AO20: 1 | AP20: 1 | AQ20: 1 | AR20: 1 | AS20: 1 | AT20: 1 | AU20: 1 | AV20: 1 | AW20: 1 | AX20: 1 | AY20: 1 | AZ20: 1 | BA20: 1 | BB20: 1 | BC20: 1 | BD20: 1 | BE20: 1 | BF20: 1 | BG20: 1 | BH20: 1 | BI20: 1 | BJ20: 1 | BK20: 1
A21: Age | B21: Col | G21: 17 | H21: 1 | I21: 1 | J21: 1 | K21: 1 | L21: 1 | M21: 1 | N21: 1 | O21: 1 | P21: 1 | Q21: 1 | R21: 1 | S21: 1 | T21: 1 | U21: 1 | V21: 1 | W21: 1 | X21: 1 | Y21: 1 | Z21: 1 | AA21: 1 | AB21: 1 | AC21: 1 | AD21: 1 | AE21: 1 | AF21: 1 | AG21: 1 | AH21: 1 | AI21: 1 | AJ21: 1 | AK21: 1 | AL21: 1 | AM21: 1 | AN21: 1 | AO21: 1 | AP21: 1 | AQ21: 1 | AR21: 1 | AS21: 1 | AT21: 1 | AU21: 1 | AV21: 1 | AW21: 1 | AX21: 1 | AY21: 1 | AZ21: 1 | BA21: 1 | BB21: 1 | BC21: 1 | BD21: 1 | BE21: 1 | BF21: 1 | BG21: 1 | BH21: 1 | BI21: 1 | BJ21: 1 | BK21: 1
A22: 16-21 | B22: 0 | G22: 18 | H22: 1 | I22: 1 | J22: 1 | K22: 1 | L22: 1 | M22: 1 | N22: 1 | O22: 1 | P22: 1 | Q22: 1 | R22: 1 | S22: 1 | T22: 1 | U22: 1 | V22: 1 | W22: 1 | X22: 1 | Y22: 1 | Z22: 1 | AA22: 1 | AB22: 1 | AC22: 1 | AD22: 1 | AE22: 1 | AF22: 1 | AG22: 1 | AH22: 1 | AI22: 1 | AJ22: 1 | AK22: 1 | AL22: 1 | AM22: 1 | AN22: 1 | AO22: 1 | AP22: 1 | AQ22: 1 | AR22: 1 | AS22: 1 | AT22: 1 | AU22: 1 | AV22: 1 | AW22: 1 | AX22: 1 | AY22: 1 | AZ22: 1 | BA22: 1 | BB22: 1 | BC22: 1 | BD22: 1 | BE22: 1 | BF22: 1 | BG22: 1 | BH22: 1 | BI22: 1 | BJ22: 1 | BK22: 1
A23: 22-29 | B23: 1 | G23: 19 | H23: 1 | I23: 1 | J23: 1 | K23: 1 | L23: 1 | M23: 1 | N23: 1 | O23: 1 | P23: 1 | Q23: 1 | R23: 1 | S23: 1 | T23: 1 | U23: 1 | V23: 1 | W23: 1 | X23: 1 | Y23: 1 | Z23: 1 | AA23: 1 | AB23: 1 | AC23: 1 | AD23: 1 | AE23: 1 | AF23: 1 | AG23: 1 | AH23: 1 | AI23: 1 | AJ23: 1 | AK23: 1 | AL23: 1 | AM23: 1 | AN23: 1 | AO23: 1 | AP23: 1 | AQ23: 1 | AR23: 1 | AS23: 1 | AT23: 1 | AU23: 1 | AV23: 1 | AW23: 1 | AX23: 1 | AY23: 1 | AZ23: 1 | BA23: 1 | BB23: 1 | BC23: 1 | BD23: 1 | BE23: 1 | BF23: 1 | BG23: 1 | BH23: 1 | BI23: 1 | BJ23: 1 | BK23: 1
A24: 30-39 | B24: 2 | G24: 20 | H24: 1 | I24: 1 | J24: 1 | K24: 1 | L24: 1 | M24: 1 | N24: 1 | O24: 1 | P24: 1 | Q24: 1 | R24: 1 | S24: 1 | T24: 1 | U24: 1 | V24: 1 | W24: 1 | X24: 1 | Y24: 1 | Z24: 1 | AA24: 1 | AB24: 1 | AC24: 1 | AD24: 1 | AE24: 1 | AF24: 1 | AG24: 1 | AH24: 1 | AI24: 1 | AJ24: 1 | AK24: 1 | AL24: 1 | AM24: 1 | AN24: 1 | AO24: 1 | AP24: 1 | AQ24: 1 | AR24: 1 | AS24: 1 | AT24: 1 | AU24: 1 | AV24: 1 | AW24: 1 | AX24: 1 | AY24: 1 | AZ24: 1 | BA24: 1 | BB24: 1 | BC24: 1 | BD24: 1 | BE24: 1 | BF24: 1 | BG24: 1 | BH24: 1 | BI24: 1 | BJ24: 1 | BK24: 1
A25: 40-49 | B25: 3 | G25: 21 | H25: 1 | I25: 1 | J25: 1 | K25: 1 | L25: 1 | M25: 1 | N25: 1 | O25: 1 | P25: 1 | Q25: 1 | R25: 1 | S25: 1 | T25: 1 | U25: 1 | V25: 1 | W25: 1 | X25: 1 | Y25: 1 | Z25: 1 | AA25: 1 | AB25: 1 | AC25: 1 | AD25: 1 | AE25: 1 | AF25: 1 | AG25: 1 | AH25: 1 | AI25: 1 | AJ25: 1 | AK25: 1 | AL25: 1 | AM25: 1 | AN25: 1 | AO25: 1 | AP25: 1 | AQ25: 1 | AR25: 1 | AS25: 1 | AT25: 1 | AU25: 1 | AV25: 1 | AW25: 1 | AX25: 1 | AY25: 1 | AZ25: 1 | BA25: 1 | BB25: 1 | BC25: 1 | BD25: 1 | BE25: 1 | BF25: 1 | BG25: 1 | BH25: 1 | BI25: 1 | BJ25: 1 | BK25: 1
A26: 50-64 | B26: 4 | G26: 22 | H26: 1 | I26: 1 | J26: 1 | K26: 1 | L26: 1 | M26: 1 | N26: 1 | O26: 1 | P26: 1 | Q26: 1 | R26: 1 | S26: 1 | T26: 1 | U26: 1 | V26: 1 | W26: 1 | X26: 1 | Y26: 1 | Z26: 1 | AA26: 1 | AB26: 1 | AC26: 1 | AD26: 1 | AE26: 1 | AF26: 1 | AG26: 1 | AH26: 1 | AI26: 1 | AJ26: 1 | AK26: 1 | AL26: 1 | AM26: 1 | AN26: 1 | AO26: 1 | AP26: 1 | AQ26: 1 | AR26: 1 | AS26: 1 | AT26: 1 | AU26: 1 | AV26: 1 | AW26: 2 | AX26: 1 | AY26: 1 | AZ26: 1 | BA26: 1 | BB26: 1 | BC26: 1 | BD26: 1 | BE26: 1 | BF26: 1 | BG26: 1 | BH26: 1 | BI26: 1 | BJ26: 1 | BK26: 1
A27: 65-74 | B27: 5 | G27: 23 | H27: 1 | I27: 1 | J27: 1 | K27: 1 | L27: 1 | M27: 1 | N27: 1 | O27: 1 | P27: 1 | Q27: 1 | R27: 1 | S27: 1 | T27: 1 | U27: 1 | V27: 1 | W27: 1 | X27: 1 | Y27: 1 | Z27: 1 | AA27: 1 | AB27: 1 | AC27: 1 | AD27: 1 | AE27: 1 | AF27: 1 | AG27: 1 | AH27: 1 | AI27: 1 | AJ27: 1 | AK27: 1 | AL27: 1 | AM27: 1 | AN27: 1 | AO27: 1 | AP27: 1 | AQ27: 1 | AR27: 1 | AS27: 1 | AT27: 1 | AU27: 1 | AV27: 1 | AW27: 2 | AX27: 1 | AY27: 1 | AZ27: 1 | BA27: 1 | BB27: 1 | BC27: 1 | BD27: 1 | BE27: 1 | BF27: 1 | BG27: 1 | BH27: 1 | BI27: 1 | BJ27: 1 | BK27: 1
A28: 75-89 | B28: 6 | G28: 24 | H28: 1 | I28: 1 | J28: 1 | K28: 1 | L28: 1 | M28: 1 | N28: 1 | O28: 1 | P28: 1 | Q28: 1 | R28: 1 | S28: 1 | T28: 1 | U28: 1 | V28: 1 | W28: 1 | X28: 1 | Y28: 1 | Z28: 1 | AA28: 1 | AB28: 1 | AC28: 1 | AD28: 1 | AE28: 1 | AF28: 1 | AG28: 1 | AH28: 1 | AI28: 1 | AJ28: 1 | AK28: 1 | AL28: 1 | AM28: 1 | AN28: 1 | AO28: 1 | AP28: 1 | AQ28: 1 | AR28: 1 | AS28: 1 | AT28: 1 | AU28: 1 | AV28: 1 | AW28: 2 | AX28: 1 | AY28: 1 | AZ28: 1 | BA28: 1 | BB28: 1 | BC28: 1 | BD28: 1 | BE28: 1 | BF28: 1 | BG28: 1 | BH28: 1 | BI28: 1 | BJ28: 1 | BK28: 1
G29: 25 | H29: 1 | I29: 1 | J29: 1 | K29: 1 | L29: 1 | M29: 1 | N29: 1 | O29: 1 | P29: 1 | Q29: 1 | R29: 1 | S29: 1 | T29: 1 | U29: 1 | V29: 1 | W29: 1 | X29: 1 | Y29: 1 | Z29: 1 | AA29: 1 | AB29: 1 | AC29: 1 | AD29: 1 | AE29: 1 | AF29: 1 | AG29: 1 | AH29: 1 | AI29: 1 | AJ29: 1 | AK29: 1 | AL29: 1 | AM29: 1 | AN29: 1 | AO29: 1 | AP29: 1 | AQ29: 1 | AR29: 1 | AS29: 1 | AT29: 1 | AU29: 1 | AV29: 1 | AW29: 2 | AX29: 1 | AY29: 1 | AZ29: 1 | BA29: 1 | BB29: 1 | BC29: 1 | BD29: 1 | BE29: 1 | BF29: 1 | BG29: 1 | BH29: 1 | BI29: 1 | BJ29: 1 | BK29: 1
G30: 26 | H30: 1 | I30: 1 | J30: 1 | K30: 1 | L30: 1 | M30: 1 | N30: 1 | O30: 1 | P30: 1 | Q30: 1 | R30: 1 | S30: 1 | T30: 1 | U30: 1 | V30: 1 | W30: 1 | X30: 1 | Y30: 1 | Z30: 1 | AA30: 1 | AB30: 1 | AC30: 1 | AD30: 1 | AE30: 1 | AF30: 1 | AG30: 1 | AH30: 1 | AI30: 1 | AJ30: 1 | AK30: 1 | AL30: 1 | AM30: 1 | AN30: 1 | AO30: 1 | AP30: 1 | AQ30: 1 | AR30: 1 | AS30: 1 | AT30: 1 | AU30: 1 | AV30: 1 | AW30: 2 | AX30: 1 | AY30: 1 | AZ30: 1 | BA30: 1 | BB30: 1 | BC30: 1 | BD30: 1 | BE30: 1 | BF30: 1 | BG30: 1 | BH30: 1 | BI30: 1 | BJ30: 1 | BK30: 1
G31: 27 | H31: 1 | I31: 1 | J31: 1 | K31: 1 | L31: 1 | M31: 1 | N31: 1 | O31: 1 | P31: 1 | Q31: 1 | R31: 1 | S31: 1 | T31: 1 | U31: 1 | V31: 1 | W31: 1 | X31: 1 | Y31: 1 | Z31: 1 | AA31: 1 | AB31: 1 | AC31: 1 | AD31: 1 | AE31: 1 | AF31: 1 | AG31: 1 | AH31: 1 | AI31: 1 | AJ31: 1 | AK31: 1 | AL31: 1 | AM31: 1 | AN31: 1 | AO31: 1 | AP31: 1 | AQ31: 1 | AR31: 1 | AS31: 1 | AT31: 1 | AU31: 1 | AV31: 1 | AW31: 2 | AX31: 1 | AY31: 1 | AZ31: 1 | BA31: 1 | BB31: 1 | BC31: 1 | BD31: 1 | BE31: 1 | BF31: 1 | BG31: 1 | BH31: 1 | BI31: 1 | BJ31: 1 | BK31: 1
G32: 28 | H32: 1 | I32: 1 | J32: 1 | K32: 1 | L32: 1 | M32: 1 | N32: 1 | O32: 1 | P32: 1 | Q32: 1 | R32: 1 | S32: 1 | T32: 1 | U32: 1 | V32: 1 | W32: 1 | X32: 1 | Y32: 1 | Z32: 1 | AA32: 1 | AB32: 1 | AC32: 1 | AD32: 1 | AE32: 1 | AF32: 1 | AG32: 1 | AH32: 1 | AI32: 1 | AJ32: 1 | AK32: 1 | AL32: 1 | AM32: 1 | AN32: 1 | AO32: 1 | AP32: 1 | AQ32: 1 | AR32: 1 | AS32: 1 | AT32: 1 | AU32: 1 | AV32: 1 | AW32: 3 | AX32: 1 | AY32: 1 | AZ32: 1 | BA32: 1 | BB32: 1 | BC32: 1 | BD32: 1 | BE32: 1 | BF32: 1 | BG32: 1 | BH32: 1 | BI32: 1 | BJ32: 1 | BK32: 1
G33: 29 | H33: 1 | I33: 1 | J33: 1 | K33: 1 | L33: 1 | M33: 1 | N33: 1 | O33: 1 | P33: 1 | Q33: 1 | R33: 1 | S33: 1 | T33: 1 | U33: 1 | V33: 1 | W33: 1 | X33: 1 | Y33: 1 | Z33: 1 | AA33: 1 | AB33: 1 | AC33: 1 | AD33: 1 | AE33: 1 | AF33: 1 | AG33: 1 | AH33: 1 | AI33: 1 | AJ33: 1 | AK33: 1 | AL33: 1 | AM33: 1 | AN33: 1 | AO33: 1 | AP33: 1 | AQ33: 1 | AR33: 1 | AS33: 1 | AT33: 1 | AU33: 1 | AV33: 1 | AW33: 3 | AX33: 1 | AY33: 1 | AZ33: 1 | BA33: 1 | BB33: 1 | BC33: 1 | BD33: 1 | BE33: 1 | BF33: 1 | BG33: 1 | BH33: 1 | BI33: 1 | BJ33: 1 | BK33: 1
G34: 30 | H34: 1 | I34: 1 | J34: 1 | K34: 1 | L34: 1 | M34: 1 | N34: 1 | O34: 1 | P34: 1 | Q34: 1 | R34: 1 | S34: 1 | T34: 1 | U34: 1 | V34: 1 | W34: 1 | X34: 1 | Y34: 1 | Z34: 1 | AA34: 1 | AB34: 1 | AC34: 1 | AD34: 1 | AE34: 1 | AF34: 1 | AG34: 1 | AH34: 1 | AI34: 1 | AJ34: 1 | AK34: 1 | AL34: 1 | AM34: 1 | AN34: 1 | AO34: 1 | AP34: 1 | AQ34: 1 | AR34: 1 | AS34: 1 | AT34: 1 | AU34: 1 | AV34: 1 | AW34: 3 | AX34: 1 | AY34: 1 | AZ34: 1 | BA34: 1 | BB34: 1 | BC34: 1 | BD34: 1 | BE34: 2 | BF34: 1 | BG34: 1 | BH34: 1 | BI34: 1 | BJ34: 1 | BK34: 1
G35: 31 | H35: 1 | I35: 1 | J35: 1 | K35: 1 | L35: 1 | M35: 1 | N35: 1 | O35: 1 | P35: 1 | Q35: 1 | R35: 1 | S35: 1 | T35: 1 | U35: 1 | V35: 1 | W35: 1 | X35: 1 | Y35: 1 | Z35: 1 | AA35: 1 | AB35: 1 | AC35: 1 | AD35: 1 | AE35: 1 | AF35: 1 | AG35: 1 | AH35: 1 | AI35: 1 | AJ35: 1 | AK35: 1 | AL35: 1 | AM35: 1 | AN35: 1 | AO35: 1 | AP35: 1 | AQ35: 2 | AR35: 1 | AS35: 1 | AT35: 1 | AU35: 1 | AV35: 1 | AW35: 3 | AX35: 1 | AY35: 1 | AZ35: 1 | BA35: 1 | BB35: 1 | BC35: 1 | BD35: 1 | BE35: 2 | BF35: 1 | BG35: 1 | BH35: 1 | BI35: 1 | BJ35: 1 | BK35: 1
G36: 32 | H36: 1 | I36: 1 | J36: 1 | K36: 1 | L36: 1 | M36: 1 | N36: 1 | O36: 1 | P36: 1 | Q36: 1 | R36: 1 | S36: 1 | T36: 1 | U36: 1 | V36: 1 | W36: 1 | X36: 1 | Y36: 1 | Z36: 1 | AA36: 1 | AB36: 1 | AC36: 1 | AD36: 1 | AE36: 1 | AF36: 1 | AG36: 1 | AH36: 1 | AI36: 1 | AJ36: 1 | AK36: 1 | AL36: 1 | AM36: 1 | AN36: 1 | AO36: 1 | AP36: 1 | AQ36: 2 | AR36: 1 | AS36: 1 | AT36: 1 | AU36: 1 | AV36: 1 | AW36: 3 | AX36: 1 | AY36: 1 | AZ36: 1 | BA36: 1 | BB36: 1 | BC36: 1 | BD36: 1 | BE36: 2 | BF36: 1 | BG36: 1 | BH36: 1 | BI36: 1 | BJ36: 1 | BK36: 1
G37: 33 | H37: 1 | I37: 1 | J37: 1 | K37: 1 | L37: 1 | M37: 1 | N37: 1 | O37: 1 | P37: 1 | Q37: 1 | R37: 1 | S37: 1 | T37: 1 | U37: 1 | V37: 1 | W37: 1 | X37: 1 | Y37: 1 | Z37: 1 | AA37: 1 | AB37: 1 | AC37: 1 | AD37: 1 | AE37: 1 | AF37: 1 | AG37: 1 | AH37: 1 | AI37: 1 | AJ37: 1 | AK37: 1 | AL37: 1 | AM37: 1 | AN37: 1 | AO37: 1 | AP37: 1 | AQ37: 2 | AR37: 1 | AS37: 1 | AT37: 1 | AU37: 1 | AV37: 1 | AW37: 3 | AX37: 1 | AY37: 1 | AZ37: 1 | BA37: 1 | BB37: 1 | BC37: 1 | BD37: 1 | BE37: 2 | BF37: 1 | BG37: 1 | BH37: 1 | BI37: 1 | BJ37: 1 | BK37: 1
G38: 34 | H38: 1 | I38: 1 | J38: 1 | K38: 1 | L38: 1 | M38: 1 | N38: 1 | O38: 1 | P38: 1 | Q38: 1 | R38: 1 | S38: 1 | T38: 1 | U38: 1 | V38: 1 | W38: 1 | X38: 1 | Y38: 1 | Z38: 1 | AA38: 1 | AB38: 1 | AC38: 1 | AD38: 1 | AE38: 1 | AF38: 1 | AG38: 1 | AH38: 1 | AI38: 1 | AJ38: 1 | AK38: 1 | AL38: 1 | AM38: 1 | AN38: 1 | AO38: 1 | AP38: 1 | AQ38: 2 | AR38: 1 | AS38: 1 | AT38: 1 | AU38: 1 | AV38: 1 | AW38: 4 | AX38: 1 | AY38: 1 | AZ38: 1 | BA38: 1 | BB38: 1 | BC38: 1 | BD38: 1 | BE38: 2 | BF38: 1 | BG38: 1 | BH38: 1 | BI38: 1 | BJ38: 1 | BK38: 1
G39: 35 | H39: 1 | I39: 1 | J39: 1 | K39: 1 | L39: 1 | M39: 1 | N39: 1 | O39: 1 | P39: 1 | Q39: 1 | R39: 1 | S39: 1 | T39: 1 | U39: 1 | V39: 1 | W39: 1 | X39: 1 | Y39: 1 | Z39: 1 | AA39: 1 | AB39: 1 | AC39: 1 | AD39: 1 | AE39: 1 | AF39: 1 | AG39: 1 | AH39: 1 | AI39: 1 | AJ39: 1 | AK39: 1 | AL39: 1 | AM39: 1 | AN39: 1 | AO39: 1 | AP39: 1 | AQ39: 2 | AR39: 1 | AS39: 1 | AT39: 1 | AU39: 1 | AV39: 1 | AW39: 4 | AX39: 1 | AY39: 1 | AZ39: 1 | BA39: 1 | BB39: 1 | BC39: 1 | BD39: 1 | BE39: 3 | BF39: 1 | BG39: 1 | BH39: 1 | BI39: 1 | BJ39: 1 | BK39: 1
G40: 36 | H40: 1 | I40: 1 | J40: 1 | K40: 1 | L40: 1 | M40: 1 | N40: 1 | O40: 1 | P40: 1 | Q40: 1 | R40: 1 | S40: 1 | T40: 1 | U40: 1 | V40: 1 | W40: 1 | X40: 1 | Y40: 1 | Z40: 1 | AA40: 1 | AB40: 1 | AC40: 1 | AD40: 1 | AE40: 1 | AF40: 1 | AG40: 1 | AH40: 1 | AI40: 1 | AJ40: 1 | AK40: 1 | AL40: 1 | AM40: 1 | AN40: 1 | AO40: 1 | AP40: 1 | AQ40: 3 | AR40: 1 | AS40: 1 | AT40: 1 | AU40: 1 | AV40: 1 | AW40: 4 | AX40: 1 | AY40: 1 | AZ40: 1 | BA40: 1 | BB40: 1 | BC40: 1 | BD40: 1 | BE40: 3 | BF40: 1 | BG40: 1 | BH40: 1 | BI40: 1 | BJ40: 1 | BK40: 1
...

Sheet Calc2
H1: GAC without Work | V1: GAC with Work | AJ1: CONCEPTUAL FUNCTIONING | AX1: SOCIAL FUNCTIONING | BL1: PRACTICAL FUNCTIONING w/o Work | BZ1: PRACTICAL FUNCTIONING with Work
H2: Rater: Self | O2: Rater: Other | V2: Rater: Self | AC2: Rater: Other | AJ2: Rater: Self | AQ2: Rater: Other | AX2: Rater: Self | BE2: Rater: Other | BL2: Rater: Self | BS2: Rater: Other | BZ2: Rater: Self | CG2: Rater: Other
A3: Selections | C3: Col. Add | G3: Raw | H3: 16-21 | I3: 22-29 | J3: 30-39 | K3: 40-49 | L3: 50-64 | M3: 65-74 | N3: 75-89 | O3: 16-21 | P3: 22-29 | Q3: 30-39 | R3: 40-49 | S3: 50-64 | T3: 65-74 | U3: 75-89 | V3: 16-21 | W3: 22-29 | X3: 30-39 | Y3: 40-49 | Z3: 50-64 | AA3: 65-74 | AB3: 75-89 | AC3: 16-21 | AD3: 22-29 | AE3: 30-39 | AF3: 40-49 | AG3: 50-64 | AH3: 65-74 | AI3: 75-89 | AJ3: 16-21 | AK3: 22-29 | AL3: 30-39 | AM3: 40-49 | AN3: 50-64 | AO3: 65-74 | AP3: 75-89 | AQ3: 16-21 | AR3: 22-29 | AS3: 30-39 | AT3: 40-49 | AU3: 50-64 | AV3: 65-74 | AW3: 75-89 | AX3: 16-21 | AY3: 22-29 | AZ3: 30-39 | BA3: 40-49 | BB3: 50-64 | BC3: 65-74 | BD3: 75-89 | BE3: 16-21 | BF3: 22-29 | BG3: 30-39 | BH3: 40-49 | BI3: 50-64 | BJ3: 65-74 | BK3: 75-89 | BL3: 16-21 | BM3: 22-29 | BN3: 30-39 | BO3: 40-49 | BP3: 50-64 | BQ3: 65-74 | BR3: 75-89 | BS3: 16-21 | BT3: 22-29 | BU3: 30-39 | BV3: 40-49 | BW3: 50-64 | BX3: 65-74 | BY3: 75-89 | BZ3: 16-21 | CA3: 22-29 | CB3: 30-39 | CC3: 40-49 | CD3: 50-64 | CE3: 65-74 | CF3: 75-89 | CG3: 16-21 | CH3: 22-29 | CI3: 30-39 | CJ3: 40-49 | CK3: 50-64 | CL3: 65-74 | CM3: 75-89
A4: Age: | B4: ='Score Summary'!D5 -> 16-21 | C4: =VLOOKUP(B4,A17:B24,2,FALSE) -> 0 | G4: 0 | H4: 41 | I4: 46 | J4: 49 | K4: 50 | L4: 50 | M4: 49 | N4: 46 | O4: 45 | P4: 44 | Q4: 45 | R4: 48 | S4: 52 | T4: 57 | U4: 62 | V4: 40 | W4: 47 | X4: 50 | Y4: 51 | Z4: 49 | AA4: 43 | AC4: 45 | AD4: 49 | AE4: 51 | AF4: 51 | AG4: 49 | AH4: 45 | AJ4: 41 | AK4: 47 | AL4: 50 | AM4: 52 | AN4: 52 | AO4: 51 | AP4: 49 | AQ4: 50 | AR4: 49 | AS4: 49 | AT4: 50 | AU4: 51 | AV4: 53 | AW4: 55 | AX4: 49 | AY4: 50 | AZ4: 51 | BA4: 52 | BB4: 52 | BC4: 52 | BD4: 52 | BE4: 54 | BF4: 52 | BG4: 51 | BH4: 52 | BI4: 54 | BJ4: 58 | BK4: 62 | BL4: 44 | BM4: 49 | BN4: 52 | BO4: 54 | BP4: 54 | BQ4: 53 | BR4: 50 | BS4: 45 | BT4: 44 | BU4: 46 | BV4: 50 | BW4: 55 | BX4: 61 | BY4: 66 | BZ4: 40 | CA4: 47 | CB4: 52 | CC4: 54 | CD4: 53 | CE4: 51 | CG4: 43 | CH4: 49 | CI4: 52 | CJ4: 52 | CK4: 51 | CL4: 48
A5: Rater: | B5: ='Score Summary'!D6 -> Self | C5: =IF(B5="Self",0,IF(B5="Other",7,"")) -> 0 | G5: 1 | H5: 41 | I5: 46 | J5: 49 | K5: 51 | L5: 51 | M5: 49 | N5: 47 | O5: 46 | P5: 45 | Q5: 46 | R5: 48 | S5: 52 | T5: 57 | U5: 62 | V5: 40 | W5: 47 | X5: 51 | Y5: 51 | Z5: 49 | AA5: 44 | AC5: 46 | AD5: 50 | AE5: 51 | AF5: 51 | AG5: 50 | AH5: 46 | AJ5: 43 | AK5: 48 | AL5: 52 | AM5: 53 | AN5: 54 | AO5: 53 | AP5: 51 | AQ5: 52 | AR5: 51 | AS5: 51 | AT5: 51 | AU5: 52 | AV5: 54 | AW5: 57 | AX5: 51 | AY5: 53 | AZ5: 54 | BA5: 54 | BB5: =BB4+2 -> 54 | BC5: 54 | BD5: =BD4+2 -> 54 | BE5: 56 | BF5: 54 | BG5: 53 | BH5: 54 | BI5: =BI4+2 -> 56 | BJ5: =BJ4+2 -> 60 | BK5: =BK4+2 -> 64 | BL5: 45 | BM5: 50 | BN5: =BN4+1 -> 53 | BO5: =BO4+1 -> 55 | BP5: =BP4+1 -> 55 | BQ5: =BQ4+1 -> 54 | BR5: 52 | BS5: 46 | BT5: 46 | BU5: =BU4+1 -> 47 | BV5: =BV4+1 -> 51 | BW5: =BW4+1 -> 56 | BX5: 62 | BY5: =BY4+1 -> 67 | BZ5: 40 | CA5: =CA4+1 -> 48 | CB5: =CB4+1 -> 53 | CC5: =CC4+1 -> 55 | CD5: =CD4+1 -> 54 | CE5: 52 | CG5: =CG4+1 -> 44 | CH5: =CH4+1 -> 50 | CI5: 52 | CJ5: =CJ4+1 -> 53 | CK5: =CK4+1 -> 52 | CL5: =CL4+1 -> 49
A6: CI: | B6: ='Score Summary'!G6 -> 0.95 | G6: 2 | H6: 42 | I6: 47 | J6: =J4+1 -> 50 | K6: 51 | L6: 51 | M6: =M4+1 -> 50 | N6: 47 | O6: 46 | P6: 45 | Q6: 46 | R6: =R4+1 -> 49 | S6: =S4+1 -> 53 | T6: 57 | U6: 62 | V6: 40 | W6: =W4+1 -> 48 | X6: 51 | Y6: =Y4+1 -> 52 | Z6: =Z4+1 -> 50 | AA6: 44 | AC6: 46 | AD6: 50 | AE6: 52 | AF6: 52 | AG6: 50 | AH6: 46 | AJ6: 44 | AK6: 50 | AL6: 53 | AM6: 55 | AN6: 55 | AO6: 54 | AP6: 52 | AQ6: 53 | AR6: 52 | AS6: 52 | AT6: 53 | AU6: 54 | AV6: 56 | AW6: 58 | AX6: =AX5+3 -> 54 | AY6: 55 | AZ6: 56 | BA6: 56 | BB6: 57 | BC6: 57 | BD6: =BD5+2 -> 56 | BE6: 58 | BF6: 56 | BG6: 56 | BH6: 56 | BI6: =BI5+2 -> 58 | BJ6: =BJ5+2 -> 62 | BK6: =BK5+2 -> 66 | BL6: 46 | BM6: 52 | BN6: =BN5+1 -> 54 | BO6: =BO5+1 -> 56 | BP6: =BP5+1 -> 56 | BQ6: =BQ5+1 -> 55 | BR6: =BR5+1 -> 53 | BS6: 48 | BT6: =BT5+1 -> 47 | BU6: 49 | BV6: =BV5+1 -> 52 | BW6: =BW5+1 -> 57 | BX6: 62 | BY6: =BY5+1 -> 68 | BZ6: 40 | CA6: =CA5+1 -> 49 | CB6: =CB5+1 -> 54 | CC6: =CC5+1 -> 56 | CD6: =CD5+1 -> 55 | CE6: 53 | CG6: =CG5+1 -> 45 | CH6: =CH5+1 -> 51 | CI6: =CI5+1 -> 53 | CJ6: =CJ5+1 -> 54 | CK6: =CK5+1 -> 53 | CL6: =CL5+1 -> 50
A7: Work?: | B7: ='Score Summary'!G5 -> No | G7: 3 | H7: 42 | I7: 48 | J7: =J5+1 -> 50 | K7: =K5+1 -> 52 | L7: =L5+1 -> 52 | M7: =M5+1 -> 50 | N7: =N5+1 -> 48 | O7: =O5+1 -> 47 | P7: =P5+1 -> 46 | Q7: =Q5+1 -> 47 | ... S7: =S5+1 -> 53 | T7: 58 | U7: =U5+1 -> 63 | V7: 40 | W7: =W5+1 -> 48 | X7: =X5+1 -> 52 | Y7: =Y5+1 -> 52 | Z7: =Z5+1 -> 50 | AA7: =AA5+1 -> 45 | AC7: =AC5+1 -> 47 | AD7: 50 | AE7: 52 | AF7: 52 | AG7: 50 | AH7: =AH5+1 -> 47 | AJ7: 46 | AK7: 52 | AL7: 55 | AM7: 56 | AN7: 57 | AO7: 56 | AP7: 54 | AQ7: 55 | AR7: 54 | AS7: 54 | AT7: 54 | AU7: 55 | AV7: 57 | AW7: 60 | AX7: 56 | AY7: 57 | AZ7: 58 | BA7: 59 | BB7: =BB6+2 -> 59 | BC7: 59 | BD7: =BD6+2 -> 58 | BE7: 61 | BF7: 58 | BG7: 58 | BH7: 58 | BI7: 61 | BJ7: =BJ6+2 -> 64 | BK7: 67 | BL7: 48 | BM7: =BM6+1 -> 53 | BN7: =BN6+1 -> 55 | BO7: =BO6+1 -> 57 | BP7: =BP6+1 -> 57 | BQ7: =BQ6+1 -> 56 | BR7: =BR6+1 -> 54 | BS7: =BS6+1 -> 49 | BT7: =BT6+1 -> 48 | ... BW7: =BW6+1 -> 58 | BX7: 63 | BY7: =BY6+1 -> 69 | BZ7: 41 | CA7: =CA6+1 -> 50 | CB7: =CB6+1 -> 55 | CC7: 56 | CD7: =CD6+1 -> 56 | CE7: 53 | CG7: =CG6+1 -> 46 | CH7: =CH6+1 -> 52 | CI7: =CI6+1 -> 54 | CJ7: =CJ6+1 -> 55 | CK7: =CK6+1 -> 54 | CL7: =CL6+1 -> 51
G8: 4 | H8: 43 | I8: 48 | J8: =J6+1 -> 51 | K8: =K6+1 -> 52 | L8: =L6+1 -> 52 | M8: =M6+1 -> 51 | N8: =N6+1 -> 48 | O8: =O6+1 -> 47 | P8: =P6+1 -> 46 | Q8: =Q6+1 -> 47 | ... S8: =S6+1 -> 54 | T8: 58 | U8: =U6+1 -> 63 | V8: 41 | W8: =W6+1 -> 49 | X8: =X6+1 -> 52 | Y8: =Y6+1 -> 53 | Z8: =Z6+1 -> 51 | AA8: =AA6+1 -> 45 | AC8: =AC6+1 -> 47 | AD8: 51 | AE8: 52 | AF8: 52 | AG8: 51 | AH8: =AH6+1 -> 47 | AJ8: 48 | AK8: 53 | AL8: 56 | AM8: =AM6+3 -> 58 | AN8: 58 | AO8: 57 | AP8: 55 | AQ8: 56 | AR8: 55 | AS8: 55 | AT8: 55 | AU8: 57 | AV8: 58 | AW8: 61 | AX8: 58 | AY8: 60 | AZ8: 60 | BA8: 61 | BB8: =BB7+2 -> 61 | BC8: 61 | BD8: 61 | BE8: 63 | BF8: 61 | BG8: 60 | BH8: 61 | BI8: =BI7+2 -> 63 | BJ8: =BJ7+2 -> 66 | BK8: =BK7+2 -> 69 | BL8: =BL7+1 -> 49 | BM8: =BM7+1 -> 54 | BN8: 57 | BO8: =BO7+1 -> 58 | BP8: =BP7+1 -> 58 | BQ8: =BQ7+1 -> 57 | BR8: =BR7+1 -> 55 | BS8: =BS7+1 -> 50 | BT8: 50 | BU8: =BU7+1 -> 51 | BV8: =BV7+1 -> 54 | BW8: =BW7+1 -> 59 | BX8: =BX7+1 -> 64 | BY8: 69 | BZ8: 42 | CA8: =CA7+1 -> 51 | CB8: =CB7+1 -> 56 | CC8: =CC7+1 -> 57 | CD8: =CD7+1 -> 57 | CE8: =CE7+1 -> 54 | CG8: =CG7+1 -> 47 | CH8: =CH7+1 -> 53 | CI8: =CI7+1 -> 55 | CJ8: =CJ7+1 -> 56 | CK8: =CK7+1 -> 55 | CL8: =CL7+1 -> 52
A9: Composite | C9: Sum of SS | D9: Comp | E9: Col. | F9: Conf. Int. | G9: 5 | H9: 44 | I9: 49 | J9: =J7+1 -> 51 | K9: =K7+1 -> 53 | L9: =L7+1 -> 53 | M9: =M7+1 -> 51 | N9: =N7+1 -> 49 | O9: =O7+1 -> 48 | P9: =P7+1 -> 47 | Q9: =Q7+1 -> 48 | ... U9: =U7+1 -> 64 | V9: 41 | W9: =W7+1 -> 49 | X9: =X7+1 -> 53 | Y9: =Y7+1 -> 53 | Z9: =Z7+1 -> 51 | AA9: =AA7+1 -> 46 | AC9: =AC7+1 -> 48 | AD9: 51 | AE9: 53 | AF9: 53 | AG9: 51 | AH9: =AH7+1 -> 48 | AJ9: 50 | AK9: 55 | AL9: 58 | AM9: =AM7+3 -> 59 | AN9: 59 | AO9: 59 | AP9: 57 | AQ9: 58 | AR9: 57 | AS9: 56 | AT9: 57 | AU9: 58 | AV9: 60 | AW9: 63 | AX9: =AX8+3 -> 61 | AY9: 62 | AZ9: 63 | BA9: 63 | BB9: =BB8+2 -> 63 | BC9: 63 | BD9: =BD8+2 -> 63 | BE9: 65 | BF9: 63 | BG9: 62 | BH9: 63 | BI9: =BI8+2 -> 65 | BJ9: =BJ8+2 -> 68 | BK9: =BK8+2 -> 71 | BL9: =BL8+1 -> 50 | BM9: =BM8+1 -> 55 | BN9: =BN8+1 -> 58 | BO9: =BO8+1 -> 59 | BP9: =BP8+1 -> 59 | BQ9: =BQ8+1 -> 58 | BR9: =BR8+1 -> 56 | BS9: 52 | BT9: =BT8+1 -> 51 | BU9: =BU8+1 -> 52 | BV9: 56 | BW9: =BW8+1 -> 60 | BX9: =BX8+1 -> 65 | BY9: =BY8+1 -> 70 | BZ9: 44 | CA9: =CA8+1 -> 52 | CB9: =CB8+1 -> 57 | CC9: =CC8+1 -> 58 | CD9: =CD8+1 -> 58 | CE9: =CE8+1 -> 55 | CG9: =CG8+1 -> 48 | CH9: 53 | CI9: =CI8+1 -> 56 | CJ9: 56 | CK9: 55 | CL9: 52
A10: GAC w/o Work | C10: =SUM('Score Summary'!E9:E17) -> 0 | D10: =VLOOKUP(C10,G4:U140,SUM(C4,C5,E10),FALSE) -> 41 | E10: 2 | F10: =VLOOKUP(B6,G144:CM146,SUM(E10,C4,C5),FALSE) -> 4 | G10: 6 | H10: 44 | I10: 49 | J10: =J8+1 -> 52 | K10: =K8+1 -> 53 | L10: =L8+1 -> 53 | M10: =M8+1 -> 52 | N10: 50 | O10: =O8+1 -> 48 | P10: =P8+1 -> 47 | Q10: =Q8+1 -> 48 | R10: =R8+1 -> 51 | S10: =S8+1 -> 55 | T10: =T8+1 -> 59 | U10: =U8+1 -> 64 | V10: 42 | W10: =W8+1 -> 50 | X10: =X8+1 -> 53 | Y10: =Y8+1 -> 54 | Z10: =Z8+1 -> 52 | AA10: =AA8+1 -> 46 | AC10: =AC8+1 -> 48 | AD10: =AD8+1 -> 52 | AE10: 53 | AF10: 53 | AG10: =AG8+1 -> 52 | AH10: =AH8+1 -> 48 | AJ10: 52 | AK10: 57 | AL10: 59 | AM10: =AM8+3 -> 61 | AN10: 61 | AO10: 60 | AP10: 59 | AQ10: 60 | AR10: 58 | AS10: 58 | AT10: 58 | AU10: 59 | AV10: 61 | AW10: 64 | AX10: 63 | AY10: 64 | AZ10: 65 | BA10: 65 | BB10: 66 | BC10: 65 | BD10: =BD9+2 -> 65 | BE10: 67 | BF10: 65 | BG10: 65 | BH10: 65 | BI10: =BI9+2 -> 67 | BJ10: =BJ9+2 -> 70 | BK10: =BK9+2 -> 73 | BL10: 52 | BM10: =BM9+1 -> 56 | BN10: =BN9+1 -> 59 | BO10: =BO9+1 -> 60 | BP10: =BP9+1 -> 60 | BQ10: =BQ9+1 -> 59 | BR10: =BR9+1 -> 57 | BS10: =BS9+1 -> 53 | BT10: =BT9+1 -> 52 | ... CA10: =CA9+1 -> 53 | CB10: 57 | CC10: =CC9+1 -> 59 | CD10: =CD9+1 -> 59 | CE10: =CE9+1 -> 56 | CG10: =CG9+1 -> 49 | CH10: =CH9+1 -> 54 | CI10: =CI9+1 -> 57 | CJ10: =CJ9+1 -> 57 | CK10: =CK9+1 -> 56 | CL10: =CL9+1 -> 53
A11: GAC w/ Work | C11: =SUM('Score Summary'!E9:E18) -> 0 | D11: =VLOOKUP(C11,G4:AI140,SUM(C4,C5,E11),FALSE) -> 40 | E11: =E10+14 -> 16 | F11: =VLOOKUP(B6,G144:CM146,SUM(C4,C5,E11),FALSE) -> 3 | G11: 7 | H11: 45 | I11: 50 | J11: =J9+1 -> 52 | K11: =K9+1 -> 54 | L11: =L9+1 -> 54 | M11: =M9+1 -> 52 | N11: =N9+1 -> 50 | O11: =O9+1 -> 49 | P11: =P9+1 -> 48 | Q11: =Q9+1 -> 49 | ... T11: =T9+1 -> 60 | U11: 64 | V11: 43 | W11: =W9+1 -> 50 | X11: =X9+1 -> 54 | Y11: =Y9+1 -> 54 | Z11: =Z9+1 -> 52 | AA11: =AA9+1 -> 47 | AC11: =AC9+1 -> 49 | AD11: =AD9+1 -> 52 | AE11: =AE9+1 -> 54 | AF11: =AF9+1 -> 54 | AG11: =AG9+1 -> 52 | AH11: =AH9+1 -> 49 | AJ11: 54 | AK11: 58 | AL11: 61 | AM11: =AM9+3 -> 62 | AN11: 62 | AO11: 62 | AP11: 60 | AQ11: 61 | AR11: 60 | AS11: 59 | AT11: 60 | AU11: 61 | AV11: 63 | AW11: 65 | AX11: =AX10+3 -> 66 | AY11: 67 | AZ11: 67 | BA11: 68 | BB11: =BB10+2 -> 68 | BC11: 68 | BD11: =BD10+2 -> 67 | BE11: 69 | BF11: 67 | BG11: 67 | BH11: 67 | BI11: =BI10+2 -> 69 | BJ11: =BJ10+2 -> 72 | BK11: =BK10+2 -> 75 | BL11: =BL10+1 -> 53 | BM11: =BM10+1 -> 57 | BN11: =BN10+1 -> 60 | BO11: =BO10+1 -> 61 | BP11: =BP10+1 -> 61 | BQ11: =BQ10+1 -> 60 | BR11: =BR10+1 -> 58 | BS11: =BS10+1 -> 54 | BT11: =BT10+1 -> 53 | BU11: 55 | BV11: =BV10+1 -> 58 | BW11: =BW10+1 -> 62 | BX11: =BX10+1 -> 67 | BY11: =BY10+1 -> 72 | BZ11: =BZ10+1 -> 46 | CA11: =CA10+1 -> 54 | CB11: =CB10+1 -> 58 | CC11: =CC10+1 -> 60 | CD11: 59 | CE11: =CE10+1 -> 57 | CG11: =CG10+1 -> 50 | CH11: =CH10+1 -> 55 | CI11: 57 | CJ11: =CJ10+1 -> 58 | CK11: =CK10+1 -> 57 | CL11: =CL10+1 -> 54
A12: CON | C12: =SUM('Score Summary'!F16,'Score Summary'!F11,'Score Summary'!F9) -> 0 | D12: =VLOOKUP(C12,G4:AW44,SUM(C4,C5,E12),FALSE) -> 41 | E12: =E11+14 -> 30 | F12: =VLOOKUP(B6,G144:CM146,SUM(C4,C5,E12),FALSE) -> 6 | G12: 8 | H12: 46 | I12: 50 | J12: =J10+1 -> 53 | K12: =K10+1 -> 54 | L12: =L10+1 -> 54 | M12: =M10+1 -> 53 | N12: =N10+1 -> 51 | O12: 50 | P12: 49 | Q12: =Q10+1 -> 49 | R12: =R10+1 -> 52 | S12: =S10+1 -> 56 | T12: =T10+1 -> 60 | U12: =U10+1 -> 65 | V12: 43 | W12: =W10+1 -> 51 | X12: =X10+1 -> 54 | Y12: =Y10+1 -> 55 | Z12: =Z10+1 -> 53 | AA12: =AA10+1 -> 47 | AC12: =AC10+1 -> 49 | AD12: =AD10+1 -> 53 | AE12: =AE10+1 -> 54 | AF12: =AF10+1 -> 54 | AG12: =AG10+1 -> 53 | AH12: =AH10+1 -> 49 | AJ12: 56 | AK12: 60 | AL12: 62 | AM12: =AM10+3 -> 64 | AN12: 64 | AO12: 63 | AP12: 62 | AQ12: 63 | AR12: 61 | AS12: 61 | AT12: 61 | AU12: 62 | AV12: 64 | AW12: 67 | AX12: 68 | AY12: 69 | AZ12: 70 | BA12: 70 | BB12: =BB11+2 -> 70 | BC12: 70 | BD12: =BD11+2 -> 69 | BE12: 71 | BF12: 70 | BG12: 69 | BH12: 70 | BI12: =BI11+2 -> 71 | BJ12: =BJ11+2 -> 74 | BK12: =BK11+2 -> 77 | BL12: 55 | BM12: 59 | BN12: =BN11+1 -> 61 | BO12: =BO11+1 -> 62 | BP12: =BP11+1 -> 62 | BQ12: =BQ11+1 -> 61 | BR12: 60 | BS12: 56 | BT12: 55 | BU12: =BU11+1 -> 56 | BV12: =BV11+1 -> 59 | BW12: =BW11+1 -> 63 | BX12: =BX11+1 -> 68 | BY12: =BY11+1 -> 73 | BZ12: =BZ11+1 -> 47 | CA12: =CA11+1 -> 55 | CB12: =CB11+1 -> 59 | ... CE12: =CE11+1 -> 58 | CG12: =CG11+1 -> 51 | CH12: =CH11+1 -> 56 | CI12: =CI11+1 -> 58 | CJ12: =CJ11+1 -> 59 | CK12: =CK11+1 -> 58 | CL12: =CL11+1 -> 55
A13: SO | C13: =SUM('Score Summary'!G14,'Score Summary'!G17) -> 0 | D13: =VLOOKUP(C13,G3:BK30,SUM(C4:C5,E13),FALSE) -> 49 | E13: =E12+14 -> 44 | F13: =VLOOKUP(B6,G144:CM146,SUM(C4,C5,E13),FALSE) -> 6 | G13: 9 | H13: 46 | I13: 51 | J13: =J11+1 -> 53 | K13: =K11+1 -> 55 | L13: =L11+1 -> 55 | M13: =M11+1 -> 53 | N13: =N11+1 -> 51 | O13: =O11+1 -> 50 | P13: =P11+1 -> 49 | Q13: =Q11+1 -> 50 | ... S13: =S11+1 -> 56 | T13: 60 | U13: =U11+1 -> 65 | V13: 44 | W13: =W11+1 -> 51 | X13: =X11+1 -> 55 | Y13: =Y11+1 -> 55 | Z13: =Z11+1 -> 53 | AA13: =AA11+1 -> 48 | AC13: =AC11+1 -> 50 | AD13: =AD11+1 -> 53 | AE13: =AE11+1 -> 55 | AF13: =AF11+1 -> 55 | AG13: =AG11+1 -> 53 | AH13: =AH11+1 -> 50 | AJ13: 58 | AK13: 62 | AL13: 64 | AM13: =AM11+3 -> 65 | AN13: 65 | AO13: 65 | AP13: 63 | AQ13: 64 | AR13: 63 | AS13: 62 | AT13: 63 | AU13: 64 | AV13: 66 | AW13: 68 | AX13: =AX12+3 -> 71 | AY13: 71 | AZ13: 72 | BA13: 72 | BB13: =BB12+2 -> 72 | BC13: 72 | BD13: 72 | BE13: 73 | BF13: 72 | BG13: 71 | BH13: 72 | BI13: =BI12+2 -> 73 | BJ13: =BJ12+2 -> 76 | BK13: 78 | BL13: =BL12+1 -> 56 | BM13: =BM12+1 -> 60 | BN13: =BN12+1 -> 62 | BO13: =BO12+1 -> 63 | BP13: =BP12+1 -> 63 | BQ13: =BQ12+1 -> 62 | BR13: =BR12+1 -> 61 | BS13: =BS12+1 -> 57 | ... BX13: =BX12+1 -> 69 | BY13: 73 | BZ13: 49 | CA13: 57 | CB13: =CB12+1 -> 60 | CC13: 61 | CD13: =CD12+1 -> 61 | CE13: =CE12+1 -> 59 | CG13: =CG12+1 -> 52 | CH13: =CH12+1 -> 57 | CI13: =CI12+1 -> 59 | CJ13: =CJ12+1 -> 60 | CK13: =CK12+1 -> 59 | CL13: =CL12+1 -> 56
A14: PR w/o Work | C14: =SUM('Score Summary'!H10:I10,'Score Summary'!H12:I12,'Score Summary'!H13:I13,'Score Summary'!H15:I15) -> 0 | D14: =VLOOKUP(C14,G3:BY58,SUM(C4,C5,E14),FALSE) -> 44 | E14: =E13+14 -> 58 | F14: =VLOOKUP(B6,G144:CM146,SUM(C4,C5,E14),FALSE) -> 5 | G14: 10 | H14: 47 | I14: 51 | J14: =J12+1 -> 54 | K14: =K12+1 -> 55 | L14: =L12+1 -> 55 | M14: =M12+1 -> 54 | N14: =N12+1 -> 52 | O14: =O12+1 -> 51 | P14: =P12+1 -> 50 | Q14: =Q12+1 -> 50 | ... U14: =U12+1 -> 66 | V14: 44 | W14: =W12+1 -> 52 | X14: =X12+1 -> 55 | Y14: 55 | Z14: 53 | AA14: =AA12+1 -> 48 | AC14: =AC12+1 -> 50 | AD14: =AD12+1 -> 54 | AE14: =AE12+1 -> 55 | AF14: =AF12+1 -> 55 | AG14: =AG12+1 -> 54 | AH14: =AH12+1 -> 50 | AJ14: 60 | AK14: 63 | AL14: 66 | AM14: =AM12+3 -> 67 | AN14: 67 | AO14: 66 | AP14: 65 | AQ14: 66 | AR14: 64 | AS14: 64 | AT14: 64 | AU14: 65 | AV14: 67 | AW14: 70 | AX14: 73 | AY14: 74 | AZ14: 74 | BA14: 74 | BB14: =BB13+2 -> 74 | BC14: 74 | BD14: =BD13+2 -> 74 | BE14: 75 | BF14: 74 | BG14: 74 | BH14: 74 | BI14: 76 | BJ14: =BJ13+2 -> 78 | BK14: =BK13+2 -> 80 | BL14: =BL13+1 -> 57 | BM14: =BM13+1 -> 61 | BN14: =BN13+1 -> 63 | BO14: =BO13+1 -> 64 | BP14: =BP13+1 -> 64 | BQ14: =BQ13+1 -> 63 | BR14: =BR13+1 -> 62 | BS14: =BS13+1 -> 58 | ... BW14: =BW13+1 -> 65 | BX14: 69 | BY14: =BY13+1 -> 74 | BZ14: =BZ13+1 -> 50 | CA14: =CA13+1 -> 58 | CB14: =CB13+1 -> 61 | CC14: =CC13+1 -> 62 | CD14: =CD13+1 -> 62 | CE14: =CE13+1 -> 60 | CG14: 54 | CH14: =CH13+1 -> 58 | CI14: =CI13+1 -> 60 | CJ14: 60 | CK14: =CK13+1 -> 60 | CL14: =CL13+1 -> 57
A15: PR w/ WORK | C15: =SUM('Score Summary'!H10:I10,'Score Summary'!H12:I12,'Score Summary'!H13:I13,'Score Summary'!H15:I15,'Score Summary'!H18:I18) -> 0 | D15: =VLOOKUP(C15,G3:CM72,SUM(C4,C5,E15),FALSE) -> 40 | E15: =E14+14 -> 72 | F15: =VLOOKUP(B6,G144:CM146,SUM(C4,C5,E15),FALSE) -> 5 | G15: 11 | H15: 48 | I15: 52 | J15: 55 | K15: =K13+1 -> 56 | L15: =L13+1 -> 56 | M15: =M13+1 -> 54 | N15: =N13+1 -> 52 | O15: =O13+1 -> 51 | P15: =P13+1 -> 50 | Q15: =Q13+1 -> 51 | R15: =R13+1 -> 53 | ... U15: =U13+1 -> 66 | V15: 45 | W15: =W13+1 -> 52 | X15: 55 | Y15: =Y13+1 -> 56 | Z15: =Z13+1 -> 54 | AA15: =AA13+1 -> 49 | AC15: =AC13+1 -> 51 | AD15: =AD13+1 -> 54 | AE15: 55 | AF15: 55 | AG15: =AG13+1 -> 54 | AH15: =AH13+1 -> 51 | AJ15: 62 | AK15: 65 | AL15: 67 | AM15: =AM13+3 -> 68 | AN15: 68 | AO15: 68 | AP15: 66 | AQ15: 67 | AR15: 66 | AS15: 65 | AT15: 66 | AU15: 67 | AV15: 68 | AW15: 71 | AX15: =AX14+3 -> 76 | AY15: 76 | AZ15: 77 | BA15: 77 | BB15: 77 | BC15: 76 | BD15: =BD14+2 -> 76 | BE15: 78 | BF15: 76 | BG15: 76 | BH15: 76 | BI15: =BI14+2 -> 78 | BJ15: =BJ14+2 -> 80 | BK15: =BK14+2 -> 82 | BL15: 59 | BM15: =BM14+1 -> 62 | BN15: =BN14+1 -> 64 | BO15: =BO14+1 -> 65 | BP15: =BP14+1 -> 65 | BQ15: =BQ14+1 -> 64 | BR15: =BR14+1 -> 63 | BS15: 60 | BT15: =BT14+1 -> 58 | BU15: =BU14+1 -> 59 | BV15: =BV14+1 -> 62 | BW15: =BW14+1 -> 66 | BX15: =BX14+1 -> 70 | BY15: =BY14+1 -> 75 | BZ15: =BZ14+1 -> 51 | CA15: =CA14+1 -> 59 | ... CE15: =CE14+1 -> 61 | CG15: =CG14+1 -> 55 | CH15: =CH14+1 -> 59 | CI15: =CI14+1 -> 61 | CJ15: =CJ14+1 -> 61 | CK15: 60 | CL15: =CL14+1 -> 58
G16: 12 | H16: 48 | I16: 53 | J16: =J14+1 -> 55 | K16: =K14+1 -> 56 | L16: =L14+1 -> 56 | M16: =M14+1 -> 55 | N16: =N14+1 -> 53 | O16: =O14+1 -> 52 | P16: =P14+1 -> 51 | Q16: 52 | R16: =R14+1 -> 54 | S16: 57 | T16: =T14+1 -> 62 | U16: 66 | V16: 46 | W16: =W14+1 -> 53 | X16: =X14+1 -> 56 | Y16: =Y14+1 -> 56 | Z16: =Z14+1 -> 54 | AA16: =AA14+1 -> 49 | AC16: =AC14+1 -> 51 | AD16: =AD14+1 -> 55 | AE16: =AE14+1 -> 56 | AF16: =AF14+1 -> 56 | AG16: 54 | AH16: =AH14+1 -> 51 | AJ16: 64 | AK16: 67 | AL16: 69 | AM16: 69 | AN16: 70 | AO16: 69 | AP16: 68 | AQ16: 69 | AR16: 67 | AS16: 67 | AT16: 67 | AU16: 68 | AV16: 70 | AW16: 72 | AX16: 78 | AY16: 79 | AZ16: 79 | BA16: 79 | BB16: =BB15+2 -> 79 | BC16: 79 | BD16: =BD15+2 -> 78 | BE16: 80 | BF16: 78 | BG16: 78 | BH16: 78 | BI16: =BI15+2 -> 80 | BJ16: =BJ15+2 -> 82 | BK16: =BK15+2 -> 84 | BL16: =BL15+1 -> 60 | BM16: =BM15+1 -> 63 | BN16: =BN15+1 -> 65 | BO16: =BO15+1 -> 66 | BP16: =BP15+1 -> 66 | BQ16: =BQ15+1 -> 65 | BR16: =BR15+1 -> 64 | BS16: =BS15+1 -> 61 | BT16: 60 | BU16: 61 | BV16: =BV15+1 -> 63 | BW16: =BW15+1 -> 67 | BX16: =BX15+1 -> 71 | BY16: =BY15+1 -> 76 | BZ16: =BZ15+1 -> 52 | CA16: =CA15+1 -> 60 | CB16: =CB15+1 -> 63 | CC16: =CC15+1 -> 64 | CD16: =CD15+1 -> 64 | CE16: 61 | CG16: =CG15+1 -> 56 | CH16: =CH15+1 -> 60 | CI16: =CI15+1 -> 62 | CJ16: =CJ15+1 -> 62 | CK16: =CK15+1 -> 61 | CL16: =CL15+1 -> 59
A17: Age | B17: Col | G17: 13 | H17: 49 | I17: 53 | J17: =J15+1 -> 56 | K17: =K15+1 -> 57 | L17: =L15+1 -> 57 | M17: =M15+1 -> 55 | N17: =N15+1 -> 53 | O17: =O15+1 -> 52 | P17: =P15+1 -> 51 | Q17: =Q15+1 -> 52 | ... U17: =U15+1 -> 67 | V17: 46 | W17: =W15+1 -> 53 | X17: =X15+1 -> 56 | Y17: =Y15+1 -> 57 | Z17: =Z15+1 -> 55 | AA17: =AA15+1 -> 50 | AC17: =AC15+1 -> 52 | AD17: =AD15+1 -> 55 | AE17: =AE15+1 -> 56 | AF17: =AF15+1 -> 56 | AG17: =AG15+1 -> 55 | AH17: =AH15+1 -> 52 | AJ17: 66 | AK17: 69 | AL17: 70 | AM17: =AM15+3 -> 71 | AN17: 71 | AO17: 71 | AP17: 69 | AQ17: 71 | AR17: 69 | AS17: 68 | AT17: 68 | AU17: 69 | AV17: 71 | AW17: 74 | AX17: 80 | AY17: 81 | AZ17: 81 | BA17: 81 | BB17: =BB16+2 -> 81 | BC17: 81 | BD17: =BD16+2 -> 80 | BE17: 82 | BF17: 81 | BG17: 80 | BH17: 81 | BI17: =BI16+2 -> 82 | BJ17: =BJ16+2 -> 84 | BK17: =BK16+2 -> 86 | BL17: =BL16+1 -> 61 | BM17: =BM16+1 -> 64 | BN17: =BN16+1 -> 66 | BO17: =BO16+1 -> 67 | BP17: =BP16+1 -> 67 | BQ17: 67 | BR17: =BR16+1 -> 65 | BS17: =BS16+1 -> 62 | BT17: =BT16+1 -> 61 | BU17: =BU16+1 -> 62 | BV17: =BV16+1 -> 64 | BW17: =BW16+1 -> 68 | BX17: =BX16+1 -> 72 | BY17: 76 | BZ17: 54 | CA17: =CA16+1 -> 61 | CB17: =CB16+1 -> 64 | CC17: =CC16+1 -> 65 | CD17: 64 | CE17: =CE16+1 -> 62 | CG17: =CG16+1 -> 57 | CH17: =CH16+1 -> 61 | CI17: =CI16+1 -> 63 | CJ17: =CJ16+1 -> 63 | CK17: =CK16+1 -> 62 | CL17: =CL16+1 -> 60
A18: 16-21 | B18: 0 | G18: 14 | H18: 49 | I18: 54 | J18: =J16+1 -> 56 | K18: =K16+1 -> 57 | L18: =L16+1 -> 57 | M18: =M16+1 -> 56 | N18: =N16+1 -> 54 | O18: =O16+1 -> 53 | P18: =P16+1 -> 52 | Q18: =Q16+1 -> 53 | ... U18: =U16+1 -> 67 | V18: 47 | W18: =W16+1 -> 54 | X18: =X16+1 -> 57 | Y18: =Y16+1 -> 57 | Z18: =Z16+1 -> 55 | AA18: =AA16+1 -> 50 | AC18: =AC16+1 -> 52 | AD18: 55 | AE18: =AE16+1 -> 57 | AF18: =AF16+1 -> 57 | AG18: =AG16+1 -> 55 | AH18: =AH16+1 -> 52 | AJ18: 68 | AK18: 70 | AL18: 72 | AM18: =AM16+3 -> 72 | AN18: 73 | AO18: 72 | AP18: 71 | AQ18: 72 | AR18: 71 | AS18: 70 | AT18: 70 | AU18: 71 | AV18: 73 | AW18: 75 | AX18: =AX17+3 -> 83 | AY18: 83 | AZ18: 83 | BA18: 83 | BB18: =BB17+2 -> 83 | BC18: 83 | BD18: =BD17+2 -> 82 | BE18: 84 | BF18: 83 | BG18: 83 | BH18: 83 | BI18: =BI17+2 -> 84 | BJ18: =BJ17+2 -> 86 | BK18: =BK17+2 -> 88 | BL18: 63 | BM18: 66 | BN18: =BN17+1 -> 67 | BO18: =BO17+1 -> 68 | BP18: =BP17+1 -> 68 | BQ18: =BQ17+1 -> 68 | BR18: =BR17+1 -> 66 | BS18: =BS17+1 -> 63 | BT18: =BT17+1 -> 62 | BU18: =BU17+1 -> 63 | ... CE18: =CE17+1 -> 63 | CG18: =CG17+1 -> 58 | CH18: =CH17+1 -> 62 | CI18: 63 | CJ18: =CJ17+1 -> 64 | CK18: =CK17+1 -> 63 | CL18: =CL17+1 -> 61
A19: 22-29 | B19: 1 | G19: 15 | H19: 50 | I19: 54 | J19: =J17+1 -> 57 | K19: =K17+1 -> 58 | L19: =L17+1 -> 58 | M19: =M17+1 -> 56 | N19: =N17+1 -> 54 | O19: 54 | P19: =P17+1 -> 52 | Q19: =Q17+1 -> 53 | R19: =R17+1 -> 55 | S19: =S17+1 -> 59 | T19: =T17+1 -> 63 | U19: =U17+1 -> 68 | V19: 47 | W19: =W17+1 -> 54 | X19: =X17+1 -> 57 | Y19: =Y17+1 -> 58 | Z19: =Z17+1 -> 56 | AA19: =AA17+1 -> 51 | AC19: =AC17+1 -> 53 | AD19: =AD17+1 -> 56 | AE19: =AE17+1 -> 57 | AF19: =AF17+1 -> 57 | AG19: =AG17+1 -> 56 | AH19: =AH17+1 -> 53 | AJ19: 69 | AK19: 72 | AL19: 73 | AM19: =AM17+3 -> 74 | AN19: 74 | AO19: 74 | AP19: 73 | AQ19: 74 | AR19: 72 | AS19: 71 | AT19: 71 | AU19: 72 | AV19: 74 | AW19: 77 | AX19: 85 | AY19: 86 | AZ19: 86 | BA19: 86 | BB19: 86 | BC19: 85 | BD19: 85 | BE19: 86 | BF19: 85 | BG19: 85 | BH19: 85 | BI19: =BI18+2 -> 86 | BJ19: =BJ18+2 -> 88 | BK19: 89 | BL19: =BL18+1 -> 64 | BM19: =BM18+1 -> 67 | BN19: =BN18+1 -> 68 | BO19: =BO18+1 -> 69 | BP19: =BP18+1 -> 69 | BQ19: =BQ18+1 -> 69 | BR19: 68 | BS19: 65 | BT19: =BT18+1 -> 63 | BU19: =BU18+1 -> 64 | BV19: =BV18+1 -> 66 | BW19: =BW18+1 -> 70 | BX19: =BX18+1 -> 74 | BY19: =BY18+1 -> 78 | BZ19: =BZ18+1 -> 56 | CA19: =CA18+1 -> 63 | ... CE19: =CE18+1 -> 64 | CG19: =CG18+1 -> 59 | CH19: =CH18+1 -> 63 | CI19: =CI18+1 -> 64 | CJ19: =CJ18+1 -> 65 | CK19: =CK18+1 -> 64 | CL19: =CL18+1 -> 62
A20: 30-39 | B20: 2 | G20: 16 | H20: 51 | I20: 55 | J20: =J18+1 -> 57 | K20: =K18+1 -> 58 | L20: =L18+1 -> 58 | M20: =M18+1 -> 57 | N20: =N18+1 -> 55 | O20: =O18+1 -> 54 | P20: =P18+1 -> 53 | Q20: =Q18+1 -> 54 | ... S20: =S18+1 -> 59 | T20: 63 | U20: =U18+1 -> 68 | V20: 48 | W20: =W18+1 -> 55 | X20: =X18+1 -> 58 | Y20: =Y18+1 -> 58 | Z20: =Z18+1 -> 56 | AA20: =AA18+1 -> 51 | AC20: =AC18+1 -> 53 | AD20: =AD18+1 -> 56 | AE20: =AE18+1 -> 58 | AF20: =AF18+1 -> 58 | AG20: =AG18+1 -> 56 | AH20: =AH18+1 -> 53 | AJ20: 71 | AK20: 74 | AL20: 75 | AM20: =AM18+3 -> 75 | AN20: 75 | AO20: 75 | AP20: 74 | AQ20: 75 | AR20: 74 | AS20: 73 | AT20: 73 | AU20: 74 | AV20: 75 | AW20: 78 | AX20: =AX19+3 -> 88 | AY20: 88 | AZ20: 88 | BA20: 88 | BB20: =BB19+2 -> 88 | BC20: 87 | BD20: =BD19+2 -> 87 | BE20: 88 | BF20: 87 | BG20: 87 | BH20: 87 | BI20: =BI19+2 -> 88 | BJ20: =BJ19+2 -> 90 | BK20: =BK19+2 -> 91 | BL20: 66 | BM20: =BM19+1 -> 68 | BN20: =BN19+1 -> 69 | BO20: =BO19+1 -> 70 | BP20: =BP19+1 -> 70 | BQ20: =BQ19+1 -> 70 | BR20: =BR19+1 -> 69 | BS20: =BS19+1 -> 66 | BT20: 65 | BU20: =BU19+1 -> 65 | BV20: 68 | BW20: =BW19+1 -> 71 | BX20: =BX19+1 -> 75 | BY20: =BY19+1 -> 79 | BZ20: =BZ19+1 -> 57 | CA20: =CA19+1 -> 64 | CB20: 66 | CC20: 67 | CD20: =CD19+1 -> 67 | CE20: =CE19+1 -> 65 | CG20: =CG19+1 -> 60 | CH20: =CH19+1 -> 64 | CI20: =CI19+1 -> 65 | CJ20: 65 | CK20: =CK19+1 -> 65 | CL20: =CL19+1 -> 63
A21: 40-49 | B21: 3 | G21: 17 | H21: 51 | I21: 55 | J21: =J19+1 -> 58 | K21: =K19+1 -> 59 | L21: =L19+1 -> 59 | M21: =M19+1 -> 57 | N21: =N19+1 -> 55 | O21: =O19+1 -> 55 | P21: 54 | Q21: =Q19+1 -> 54 | R21: =R19+1 -> 56 | S21: =S19+1 -> 60 | T21: =T19+1 -> 64 | U21: 68 | V21: 49 | W21: =W19+1 -> 55 | X21: =X19+1 -> 58 | Y21: =Y19+1 -> 59 | Z21: =Z19+1 -> 57 | AA21: =AA19+1 -> 52 | AC21: =AC19+1 -> 54 | AD21: =AD19+1 -> 57 | AE21: =AE19+1 -> 58 | AF21: =AF19+1 -> 58 | AG21: =AG19+1 -> 57 | AH21: =AH19+1 -> 54 | AJ21: 73 | AK21: 75 | AL21: 76 | AM21: =AM19+3 -> 77 | AN21: 77 | AO21: 77 | AP21: 76 | AQ21: 77 | AR21: 75 | AS21: 74 | AT21: 74 | AU21: 75 | AV21: 77 | AW21: 79 | AX21: 90 | AY21: 90 | AZ21: 90 | BA21: 90 | BB21: =BB20+2 -> 90 | BC21: 90 | BD21: =BD20+2 -> 89 | BE21: 90 | BF21: 89 | BG21: 89 | BH21: 90 | BI21: =BI20+2 -> 90 | BJ21: =BJ20+2 -> 92 | BK21: =BK20+2 -> 93 | BL21: =BL20+1 -> 67 | BM21: =BM20+1 -> 69 | BN21: =BN20+1 -> 70 | BO21: =BO20+1 -> 71 | BP21: =BP20+1 -> 71 | BQ21: =BQ20+1 -> 71 | BR21: =BR20+1 -> 70 | BS21: =BS20+1 -> 67 | BT21: =BT20+1 -> 66 | BU21: 67 | BV21: =BV20+1 -> 69 | BW21: =BW20+1 -> 72 | BX21: =BX20+1 -> 76 | BY21: 79 | BZ21: 59 | CA21: =CA20+1 -> 65 | CB21: =CB20+1 -> 67 | CC21: =CC20+1 -> 68 | CD21: =CD20+1 -> 68 | CE21: =CE20+1 -> 66 | CG21: =CG20+1 -> 61 | CH21: 64 | CI21: =CI20+1 -> 66 | CJ21: =CJ20+1 -> 66 | CK21: =CK20+1 -> 66 | CL21: =CL20+1 -> 64
